Workbook
Name COLOR: #REF!
Name Size: #REF!

Sheet Axkid Template
A1: Axkid Product Template | I1: Change RRP currency --> | J1: EUR | R1: Product size | V1: Box size
A2: Article Number | B2: Article Name | C2: Color | D2: EAN code | E2: Status | F2: Category | G2: Approval description | H2: Recommended age | I2: Range limit | J2: Currency | K2: Recommended Retail Price | L2: Full container qty | M2: Master box quantity | N2: Sales qty | O2: Qty per pallet | P2: Country of origin | Q2: HS code | R2: Width in CM | S2: Height in cm | T2: Depth in cm | U2: Net weight kg | V2: Lenght in cm | W2: Width in cm2 | X2: Height in cm2 | Y2: Gross weight kg | Z2: Volume m3 | AA2: Washing instruction | AB2: Product images & movies | AC2: Product manual
A3: 20050002 | B3: Axkid Babyfix Grey | C3: Grey | D3: 7350057581933 | E3: Active | F3: Infant carrier | G3: ECE R44 | H3: 0-1 years | I3: 0-13kg | J3: =$J$1 -> EUR | K3: =IF($J$1="SEK / NOK",(VLOOKUP(A3,'RRP data'!A:C,3,FALSE)),(IF($J$1="DKK",(VLOOKUP('RRP data'!A3,'RRP data'!A:D,4,FALSE)),(IF($J$1="EUR",(VLOOKUP(A3,'RRP data'!A:E,5,FALSE))))))) -> 149 | M3: 1 | N3: 1 | P3: CN | Q3: 94018000 | R3: 43 | S3: 54 | T3: 65 | U3: 3.4 | V3: 45 | W3: 58 | X3: 67 | Y3: 5.79 | Z3: =PRODUCT(V3:X3)/1000000 -> 0.17487 | AA3: 30°
A4: 20050003 | B4: Axkid Babyfix Black | C4: Black | D4: 7350057581940 | E4: Active | F4: Infant carrier | G4: ECE R44 | H4: 0-1 years | I4: 0-13kg | J4: =$J$1 -> EUR | K4: =IF($J$1="SEK / NOK",(VLOOKUP(A4,'RRP data'!A:C,3,FALSE)),(IF($J$1="DKK",(VLOOKUP('RRP data'!A4,'RRP data'!A:D,4,FALSE)),(IF($J$1="EUR",(VLOOKUP(A4,'RRP data'!A:E,5,FALSE))))))) -> 149 | M4: 1 | N4: 1 | P4: CN | Q4: 94018000 | R4: 43 | S4: 54 | T4: 65 | U4: 3.4 | V4: 45 | W4: 58 | X4: 67 | Y4: 5.79 | Z4: =PRODUCT(V4:X4)/1000000 -> 0.17487 | AA4: 30°
A5: 210103 | B5: Axkid Babyfix Base Black | C5: Black | D5: 7350057580042 | E5: Active | F5: Base | G5: ECE R44 | H5: n/a | I5: n/a | J5: =$J$1 -> EUR | K5: =IF($J$1="SEK / NOK",(VLOOKUP(A5,'RRP data'!A:C,3,FALSE)),(IF($J$1="DKK",(VLOOKUP('RRP data'!A5,'RRP data'!A:D,4,FALSE)),(IF($J$1="EUR",(VLOOKUP(A5,'RRP data'!A:E,5,FALSE))))))) -> 100 | M5: 1 | N5: 1 | P5: CN | Q5: 94018000 | R5: 33 | S5: 43 | T5: 69 | U5: 4.63 | V5: 34 | W5: 20 | X5: 60.5 | Y5: 5.45 | Z5: =PRODUCT(V5:X5)/1000000 -> 0.04114 | AA5: 30°
A6: 22150116 | B6: Axkid Minikid 3 Tar | C6: Tar Black | D6: 7350057586723 | E6: Active | F6: Rear-facing car seat | G6: UN R129 | H6: 0-7 years | I6: 36kg | J6: =$J$1 -> EUR | K6: =IF($J$1="SEK / NOK",(VLOOKUP(A6,'RRP data'!A:C,3,FALSE)),(IF($J$1="DKK",(VLOOKUP('RRP data'!A6,'RRP data'!A:D,4,FALSE)),(IF($J$1="EUR",(VLOOKUP(A6,'RRP data'!A:E,5,FALSE))))))) -> 549 | M6: 1 | N6: 1 | P6: CN | Q6: 94018000 | R6: 44 | S6: 65 | T6: 54 | U6: 11 | V6: 46 | W6: 58 | X6: 66 | Y6: 14 | Z6: =PRODUCT(V6:X6)/1000000 -> 0.176088 | AA6: 30°
A7: 22150117 | B7: Axkid Minikid 3 Granite | C7: Granite Grey | D7: 7350057586730 | E7: Active | F7: Rear-facing car seat | G7: UN R129 | H7: 0-7 years | I7: 61-125cm (max 36kg) | J7: =$J$1 -> EUR | K7: =IF($J$1="SEK / NOK",(VLOOKUP(A7,'RRP data'!A:C,3,FALSE)),(IF($J$1="DKK",(VLOOKUP('RRP data'!A7,'RRP data'!A:D,4,FALSE)),(IF($J$1="EUR",(VLOOKUP(A7,'RRP data'!A:E,5,FALSE))))))) -> 549 | M7: 1 | N7: 1 | P7: CN | Q7: 94018000 | R7: 44 | S7: 65 | T7: 54 | U7: 11 | V7: 46 | W7: 58 | X7: 66 | Y7: 14 | Z7: =PRODUCT(V7:X7)/1000000 -> 0.176088 | AA7: 30°
A8: 22150118 | B8: Axkid Minikid 3 Shellfish | C8: Shellfish Red | D8: 7350057586747 | E8: Active | F8: Rear-facing car seat | G8: UN R129 | H8: 0-7 years | I8: 61-125cm (max 36kg) | J8: =$J$1 -> EUR | K8: =IF($J$1="SEK / NOK",(VLOOKUP(A8,'RRP data'!A:C,3,FALSE)),(IF($J$1="DKK",(VLOOKUP('RRP data'!A8,'RRP data'!A:D,4,FALSE)),(IF($J$1="EUR",(VLOOKUP(A8,'RRP data'!A:E,5,FALSE))))))) -> 549 | M8: 1 | N8: 1 | P8: CN | Q8: 94018000 | R8: 44 | S8: 65 | T8: 54 | U8: 11 | V8: 46 | W8: 58 | X8: 66 | Y8: 14 | Z8: =PRODUCT(V8:X8)/1000000 -> 0.176088 | AA8: 30°
A9: 22150119 | B9: Axkid Minikid 3 Sea | C9: Sea Blue | D9: 7350057586754 | E9: Active | F9: Rear-facing car seat | G9: UN R129 | H9: 0-7 years | I9: 61-125cm (max 36kg) | J9: =$J$1 -> EUR | K9: =IF($J$1="SEK / NOK",(VLOOKUP(A9,'RRP data'!A:C,3,FALSE)),(IF($J$1="DKK",(VLOOKUP('RRP data'!A9,'RRP data'!A:D,4,FALSE)),(IF($J$1="EUR",(VLOOKUP(A9,'RRP data'!A:E,5,FALSE))))))) -> 549 | M9: 1 | N9: 1 | P9: CN | Q9: 94018000 | R9: 44 | S9: 65 | T9: 54 | U9: 11 | V9: 46 | W9: 58 | X9: 66 | Y9: 14 | Z9: =PRODUCT(V9:X9)/1000000 -> 0.176088 | AA9: 30°
A10: 22150120 | B10: Axkid Minikid 3 Moss | C10: Moss Green | D10: 7350057586761 | E10: Active | F10: Rear-facing car seat | G10: UN R129 | H10: 0-7 years | I10: 61-125cm (max 36kg) | J10: =$J$1 -> EUR | K10: =IF($J$1="SEK / NOK",(VLOOKUP(A10,'RRP data'!A:C,3,FALSE)),(IF($J$1="DKK",(VLOOKUP('RRP data'!A10,'RRP data'!A:D,4,FALSE)),(IF($J$1="EUR",(VLOOKUP(A10,'RRP data'!A:E,5,FALSE))))))) -> 549 | M10: 1 | N10: 1 | P10: CN | Q10: 94018000 | R10: 44 | S10: 65 | T10: 54 | U10: 11 | V10: 46 | W10: 58 | X10: 66 | Y10: 14 | Z10: =PRODUCT(V10:X10)/1000000 -> 0.176088 | AA10: 30°
A11: 22150121 | B11: Axkid Minikid 3 Premium Shell Black | C11: Shell black | D11: 7350057586778 | E11: Active | F11: Rear-facing car seat | G11: UN R129 | H11: 0-7 years | I11: 61-125cm (max 36kg) | J11: =$J$1 -> EUR | K11: =IF($J$1="SEK / NOK",(VLOOKUP(A11,'RRP data'!A:C,3,FALSE)),(IF($J$1="DKK",(VLOOKUP('RRP data'!A11,'RRP data'!A:D,4,FALSE)),(IF($J$1="EUR",(VLOOKUP(A11,'RRP data'!A:E,5,FALSE))))))) -> 599 | M11: 1 | N11: 1 | P11: CN | Q11: 94018000 | R11: 44 | S11: 65 | T11: 54 | U11: 11 | V11: 46 | W11: 58 | X11: 66 | Y11: 14 | Z11: =PRODUCT(V11:X11)/1000000 -> 0.176088 | AA11: 30°
A12: 22150122 | B12: Axkid Minikid 3 Premium Granite Melange | C12: Granite Grey Melange | D12: 7350057586785 | E12: Active | F12: Rear-facing car seat | G12: UN R129 | H12: 0-7 years | I12: 61-125cm (max 36kg) | J12: =$J$1 -> EUR | K12: =IF($J$1="SEK / NOK",(VLOOKUP(A12,'RRP data'!A:C,3,FALSE)),(IF($J$1="DKK",(VLOOKUP('RRP data'!A12,'RRP data'!A:D,4,FALSE)),(IF($J$1="EUR",(VLOOKUP(A12,'RRP data'!A:E,5,FALSE))))))) -> 599 | M12: 1 | N12: 1 | P12: CN | Q12: 94018000 | R12: 44 | S12: 65 | T12: 54 | U12: 11 | V12: 46 | W12: 58 | X12: 66 | Y12: 14 | Z12: =PRODUCT(V12:X12)/1000000 -> 0.176088 | AA12: 30°
A13: 22140316 | B13: Axkid Minikid 2 (2022/23) Tar | C13: Tar Black | D13: 7350057585870 | E13: Active | F13: Rear-facing car seat | G13: ECE R44 | H13: 0-7 years | I13: 0-25kg | J13: =$J$1 -> EUR | K13: =IF($J$1="SEK / NOK",(VLOOKUP(A13,'RRP data'!A:C,3,FALSE)),(IF($J$1="DKK",(VLOOKUP('RRP data'!A13,'RRP data'!A:D,4,FALSE)),(IF($J$1="EUR",(VLOOKUP(A13,'RRP data'!A:E,5,FALSE))))))) -> 429 | M13: 1 | N13: 1 | P13: CN | Q13: 94018000 | R13: 44 | S13: 62 | T13: 56 | U13: 11.4 | V13: 46 | W13: 58 | X13: 66 | Y13: 13.8 | Z13: =PRODUCT(V13:X13)/1000000 -> 0.176088 | AA13: 30°
A14: 22140317 | B14: Axkid Minikid 2 (2022/23) Granite | C14: Granite Grey | D14: 7350057585887 | E14: Active | F14: Rear-facing car seat | G14: ECE R44 | H14: 0-7 years | I14: 0-25kg | J14: =$J$1 -> EUR | K14: =IF($J$1="SEK / NOK",(VLOOKUP(A14,'RRP data'!A:C,3,FALSE)),(IF($J$1="DKK",(VLOOKUP('RRP data'!A14,'RRP data'!A:D,4,FALSE)),(IF($J$1="EUR",(VLOOKUP(A14,'RRP data'!A:E,5,FALSE))))))) -> 429 | M14: 1 | N14: 1 | P14: CN | Q14: 94018000 | R14: 44 | S14: 62 | T14: 56 | U14: 11.4 | V14: 46 | W14: 58 | X14: 66 | Y14: 13.8 | Z14: =PRODUCT(V14:X14)/1000000 -> 0.176088 | AA14: 30°
... A45: 24100021 | B45: Axkid Modukid Seat Premium Shell black | C45: Shell black | D45: 7350057584484 | E45: Active | F45: Rear-facing car seat | G45: UN R129 | H45: 6 months - 4 years | I45: 61-105cm (max 18kg) | J45: =$J$1 -> EUR | K45: =IF($J$1="SEK / NOK",(VLOOKUP(A45,'RRP data'!A:C,3,FALSE)),(IF($J$1="DKK",(VLOOKUP('RRP data'!A45,'RRP data'!A:D,4,FALSE)),(IF($J$1="EUR",(VLOOKUP(A45,'RRP data'!A:E,5,FALSE))))))) -> 275 | M45: 1 | N45: 1 | P45: CN | Q45: 94018000 | R45: 43 | S45: 62 | T45: 52 | U45: 7.5 | V45: 71 | W45: 47 | X45: 44 | Y45: 10.5 | Z45: =PRODUCT(V45:X45)/1000000 -> 0.146828 | AA45: 30°
A46: 24100022 | B46: Axkid Modukid Seat Premium Granite Melange | C46: Granite Melange | D46: 7350057584491 | E46: Active | F46: Rear-facing car seat | G46: UN R129 | H46: 6 months - 4 years | I46: 61-105cm (max 18kg) | J46: =$J$1 -> EUR | K46: =IF($J$1="SEK / NOK",(VLOOKUP(A46,'RRP data'!A:C,3,FALSE)),(IF($J$1="DKK",(VLOOKUP('RRP data'!A46,'RRP data'!A:D,4,FALSE)),(IF($J$1="EUR",(VLOOKUP(A46,'RRP data'!A:E,5,FALSE))))))) -> 275 | M46: 1 | N46: 1 | P46: CN | Q46: 94018000 | R46: k | S46: 62 | T46: 52 | U46: 7.5 | V46: 71 | W46: 47 | X46: 44 | Y46: 10.5 | Z46: =PRODUCT(V46:X46)/1000000 -> 0.146828 | AA46: 30°
A47: 24100023 | B47: Axkid Modukid Seat Premium Sky Grey | C47: Sky Grey | D47: 7350057584507 | E47: Active | F47: Rear-facing car seat | G47: UN R129 | H47: 6 months - 4 years | I47: 61-105cm (max 18kg) | J47: =$J$1 -> EUR | K47: =IF($J$1="SEK / NOK",(VLOOKUP(A47,'RRP data'!A:C,3,FALSE)),(IF($J$1="DKK",(VLOOKUP('RRP data'!A47,'RRP data'!A:D,4,FALSE)),(IF($J$1="EUR",(VLOOKUP(A47,'RRP data'!A:E,5,FALSE))))))) -> 275 | M47: 1 | N47: 1 | P47: CN | Q47: 94018000 | R47: 43 | S47: 62 | T47: 52 | U47: 7.5 | V47: 71 | W47: 47 | X47: 44 | Y47: 10.5 | Z47: =PRODUCT(V47:X47)/1000000 -> 0.146828 | AA47: 30°
A48: 21020003 | B48: Axkid Modukid Base | C48: Black | D48: 7350057582732 | E48: Active | F48: Base | G48: UN R129 | H48: n/a | I48: n/a | J48: =$J$1 -> EUR | K48: =IF($J$1="SEK / NOK",(VLOOKUP(A48,'RRP data'!A:C,3,FALSE)),(IF($J$1="DKK",(VLOOKUP('RRP data'!A48,'RRP data'!A:D,4,FALSE)),(IF($J$1="EUR",(VLOOKUP(A48,'RRP data'!A:E,5,FALSE))))))) -> 100 | M48: 1 | N48: 1 | P48: CN | Q48: 94018000 | R48: 43 | S48: 30 | T48: 65 | U48: 7 | V48: 61 | W48: 39 | X48: 23 | Y48: 8.8 | Z48: =PRODUCT(V48:X48)/1000000 -> 0.054717 | AA48: 30°
A49: 25110116 | B49: Axkid ONE 2 Tar | C49: Tar Black | D49: 7350057586648 | E49: Active | F49: Rear-facing car seat | G49: UN R129 | H49: 6 months - 7 years | I49: 61-125cm (max 23kg) | J49: =$J$1 -> EUR | K49: =IF($J$1="SEK / NOK",(VLOOKUP(A49,'RRP data'!A:C,3,FALSE)),(IF($J$1="DKK",(VLOOKUP('RRP data'!A49,'RRP data'!A:D,4,FALSE)),(IF($J$1="EUR",(VLOOKUP(A49,'RRP data'!A:E,5,FALSE))))))) -> 799 | M49: 1 | N49: 1 | P49: CN | Q49: 94018000 | R49: 44 | S49: 76 | T49: 54 | U49: 9.99 | V49: 87 | W49: 46 | X49: 52 | Y49: 16.3 | Z49: =PRODUCT(V49:X49)/1000000 -> 0.208104 | AA49: 30°
A50: 25110121 | B50: Axkid ONE 2 Granite Melange | C50: Granite Grey Melange | D50: 7350057586655 | E50: Active | F50: Rear-facing car seat | G50: UN R129 | H50: 6 months - 7 years | I50: 61-125cm (max 23kg) | J50: =$J$1 -> EUR | K50: =IF($J$1="SEK / NOK",(VLOOKUP(A50,'RRP data'!A:C,3,FALSE)),(IF($J$1="DKK",(VLOOKUP('RRP data'!A50,'RRP data'!A:D,4,FALSE)),(IF($J$1="EUR",(VLOOKUP(A50,'RRP data'!A:E,5,FALSE))))))) -> 799 | M50: 1 | N50: 1 | P50: CN | Q50: 94018000 | R50: 44 | S50: 76 | T50: 54 | U50: 9.99 | V50: 87 | W50: 46 | X50: 52 | Y50: 16.3 | Z50: =PRODUCT(V50:X50)/1000000 -> 0.208104 | AA50: 30°
A51: 25110124 | B51: Axkid ONE 2 Brick Melange | C51: Brick Beige Melange | D51: 7350057586662 | E51: Active | F51: Rear-facing car seat | G51: UN R129 | H51: 6 months - 7 years | I51: 61-125cm (max 23kg) | J51: =$J$1 -> EUR | K51: =IF($J$1="SEK / NOK",(VLOOKUP(A51,'RRP data'!A:C,3,FALSE)),(IF($J$1="DKK",(VLOOKUP('RRP data'!A51,'RRP data'!A:D,4,FALSE)),(IF($J$1="EUR",(VLOOKUP(A51,'RRP data'!A:E,5,FALSE))))))) -> 799 | M51: 1 | N51: 1 | P51: CN | Q51: 94018000 | R51: 44 | S51: 76 | T51: 54 | U51: 9.99 | V51: 87 | W51: 46 | X51: 52 | Y51: 16.3 | Z51: =PRODUCT(V51:X51)/1000000 -> 0.208104 | AA51: 30°
A52: 25110125 | B52: Axkid ONE 2 Tile Melange | C52: Tile Red Melange | D52: 7350057586679 | E52: Active | F52: Rear-facing car seat | G52: UN R129 | H52: 6 months - 7 years | I52: 61-125cm (max 23kg) | J52: =$J$1 -> EUR | K52: =IF($J$1="SEK / NOK",(VLOOKUP(A52,'RRP data'!A:C,3,FALSE)),(IF($J$1="DKK",(VLOOKUP('RRP data'!A52,'RRP data'!A:D,4,FALSE)),(IF($J$1="EUR",(VLOOKUP(A52,'RRP data'!A:E,5,FALSE))))))) -> 799 | M52: 1 | N52: 1 | P52: CN | Q52: 94018000 | R52: 44 | S52: 76 | T52: 54 | U52: 9.99 | V52: 87 | W52: 46 | X52: 52 | Y52: 16.3 | Z52: =PRODUCT(V52:X52)/1000000 -> 0.208104 | AA52: 30°
A53: 25120116 | B53: Axkid ONE+ 2 Tar | C53: Tar Black | D53: 7350057586686 | E53: Active | F53: Rear-facing car seat | G53: UN R129 | H53: 0-7 years | I53: 40-125cm (max 23kg) | J53: =$J$1 -> EUR | K53: =IF($J$1="SEK / NOK",(VLOOKUP(A53,'RRP data'!A:C,3,FALSE)),(IF($J$1="DKK",(VLOOKUP('RRP data'!A53,'RRP data'!A:D,4,FALSE)),(IF($J$1="EUR",(VLOOKUP(A53,'RRP data'!A:E,5,FALSE))))))) -> 849 | M53: 1 | N53: 1 | P53: CN | Q53: 94018000 | R53: 44 | S53: 76 | T53: 54 | U53: 9.99 | V53: 87 | W53: 46 | X53: 52 | Y53: 16.7 | Z53: =PRODUCT(V53:X53)/1000000 -> 0.208104 | AA53: 30°
A54: 25120121 | B54: Axkid ONE+ 2 Granite Melange | C54: Granite Grey Melange | D54: 7350057586693 | E54: Active | F54: Rear-facing car seat | G54: UN R129 | H54: 0-7 years | I54: 40-125cm (max 23kg) | J54: =$J$1 -> EUR | K54: =IF($J$1="SEK / NOK",(VLOOKUP(A54,'RRP data'!A:C,3,FALSE)),(IF($J$1="DKK",(VLOOKUP('RRP data'!A54,'RRP data'!A:D,4,FALSE)),(IF($J$1="EUR",(VLOOKUP(A54,'RRP data'!A:E,5,FALSE))))))) -> 849 | M54: 1 | N54: 1 | P54: CN | Q54: 94018000 | R54: 44 | S54: 76 | T54: 54 | U54: 9.99 | V54: 87 | W54: 46 | X54: 52 | Y54: 16.7 | Z54: =PRODUCT(V54:X54)/1000000 -> 0.208104 | AA54: 30°
A55: 25120124 | B55: Axkid ONE+ 2 Brick Melange | C55: Brick Beige Melange | D55: 7350057586709 | E55: Active | F55: Rear-facing car seat | G55: UN R129 | H55: 0-7 years | I55: 40-125cm (max 23kg) | J55: =$J$1 -> EUR | K55: =IF($J$1="SEK / NOK",(VLOOKUP(A55,'RRP data'!A:C,3,FALSE)),(IF($J$1="DKK",(VLOOKUP('RRP data'!A55,'RRP data'!A:D,4,FALSE)),(IF($J$1="EUR",(VLOOKUP(A55,'RRP data'!A:E,5,FALSE))))))) -> 849 | M55: 1 | N55: 1 | P55: CN | Q55: 94018000 | R55: 44 | S55: 76 | T55: 54 | U55: 9.99 | V55: 87 | W55: 46 | X55: 52 | Y55: 16.7 | Z55: =PRODUCT(V55:X55)/1000000 -> 0.208104 | AA55: 30°
A56: 25120125 | B56: Axkid ONE+ 2 Tile Melange | C56: Tile Red Melange | D56: 7350057586716 | E56: Active | F56: Rear-facing car seat | G56: UN R129 | H56: 0-7 years | I56: 40-125cm (max 23kg) | J56: =$J$1 -> EUR | K56: =IF($J$1="SEK / NOK",(VLOOKUP(A56,'RRP data'!A:C,3,FALSE)),(IF($J$1="DKK",(VLOOKUP('RRP data'!A56,'RRP data'!A:D,4,FALSE)),(IF($J$1="EUR",(VLOOKUP(A56,'RRP data'!A:E,5,FALSE))))))) -> 849 | M56: 1 | N56: 1 | P56: CN | Q56: 94018000 | R56: 44 | S56: 76 | T56: 54 | U56: 9.99 | V56: 87 | W56: 46 | X56: 52 | Y56: 16.7 | Z56: =PRODUCT(V56:X56)/1000000 -> 0.208104 | AA56: 30°
A57: 25110016 | B57: Axkid ONE Tar | C57: Tar | D57: 7350057584590 | E57: Discontinued | F57: Rear-facing car seat | G57: UN R129 | H57: 6 months - 7 years | I57: 61-125cm (max 23kg) | J57: =$J$1 -> EUR | K57: =IF($J$1="SEK / NOK",(VLOOKUP(A57,'RRP data'!A:C,3,FALSE)),(IF($J$1="DKK",(VLOOKUP('RRP data'!A57,'RRP data'!A:D,4,FALSE)),(IF($J$1="EUR",(VLOOKUP(A57,'RRP data'!A:E,5,FALSE))))))) -> 749 | M57: 1 | N57: 1 | P57: CN | Q57: 94018000 | R57: 44 | S57: 76 | T57: 54 | U57: 9.99 | V57: 82 | W57: 46 | X57: 60 | Y57: 16.3 | Z57: =PRODUCT(V57:X57)/1000000 -> 0.22632 | AA57: 30°
A58: 25110021 | B58: Axkid ONE Granite Melange | C58: Granite Melange | D58: 7350057584606 | E58: Discontinued | F58: Rear-facing car seat | G58: UN R129 | H58: 6 months - 7 years | I58: 61-125cm (max 23kg) | J58: =$J$1 -> EUR | K58: =IF($J$1="SEK / NOK",(VLOOKUP(A58,'RRP data'!A:C,3,FALSE)),(IF($J$1="DKK",(VLOOKUP('RRP data'!A58,'RRP data'!A:D,4,FALSE)),(IF($J$1="EUR",(VLOOKUP(A58,'RRP data'!A:E,5,FALSE))))))) -> 749 | M58: 1 | N58: 1 | P58: CN | Q58: 94018000 | R58: 44 | S58: 76 | T58: 54 | U58: 9.99 | V58: 82 | W58: 46 | X58: 60 | Y58: 16.3 | Z58: =PRODUCT(V58:X58)/1000000 -> 0.22632 | AA58: 30°
... A90: 801403 | B90: Axkid Angle adjusting wedge | C90: Black | D90: 7350057581087 | E90: Active | F90: Accessory | G90: EN1888 | H90: - | I90: - | J90: =$J$1 -> EUR | K90: =IF($J$1="SEK / NOK",(VLOOKUP(A90,'RRP data'!A:C,3,FALSE)),(IF($J$1="DKK",(VLOOKUP('RRP data'!A90,'RRP data'!A:D,4,FALSE)),(IF($J$1="EUR",(VLOOKUP(A90,'RRP data'!A:E,5,FALSE))))))) -> 17 | M90: 40 | N90: 1 | P90: CN | Q90: 94019990 | R90: 16.5 | S90: 23 | T90: 7.5 | U90: 0.263 | V90: 30 | W90: 8 | X90: 20 | Y90: 0.44 | Z90: =PRODUCT(V90:X90)/1000000 -> 0.0048 | AA90: Not washable
A91: 803303 | B91: Axkid Baby mirror | C91: Black | D91: 7350057581339 | E91: Active | F91: Accessory | G91: EN1888 | H91: - | I91: - | J91: =$J$1 -> EUR | K91: =IF($J$1="SEK / NOK",(VLOOKUP(A91,'RRP data'!A:C,3,FALSE)),(IF($J$1="DKK",(VLOOKUP('RRP data'!A91,'RRP data'!A:D,4,FALSE)),(IF($J$1="EUR",(VLOOKUP(A91,'RRP data'!A:E,5,FALSE))))))) -> 19 | M91: 10 | N91: 1 | P91: CN | Q91: 94019990 | R91: 21.5 | S91: 17.5 | U91: 0.71 | V91: 30 | W91: 8 | X91: 20 | Y91: 1.05 | Z91: =PRODUCT(V91:X91)/1000000 -> 0.0048 | AA91: Not washable
A92: 803803 | B92: Axkid Seat protection Premium | C92: Black | D92: 7350057582008 | E92: Active | F92: Accessory | G92: EN1888 | H92: - | I92: - | J92: =$J$1 -> EUR | K92: =IF($J$1="SEK / NOK",(VLOOKUP(A92,'RRP data'!A:C,3,FALSE)),(IF($J$1="DKK",(VLOOKUP('RRP data'!A92,'RRP data'!A:D,4,FALSE)),(IF($J$1="EUR",(VLOOKUP(A92,'RRP data'!A:E,5,FALSE))))))) -> 50 | M92: 10 | N92: 1 | P92: CN | Q92: 94019990 | R92: 122 | S92: 47 | T92: 1 | U92: 0.5 | V92: 29.5 | W92: 8 | X92: 58 | Y92: 1 | Z92: =PRODUCT(V92:X92)/1000000 -> 0.013688 | AA92: Not washable
A93: 803906 | B93: Axkid Sunshades for window self attaching | C93: Grey | D93: 7350057582015 | E93: Active | F93: Accessory | G93: EN1888 | H93: - | I93: - | J93: =$J$1 -> EUR | K93: =IF($J$1="SEK / NOK",(VLOOKUP(A93,'RRP data'!A:C,3,FALSE)),(IF($J$1="DKK",(VLOOKUP('RRP data'!A93,'RRP data'!A:D,4,FALSE)),(IF($J$1="EUR",(VLOOKUP(A93,'RRP data'!A:E,5,FALSE))))))) -> 9 | M93: 48 | N93: 1 | P93: CN | Q93: 94019990 | R93: 38 | S93: 44 | T93: 0.2 | U93: 0.16 | V93: 18 | W93: 6 | X93: 16 | Y93: 0.33 | Z93: =PRODUCT(V93:X93)/1000000 -> 0.001728 | AA93: Not washable
A94: 804003 | B94: Axkid iPad holder | C94: Black | D94: 7350057582022 | E94: Active | F94: Accessory | G94: EN1888 | H94: - | I94: - | J94: =$J$1 -> EUR | K94: =IF($J$1="SEK / NOK",(VLOOKUP(A94,'RRP data'!A:C,3,FALSE)),(IF($J$1="DKK",(VLOOKUP('RRP data'!A94,'RRP data'!A:D,4,FALSE)),(IF($J$1="EUR",(VLOOKUP(A94,'RRP data'!A:E,5,FALSE))))))) -> 18 | M94: 20 | N94: 1 | P94: CN | Q94: 94019990 | R94: 27.5 | S94: 19.5 | T94: 2 | U94: 0.24 | V94: 30 | W94: 8 | X94: 20 | Y94: 0.45 | Z94: =PRODUCT(V94:X94)/1000000 -> 0.0048 | AA94: Not washable
A95: 804103 | B95: Axkid Backseat organizer | C95: Black | D95: 7350057582039 | E95: Active | F95: Accessory | G95: EN1888 | H95: - | I95: - | J95: =$J$1 -> EUR | K95: =IF($J$1="SEK / NOK",(VLOOKUP(A95,'RRP data'!A:C,3,FALSE)),(IF($J$1="DKK",(VLOOKUP('RRP data'!A95,'RRP data'!A:D,4,FALSE)),(IF($J$1="EUR",(VLOOKUP(A95,'RRP data'!A:E,5,FALSE))))))) -> 19 | M95: 20 | N95: 1 | P95: CN | Q95: 94019990 | R95: 42.5 | S95: 57 | T95: 1 | U95: 0.16 | V95: 23.5 | W95: 7 | X95: 37 | Y95: 0.16 | Z95: =PRODUCT(V95:X95)/1000000 -> 0.0060865 | AA95: Not washable
A96: 804303 | B96: Axkid Tether straps for Move | C96: Black | D96: 7350057582060 | E96: Active | F96: Accessory | G96: EN1888 | H96: - | I96: - | J96: =$J$1 -> EUR | K96: =IF($J$1="SEK / NOK",(VLOOKUP(A96,'RRP data'!A:C,3,FALSE)),(IF($J$1="DKK",(VLOOKUP('RRP data'!A96,'RRP data'!A:D,4,FALSE)),(IF($J$1="EUR",(VLOOKUP(A96,'RRP data'!A:E,5,FALSE))))))) -> 29 | M96: 100 | N96: 1 | P96: CN | Q96: 94019990 | R96: 4 | S96: 133 | T96: 0.2 | U96: 0.14 | V96: 18 | W96: 6 | X96: 16 | Y96: 0.15 | Z96: =PRODUCT(V96:X96)/1000000 -> 0.001728 | AA96: Not washable
A97: 804403 | B97: Axkid Swedish safety kit | C97: Black | D97: 7350057582121 | E97: Active | F97: Accessory | G97: EN1888 | H97: - | I97: - | J97: =$J$1 -> EUR | K97: =IF($J$1="SEK / NOK",(VLOOKUP(A97,'RRP data'!A:C,3,FALSE)),(IF($J$1="DKK",(VLOOKUP('RRP data'!A97,'RRP data'!A:D,4,FALSE)),(IF($J$1="EUR",(VLOOKUP(A97,'RRP data'!A:E,5,FALSE))))))) -> 55 | M97: 1 | N97: 1 | P97: CN | Q97: 94019990 | R97: - | S97: - | T97: - | U97: 1.5 | V97: 29.5 | W97: 8 | X97: 58 | Y97: 2 | Z97: =PRODUCT(V97:X97)/1000000 -> 0.013688 | AA97: Not washable
A98: 804503 | B98: Axkid Sun cover (seat sunshade) | C98: Black | D98: 7350057582749 | E98: Active | F98: Accessory | G98: EN1888 | H98: - | I98: - | J98: =$J$1 -> EUR | K98: =IF($J$1="SEK / NOK",(VLOOKUP(A98,'RRP data'!A:C,3,FALSE)),(IF($J$1="DKK",(VLOOKUP('RRP data'!A98,'RRP data'!A:D,4,FALSE)),(IF($J$1="EUR",(VLOOKUP(A98,'RRP data'!A:E,5,FALSE))))))) -> 35 | M98: 40 | N98: 1 | P98: CN | Q98: 94019990 | R98: 41 | S98: 21 | T98: 47 | U98: 0.3 | V98: 30 | W98: 8 | X98: 20 | Y98: 0.61 | Z98: =PRODUCT(V98:X98)/1000000 -> 0.0048 | AA98: Not washable
A99: 804603 | B99: Axkid Support leg adapter | C99: Black | D99: 7350057582756 | E99: Active | F99: Accessory | G99: EN1888 | H99: - | I99: - | J99: =$J$1 -> EUR | K99: =IF($J$1="SEK / NOK",(VLOOKUP(A99,'RRP data'!A:C,3,FALSE)),(IF($J$1="DKK",(VLOOKUP('RRP data'!A99,'RRP data'!A:D,4,FALSE)),(IF($J$1="EUR",(VLOOKUP(A99,'RRP data'!A:E,5,FALSE))))))) -> 29 | M99: 10 | N99: 1 | P99: CN | Q99: 94019990 | R99: 8 | S99: 27.5 | T99: 3.5 | U99: 0.5 | V99: 30 | W99: 8 | X99: 20 | Y99: 0.8 | Z99: =PRODUCT(V99:X99)/1000000 -> 0.0048 | AA99: Not washable
A100: 804916 | B100: Axkid Connect | C100: Tar Black | D100: 7350057584347 | E100: Active | F100: Accessory | G100: EN1888 | H100: - | I100: - | J100: =$J$1 -> EUR | K100: =IF($J$1="SEK / NOK",(VLOOKUP(A100,'RRP data'!A:C,3,FALSE)),(IF($J$1="DKK",(VLOOKUP('RRP data'!A100,'RRP data'!A:D,4,FALSE)),(IF($J$1="EUR",(VLOOKUP(A100,'RRP data'!A:E,5,FALSE))))))) -> 99 | M100: 1 | N100: 1 | P100: CN | Q100: 94019990 | R100: 21 | S100: 1.5 | T100: 17 | U100: 0.4 | V100: 23.5 | W100: 3.8 | X100: 19.3 | Y100: 0.8 | Z100: =PRODUCT(V100:X100)/1000000 -> 0.00172349 | AA100: Not washable
A101: 805006 | B101: Axkid Bamboo Summer cover Minikid 2 | C101: White | D101: 7350057584798 | E101: Active | F101: Accessory | G101: EN1888 | H101: - | I101: - | J101: =$J$1 -> EUR | K101: =IF($J$1="SEK / NOK",(VLOOKUP(A101,'RRP data'!A:C,3,FALSE)),(IF($J$1="DKK",(VLOOKUP('RRP data'!A101,'RRP data'!A:D,4,FALSE)),(IF($J$1="EUR",(VLOOKUP(A101,'RRP data'!A:E,5,FALSE))))))) -> 50 | M101: 1 | N101: 1 | P101: CN | Q101: 94019990 | R101: 85 | S101: 45 | T101: 0.2 | U101: 0.2 | V101: 7 | W101: 20 | X101: 30 | Y101: 0.25 | Z101: =PRODUCT(V101:X101)/1000000 -> 0.0042 | AA101: 30°
...

Sheet RRP data
A1: Item number | B1: Name | C1: SEK/NOK | D1: DKK | E1: EUR | AB1: SEK / NOK
A2: 200302 | B2: =VLOOKUP(Table2[[#This Row],[Item number]],'Axkid Template'!A:C,2,FALSE) -> #N/A | C2: 1499 | D2: 999 | E2: 149 | AB2: DKK
A3: 200303 | B3: =VLOOKUP(Table2[[#This Row],[Item number]],'Axkid Template'!A:C,2,FALSE) -> #N/A | C3: 1499 | D3: 999 | E3: 149 | AB3: EUR
A4: 210103 | B4: =VLOOKUP(Table2[[#This Row],[Item number]],'Axkid Template'!A:C,2,FALSE) -> Axkid Babyfix Base Black | C4: 1000 | D4: 500 | E4: 100
A5: 22140201 | B5: =VLOOKUP(Table2[[#This Row],[Item number]],'Axkid Template'!A:C,2,FALSE) -> #N/A | C5: 3999 | D5: 2999 | E5: 399
A6: 22140202 | B6: =VLOOKUP(Table2[[#This Row],[Item number]],'Axkid Template'!A:C,2,FALSE) -> #N/A | C6: 3999 | D6: 2999 | E6: 399
A7: 22140203 | B7: =VLOOKUP(Table2[[#This Row],[Item number]],'Axkid Template'!A:C,2,FALSE) -> #N/A | C7: 3999 | D7: 2999 | E7: 399
A8: 22140210 | B8: =VLOOKUP(Table2[[#This Row],[Item number]],'Axkid Template'!A:C,2,FALSE) -> #N/A | C8: 3999 | D8: 2999 | E8: 399
A9: 22140211 | B9: =VLOOKUP(Table2[[#This Row],[Item number]],'Axkid Template'!A:C,2,FALSE) -> #N/A | C9: 3999 | D9: 2999 | E9: 399
A10: 22140213 | B10: =VLOOKUP(Table2[[#This Row],[Item number]],'Axkid Template'!A:C,2,FALSE) -> #N/A | C10: 3999 | D10: 2999 | E10: 399
A11: 22120102 | B11: =VLOOKUP(Table2[[#This Row],[Item number]],'Axkid Template'!A:C,2,FALSE) -> Axkid Move Grey | C11: 2999 | D11: 1799 | E11: 279
A12: 22120103 | B12: =VLOOKUP(Table2[[#This Row],[Item number]],'Axkid Template'!A:C,2,FALSE) -> Axkid Move Black | C12: 2999 | D12: 1799 | E12: 279
A13: 20040001 | B13: =VLOOKUP(Table2[[#This Row],[Item number]],'Axkid Template'!A:C,2,FALSE) -> #N/A | C13: 1999 | D13: 1450 | E13: 199
A14: 20040002 | B14: =VLOOKUP(Table2[[#This Row],[Item number]],'Axkid Template'!A:C,2,FALSE) -> #N/A | C14: 1999 | D14: 1450 | E14: 199
A15: 20040003 | B15: =VLOOKUP(Table2[[#This Row],[Item number]],'Axkid Template'!A:C,2,FALSE) -> #N/A | C15: 1999 | D15: 1450 | E15: 199
... A17: 20040013 | B17: =VLOOKUP(Table2[[#This Row],[Item number]],'Axkid Template'!A:C,2,FALSE) -> #N/A | C17: 1999 | D17: 1450 | E17: 199
A18: 21020003 | B18: =VLOOKUP(Table2[[#This Row],[Item number]],'Axkid Template'!A:C,2,FALSE) -> Axkid Modukid Base | C18: 2499 | D18: - | E18: 100
A19: 24100001 | B19: =VLOOKUP(Table2[[#This Row],[Item number]],'Axkid Template'!A:C,2,FALSE) -> #N/A | C19: 3499 | D19: 2599 | E19: 349
A20: 24100002 | B20: =VLOOKUP(Table2[[#This Row],[Item number]],'Axkid Template'!A:C,2,FALSE) -> #N/A | C20: 3499 | D20: 2599 | E20: 349
A21: 24100003 | B21: =VLOOKUP(Table2[[#This Row],[Item number]],'Axkid Template'!A:C,2,FALSE) -> #N/A | C21: 3499 | D21: 2599 | E21: 349
A22: 24100011 | B22: =VLOOKUP(Table2[[#This Row],[Item number]],'Axkid Template'!A:C,2,FALSE) -> #N/A | C22: 3499 | D22: 2599 | E22: 349
A23: 24100013 | B23: =VLOOKUP(Table2[[#This Row],[Item number]],'Axkid Template'!A:C,2,FALSE) -> #N/A | C23: 3499 | D23: 2599 | E23: 349
A24: 260301 | B24: =VLOOKUP(Table2[[#This Row],[Item number]],'Axkid Template'!A:C,2,FALSE) -> Axkid Rekid Red | C24: 4999 | D24: 3999 | E24: 469
A25: 260302 | B25: =VLOOKUP(Table2[[#This Row],[Item number]],'Axkid Template'!A:C,2,FALSE) -> Axkid Rekid Grey | C25: 4999 | D25: 3999 | E25: 469
A26: 260303 | B26: =VLOOKUP(Table2[[#This Row],[Item number]],'Axkid Template'!A:C,2,FALSE) -> Axkid Rekid Black | C26: 4999 | D26: 3999 | E26: 469
A27: 260311 | B27: =VLOOKUP(Table2[[#This Row],[Item number]],'Axkid Template'!A:C,2,FALSE) -> Axkid Rekid Petrol | C27: 4999 | D27: 3999 | E27: 469
A28: 27040002 | B28: =VLOOKUP(Table2[[#This Row],[Item number]],'Axkid Template'!A:C,2,FALSE) -> #N/A | C28: 2399 | D28: 1699 | E28: 239
A29: 27040003 | B29: =VLOOKUP(Table2[[#This Row],[Item number]],'Axkid Template'!A:C,2,FALSE) -> #N/A | C29: 2399 | D29: 1699 | E29: 239
A30: 26040002 | B30: =VLOOKUP(Table2[[#This Row],[Item number]],'Axkid Template'!A:C,2,FALSE) -> Axkid Bigkid Grey | C30: 1899 | D30: 1399 | E30: 189
... A37: 800507 | B37: =VLOOKUP(Table2[[#This Row],[Item number]],'Axkid Template'!A:C,2,FALSE) -> Axkid Baby on board sign | C37: 99 | D37: 45 | E37: 19
A38: 800608 | B38: =VLOOKUP(Table2[[#This Row],[Item number]],'Axkid Template'!A:C,2,FALSE) -> Axkid Attachment loops | C38: 199 | D38: - | E38: 19.9
A39: 800803 | B39: =VLOOKUP(Table2[[#This Row],[Item number]],'Axkid Template'!A:C,2,FALSE) -> Axkid Baby cushion | C39: 199 | D39: 109 | E39: 19
A40: 801003 | B40: =VLOOKUP(Table2[[#This Row],[Item number]],'Axkid Template'!A:C,2,FALSE) -> Axkid Adapter babyfix | C40: 249 | D40: 189 | E40: 19
A41: 801106 | B41: =VLOOKUP(Table2[[#This Row],[Item number]],'Axkid Template'!A:C,2,FALSE) -> Axkid Summer cover Minikid, rekid & Modukid seat | C41: 249 | D41: 199 | E41: 19
A42: 801206 | B42: =VLOOKUP(Table2[[#This Row],[Item number]],'Axkid Template'!A:C,2,FALSE) -> Axkid Summer cover Dallas/Grow | C42: 249 | D42: 199 | E42: 19
A43: 801403 | B43: =VLOOKUP(Table2[[#This Row],[Item number]],'Axkid Template'!A:C,2,FALSE) -> Axkid Angle adjusting wedge | C43: 169 | D43: 129 | E43: 17
A44: 803303 | B44: =VLOOKUP(Table2[[#This Row],[Item number]],'Axkid Template'!A:C,2,FALSE) -> Axkid Baby mirror | C44: 299 | D44: 149 | E44: 19
A45: 803803 | B45: =VLOOKUP(Table2[[#This Row],[Item number]],'Axkid Template'!A:C,2,FALSE) -> Axkid Seat protection Premium | C45: 649 | D45: 349 | E45: 50
A46: 803906 | B46: =VLOOKUP(Table2[[#This Row],[Item number]],'Axkid Template'!A:C,2,FALSE) -> Axkid Sunshades for window self attaching | C46: 199 | D46: 75 | E46: 9
A47: 804003 | B47: =VLOOKUP(Table2[[#This Row],[Item number]],'Axkid Template'!A:C,2,FALSE) -> Axkid iPad holder | C47: 199 | D47: 129 | E47: 18
...

Sheet Axkid Template - SE
A1: Axkid Template | J1: SEK / NOK | Q1: Produkt storlek | T1: Kartongstorlek
A2: Artikel Namn | B2: Artikel Nummer | C2: Färg | D2: EAN kod | E2: Modell | F2: Modell beskrivning | G2: Rekommenderad ålder | H2: Grupp | I2: Maxvikt | J2: Valuta | K2: Rek Pris | L2: Inköpskvantitet | M2: Försäljningskvantitet | N2: Beskrivning | O2: Ursprungsland | P2: Intrastat nummer | Q2: Bredd i CM | R2: Höjd i CM | S2: Djup i CM | T2: Längd i CM | U2: Bredd i CM | V2: Höjd i CM | W2: Brutto vikt | X2: Netto vikt | Y2: Tvättbar | Z2: Egenskaper
A3: Axkid Babyfix Grå | B3: 200302 | C3: Grå | D3: 7350057581933 | E3: 0-13KG | F3: Babyskydd ECE R44 | G3: - | I3: 13kg | J3: =$J$1 -> SEK / NOK | K3: =IF(J3="SEK / NOK",(VLOOKUP(B3,'RRP data'!A:E,2,FALSE)),(IF(J3="DKK",(VLOOKUP('Axkid Template - SE'!B3,'RRP data'!A:E,4,FALSE)),(IF(J3="EUR",(VLOOKUP(B3,'RRP data'!A:E,5,FALSE))))))) -> #N/A | L3: 1 | M3: 1 | N3: Babyskyddet Axkid Babyfix ger maximal säkerhet och trygghet för det nyfödda barnet under de första månaderna i livet. Att det också är ett av marknadens lättaste babyskydd med en vikt på 3,5 kg gör inte saken sämre. Nackkudden tillsammans med de mjuka axelmuddarna gör resan bekväm för ditt barn. En extra urtagbar babydyna levereras med babyskyddet, för de allra minsta. Axkid Babyfix är godkänd 0–13 kg enligt ECE R44/04. Vi rekommenderar alltid att börja med babyskyddet eftersom det är bäst anpassat för de allra minsta. När ditt barn växt ur babyskyddet är det dags att byta till en bakåtvänd bilbarnstol. Axkid Babyfix installerar du smidigast med Axkid Babyfix Bas. Basen installerar du antingen med bilens trepunktsbälte eller med ISOFIX. Med ett enkelt klick tar du babyskyddet i eller ur bilen och ditt barn kan tryggt sova vidare i Axkid Babyfix. Väljer du att installera Axkid Babyfix utan bas använder du dig av bilens trepunktsbälte. När babyskyddet inte är installerat i bilen kan det användas som gungstol, matstol eller babysitter tack vare att handtaget kan justeras i fem olika lägen. Solskyddet har en extra utvikningsbar skärm för att skydda ditt barn från solens starka strålar. | O3: CN | P3: 94018000 | Q3: 43 | R3: 54 | S3: 65 | T3: 45 | U3: 58 | V3: 67 | W3: 5.79 | X3: 3.4 | Y3: 30° | Z3: Best Budget Choice - Bäst-i-test.se
A4: Axkid Babyfix Svart | B4: 200303 | C4: Svart | D4: 7350057581940 | E4: 0-13KG | F4: Babyskydd ECE R44 | G4: - | I4: 13kg | J4: =$J$1 -> SEK / NOK | K4: =IF(J4="SEK / NOK",(VLOOKUP(B4,'RRP data'!A:E,2,FALSE)),(IF(J4="DKK",(VLOOKUP('Axkid Template - SE'!B4,'RRP data'!A:E,4,FALSE)),(IF(J4="EUR",(VLOOKUP(B4,'RRP data'!A:E,5,FALSE))))))) -> #N/A | L4: 1 | M4: 1 | N4: Babyskyddet Axkid Babyfix ger maximal säkerhet och trygghet för det nyfödda barnet under de första månaderna i livet. Att det också är ett av marknadens lättaste babyskydd med en vikt på 3,5 kg gör inte saken sämre. Nackkudden tillsammans med de mjuka axelmuddarna gör resan bekväm för ditt barn. En extra urtagbar babydyna levereras med babyskyddet, för de allra minsta. Axkid Babyfix är godkänd 0–13 kg enligt ECE R44/04. Vi rekommenderar alltid att börja med babyskyddet eftersom det är bäst anpassat för de allra minsta. När ditt barn växt ur babyskyddet är det dags att byta till en bakåtvänd bilbarnstol. Axkid Babyfix installerar du smidigast med Axkid Babyfix Bas. Basen installerar du antingen med bilens trepunktsbälte eller med ISOFIX. Med ett enkelt klick tar du babyskyddet i eller ur bilen och ditt barn kan tryggt sova vidare i Axkid Babyfix. Väljer du att installera Axkid Babyfix utan bas använder du dig av bilens trepunktsbälte. När babyskyddet inte är installerat i bilen kan det användas som gungstol, matstol eller babysitter tack vare att handtaget kan justeras i fem olika lägen. Solskyddet har en extra utvikningsbar skärm för att skydda ditt barn från solens starka strålar. | O4: CN | P4: 94018000 | Q4: 43 | R4: 54 | S4: 65 | T4: 45 | U4: 58 | V4: 67 | W4: 5.79 | X4: 3.4 | Y4: 30° | Z4: Best Budget Choice - Bäst-i-test.se
A5: Axkid Babyfix Bas Svart | B5: 210103 | C5: Svart | D5: 7350057580042 | E5: ISOFIX BAS | F5: Bas till Babyskydd ECE R44 | G5: - | I5: 13kg | J5: =$J$1 -> SEK / NOK | K5: =IF(J5="SEK / NOK",(VLOOKUP(B5,'RRP data'!A:E,2,FALSE)),(IF(J5="DKK",(VLOOKUP('Axkid Template - SE'!B5,'RRP data'!A:E,4,FALSE)),(IF(J5="EUR",(VLOOKUP(B5,'RRP data'!A:E,5,FALSE))))))) -> Axkid Babyfix Base Black | L5: 1 | M5: 1 | N5: Babyskyddet Axkid Babyfix ger maximal säkerhet och trygghet för det nyfödda barnet under de första månaderna i livet. Att det också är ett av marknadens lättaste babyskydd med en vikt på 3,5 kg gör inte saken sämre. Nackkudden tillsammans med de mjuka axelmuddarna gör resan bekväm för ditt barn. En extra urtagbar babydyna levereras med babyskyddet, för de allra minsta. Axkid Babyfix är godkänd 0–13 kg enligt ECE R44/04. Vi rekommenderar alltid att börja med babyskyddet eftersom det är bäst anpassat för de allra minsta. När ditt barn växt ur babyskyddet är det dags att byta till en bakåtvänd bilbarnstol. Axkid Babyfix installerar du smidigast med Axkid Babyfix Bas. Basen installerar du antingen med bilens trepunktsbälte eller med ISOFIX. Med ett enkelt klick tar du babyskyddet i eller ur bilen och ditt barn kan tryggt sova vidare i Axkid Babyfix. Väljer du att installera Axkid Babyfix utan bas använder du dig av bilens trepunktsbälte. När babyskyddet inte är installerat i bilen kan det användas som gungstol, matstol eller babysitter tack vare att handtaget kan justeras i fem olika lägen. Solskyddet har en extra utvikningsbar skärm för att skydda ditt barn från solens starka strålar. | O5: CN | P5: 94018000 | Q5: 33 | R5: 43 | S5: 69 | T5: 34 | U5: 20 | V5: 60.5 | W5: 5.45 | X5: 4.63 | Y5: 30° | Z5: Best Budget Choice - Bäst-i-test.se
A6: Axkid Minikid Röd | B6: 22140201 | C6: Röd | D6: 7350057582350 | E6: 0-25KG | F6: Bilbarnstol ECE R44 | G6: - | I6: 25kg | J6: =$J$1 -> SEK / NOK | K6: =IF(J6="SEK / NOK",(VLOOKUP(B6,'RRP data'!A:E,2,FALSE)),(IF(J6="DKK",(VLOOKUP('Axkid Template - SE'!B6,'RRP data'!A:E,4,FALSE)),(IF(J6="EUR",(VLOOKUP(B6,'RRP data'!A:E,5,FALSE))))))) -> #N/A | L6: 1 | M6: 1 | N6: Den bakåtvända bilbarnstolen, Axkid Minikid 2018, är framtagen för att ge bästa möjliga säkerhet och komfort för både små och stora barn, och möjliggör bakåtvänt åkande så länge som möjligt. Nya Axkid Minikid levereras med det innovativa sidokrocksskyddet – ASIP (Axkid Side Impact Protection) som är framtaget tillsammans med ett erkänt krockinstitiut i Tyskland, och ger bästa möjliga skydd för barnet vid eventuell krock från sidan. ASIP ska användas på den sidan av bilbarnstolen som är ut mot bildörren, vid användning i mitten behöver inte ASIP användas. Stödbenet på bilbarnstolen Axkid Minikid har utvecklats och förbättrats, och kommer nu att kunna sträckas ut med enbart en knapp, som enklare går att komma åt. Klädseln har förbättrats och momentet att trä av och på klädseln har förenklats, så att möjligheten att tvätta klädseln blir smidigare. Nackstödet är tjockare och mer ombonat, för optimal komfort för barnet när de sover. Den unika funktionen med nackstödet och internselen, som justeras automatiskt efter barnets längd och storlek när du drar åt bältet, finns kvar med en tydligare nackstödsbroms. De självåtdragande underförankringsbanden gör installationen smidig, då bilbarnstolen vickas på plats. De fem främre lutningslägena möjliggör optimal lutning för just ditt barn, beroende på ålder och längd. Skulle det behövas ännu mer lutning är vår lutningskil ett bra komplement. Axkid Minikid är godkänd 0–25 kg (cirka 125 cm, 6 år) och har fått utmärkta omdömen av flera oberoende testinstitut. Den är Plusgodkänd upp till 25 kg, fått utmärkelsen ”Bra Val 2015” av Folksam, ”Bästa prisvärde” av Bäst-i-Test.se och är Rollover-godkänd av VCA. Axkid Minikid levereras alltid med en svart babydyna, för att ge bättre support för de allra minsta barnen. Axkid Minikid, 0–25 kg, ersätter inte babyskyddet. Vi rekommenderar alltid att börja med babyskyddet eftersom det är bäst anpassat för de allra minsta. När ditt barn växt ur babyskyddet är Axkid Minikid ett bra val för ditt barn att åka bakåtvänt i länge. | O6: CN | P6: 94018000 | Q6: 44 | R6: 62 | S6: 56 | T6: 46 | U6: 58 | V6: 66 | W6: 13.8 | X6: 11.4 | Y6: 30° | Z6: Plus approved up to 25kg , Good Chocie 2015 by Folksam, Best cost Value - Bäst-i-test.se, Rullover approved, REACH tested
A7: Axkid Minikid Grå | B7: 22140202 | C7: Grå | D7: 7350057582366 | E7: 0-25KG | F7: Bilbarnstol ECE R44 | G7: - | I7: 25kg | J7: =$J$1 -> SEK / NOK | K7: =IF(J7="SEK / NOK",(VLOOKUP(B7,'RRP data'!A:E,2,FALSE)),(IF(J7="DKK",(VLOOKUP('Axkid Template - SE'!B7,'RRP data'!A:E,4,FALSE)),(IF(J7="EUR",(VLOOKUP(B7,'RRP data'!A:E,5,FALSE))))))) -> #N/A | L7: 1 | M7: 1 | N7: Den bakåtvända bilbarnstolen, Axkid Minikid 2018, är framtagen för att ge bästa möjliga säkerhet och komfort för både små och stora barn, och möjliggör bakåtvänt åkande så länge som möjligt. Nya Axkid Minikid levereras med det innovativa sidokrocksskyddet – ASIP (Axkid Side Impact Protection) som är framtaget tillsammans med ett erkänt krockinstitiut i Tyskland, och ger bästa möjliga skydd för barnet vid eventuell krock från sidan. ASIP ska användas på den sidan av bilbarnstolen som är ut mot bildörren, vid användning i mitten behöver inte ASIP användas. Stödbenet på bilbarnstolen Axkid Minikid har utvecklats och förbättrats, och kommer nu att kunna sträckas ut med enbart en knapp, som enklare går att komma åt. Klädseln har förbättrats och momentet att trä av och på klädseln har förenklats, så att möjligheten att tvätta klädseln blir smidigare. Nackstödet är tjockare och mer ombonat, för optimal komfort för barnet när de sover. Den unika funktionen med nackstödet och internselen, som justeras automatiskt efter barnets längd och storlek när du drar åt bältet, finns kvar med en tydligare nackstödsbroms. De självåtdragande underförankringsbanden gör installationen smidig, då bilbarnstolen vickas på plats. De fem främre lutningslägena möjliggör optimal lutning för just ditt barn, beroende på ålder och längd. Skulle det behövas ännu mer lutning är vår lutningskil ett bra komplement. Axkid Minikid är godkänd 0–25 kg (cirka 125 cm, 6 år) och har fått utmärkta omdömen av flera oberoende testinstitut. Den är Plusgodkänd upp till 25 kg, fått utmärkelsen ”Bra Val 2015” av Folksam, ”Bästa prisvärde” av Bäst-i-Test.se och är Rollover-godkänd av VCA. Axkid Minikid levereras alltid med en svart babydyna, för att ge bättre support för de allra minsta barnen. Axkid Minikid, 0–25 kg, ersätter inte babyskyddet. Vi rekommenderar alltid att börja med babyskyddet eftersom det är bäst anpassat för de allra minsta. När ditt barn växt ur babyskyddet är Axkid Minikid ett bra val för ditt barn att åka bakåtvänt i länge. | O7: CN | P7: 94018000 | Q7: 44 | R7: 62 | S7: 56 | T7: 46 | U7: 58 | V7: 66 | W7: 13.8 | X7: 11.4 | Y7: 30° | Z7: Plus approved up to 25kg , Good Chocie 2015 by Folksam, Best cost Value - Bäst-i-test.se, Rullover approved, REACH tested
A8: Axkid Minikid Svart | B8: 22140203 | C8: Svart | D8: 7350057582374 | E8: 0-25KG | F8: Bilbarnstol ECE R44 | G8: - | I8: 25kg | J8: =$J$1 -> SEK / NOK | K8: =IF(J8="SEK / NOK",(VLOOKUP(B8,'RRP data'!A:E,2,FALSE)),(IF(J8="DKK",(VLOOKUP('Axkid Template - SE'!B8,'RRP data'!A:E,4,FALSE)),(IF(J8="EUR",(VLOOKUP(B8,'RRP data'!A:E,5,FALSE))))))) -> #N/A | L8: 1 | M8: 1 | N8: Den bakåtvända bilbarnstolen, Axkid Minikid 2018, är framtagen för att ge bästa möjliga säkerhet och komfort för både små och stora barn, och möjliggör bakåtvänt åkande så länge som möjligt. Nya Axkid Minikid levereras med det innovativa sidokrocksskyddet – ASIP (Axkid Side Impact Protection) som är framtaget tillsammans med ett erkänt krockinstitiut i Tyskland, och ger bästa möjliga skydd för barnet vid eventuell krock från sidan. ASIP ska användas på den sidan av bilbarnstolen som är ut mot bildörren, vid användning i mitten behöver inte ASIP användas. Stödbenet på bilbarnstolen Axkid Minikid har utvecklats och förbättrats, och kommer nu att kunna sträckas ut med enbart en knapp, som enklare går att komma åt. Klädseln har förbättrats och momentet att trä av och på klädseln har förenklats, så att möjligheten att tvätta klädseln blir smidigare. Nackstödet är tjockare och mer ombonat, för optimal komfort för barnet när de sover. Den unika funktionen med nackstödet och internselen, som justeras automatiskt efter barnets längd och storlek när du drar åt bältet, finns kvar med en tydligare nackstödsbroms. De självåtdragande underförankringsbanden gör installationen smidig, då bilbarnstolen vickas på plats. De fem främre lutningslägena möjliggör optimal lutning för just ditt barn, beroende på ålder och längd. Skulle det behövas ännu mer lutning är vår lutningskil ett bra komplement. Axkid Minikid är godkänd 0–25 kg (cirka 125 cm, 6 år) och har fått utmärkta omdömen av flera oberoende testinstitut. Den är Plusgodkänd upp till 25 kg, fått utmärkelsen ”Bra Val 2015” av Folksam, ”Bästa prisvärde” av Bäst-i-Test.se och är Rollover-godkänd av VCA. Axkid Minikid levereras alltid med en svart babydyna, för att ge bättre support för de allra minsta barnen. Axkid Minikid, 0–25 kg, ersätter inte babyskyddet. Vi rekommenderar alltid att börja med babyskyddet eftersom det är bäst anpassat för de allra minsta. När ditt barn växt ur babyskyddet är Axkid Minikid ett bra val för ditt barn att åka bakåtvänt i länge. | O8: CN | P8: 94018000 | Q8: 44 | R8: 62 | S8: 56 | T8: 46 | U8: 58 | V8: 66 | W8: 13.8 | X8: 11.4 | Y8: 30° | Z8: Plus approved up to 25kg , Good Chocie 2015 by Folksam, Best cost Value - Bäst-i-test.se, Rullover approved, REACH tested
A9: Axkid Minikid Grön | B9: 22140210 | C9: Grön | D9: 7350057582381 | E9: 0-25KG | F9: Bilbarnstol ECE R44 | G9: - | I9: 25kg | J9: =$J$1 -> SEK / NOK | K9: =IF(J9="SEK / NOK",(VLOOKUP(B9,'RRP data'!A:E,2,FALSE)),(IF(J9="DKK",(VLOOKUP('Axkid Template - SE'!B9,'RRP data'!A:E,4,FALSE)),(IF(J9="EUR",(VLOOKUP(B9,'RRP data'!A:E,5,FALSE))))))) -> #N/A | L9: 1 | M9: 1 | N9: Den bakåtvända bilbarnstolen, Axkid Minikid 2018, är framtagen för att ge bästa möjliga säkerhet och komfort för både små och stora barn, och möjliggör bakåtvänt åkande så länge som möjligt. Nya Axkid Minikid levereras med det innovativa sidokrocksskyddet – ASIP (Axkid Side Impact Protection) som är framtaget tillsammans med ett erkänt krockinstitiut i Tyskland, och ger bästa möjliga skydd för barnet vid eventuell krock från sidan. ASIP ska användas på den sidan av bilbarnstolen som är ut mot bildörren, vid användning i mitten behöver inte ASIP användas. Stödbenet på bilbarnstolen Axkid Minikid har utvecklats och förbättrats, och kommer nu att kunna sträckas ut med enbart en knapp, som enklare går att komma åt. Klädseln har förbättrats och momentet att trä av och på klädseln har förenklats, så att möjligheten att tvätta klädseln blir smidigare. Nackstödet är tjockare och mer ombonat, för optimal komfort för barnet när de sover. Den unika funktionen med nackstödet och internselen, som justeras automatiskt efter barnets längd och storlek när du drar åt bältet, finns kvar med en tydligare nackstödsbroms. De självåtdragande underförankringsbanden gör installationen smidig, då bilbarnstolen vickas på plats. De fem främre lutningslägena möjliggör optimal lutning för just ditt barn, beroende på ålder och längd. Skulle det behövas ännu mer lutning är vår lutningskil ett bra komplement. Axkid Minikid är godkänd 0–25 kg (cirka 125 cm, 6 år) och har fått utmärkta omdömen av flera oberoende testinstitut. Den är Plusgodkänd upp till 25 kg, fått utmärkelsen ”Bra Val 2015” av Folksam, ”Bästa prisvärde” av Bäst-i-Test.se och är Rollover-godkänd av VCA. Axkid Minikid levereras alltid med en svart babydyna, för att ge bättre support för de allra minsta barnen. Axkid Minikid, 0–25 kg, ersätter inte babyskyddet. Vi rekommenderar alltid att börja med babyskyddet eftersom det är bäst anpassat för de allra minsta. När ditt barn växt ur babyskyddet är Axkid Minikid ett bra val för ditt barn att åka bakåtvänt i länge. | O9: CN | P9: 94018000 | Q9: 44 | R9: 62 | S9: 56 | T9: 46 | U9: 58 | V9: 66 | W9: 13.8 | X9: 11.4 | Y9: 30° | Z9: Plus approved up to 25kg , Good Chocie 2015 by Folksam, Best cost Value - Bäst-i-test.se, Rullover approved, REACH tested
A10: Axkid Minikid Petrol | B10: 22140211 | C10: Petrol | D10: 7350057582398 | E10: 0-25KG | F10: Bilbarnstol ECE R44 | G10: - | I10: 25kg | J10: =$J$1 -> SEK / NOK | K10: =IF(J10="SEK / NOK",(VLOOKUP(B10,'RRP data'!A:E,2,FALSE)),(IF(J10="DKK",(VLOOKUP('Axkid Template - SE'!B10,'RRP data'!A:E,4,FALSE)),(IF(J10="EUR",(VLOOKUP(B10,'RRP data'!A:E,5,FALSE))))))) -> #N/A | L10: 1 | M10: 1 | N10: Den bakåtvända bilbarnstolen, Axkid Minikid 2018, är framtagen för att ge bästa möjliga säkerhet och komfort för både små och stora barn, och möjliggör bakåtvänt åkande så länge som möjligt. Nya Axkid Minikid levereras med det innovativa sidokrocksskyddet – ASIP (Axkid Side Impact Protection) som är framtaget tillsammans med ett erkänt krockinstitiut i Tyskland, och ger bästa möjliga skydd för barnet vid eventuell krock från sidan. ASIP ska användas på den sidan av bilbarnstolen som är ut mot bildörren, vid användning i mitten behöver inte ASIP användas. Stödbenet på bilbarnstolen Axkid Minikid har utvecklats och förbättrats, och kommer nu att kunna sträckas ut med enbart en knapp, som enklare går att komma åt. Klädseln har förbättrats och momentet att trä av och på klädseln har förenklats, så att möjligheten att tvätta klädseln blir smidigare. Nackstödet är tjockare och mer ombonat, för optimal komfort för barnet när de sover. Den unika funktionen med nackstödet och internselen, som justeras automatiskt efter barnets längd och storlek när du drar åt bältet, finns kvar med en tydligare nackstödsbroms. De självåtdragande underförankringsbanden gör installationen smidig, då bilbarnstolen vickas på plats. De fem främre lutningslägena möjliggör optimal lutning för just ditt barn, beroende på ålder och längd. Skulle det behövas ännu mer lutning är vår lutningskil ett bra komplement. Axkid Minikid är godkänd 0–25 kg (cirka 125 cm, 6 år) och har fått utmärkta omdömen av flera oberoende testinstitut. Den är Plusgodkänd upp till 25 kg, fått utmärkelsen ”Bra Val 2015” av Folksam, ”Bästa prisvärde” av Bäst-i-Test.se och är Rollover-godkänd av VCA. Axkid Minikid levereras alltid med en svart babydyna, för att ge bättre support för de allra minsta barnen. Axkid Minikid, 0–25 kg, ersätter inte babyskyddet. Vi rekommenderar alltid att börja med babyskyddet eftersom det är bäst anpassat för de allra minsta. När ditt barn växt ur babyskyddet är Axkid Minikid ett bra val för ditt barn att åka bakåtvänt i länge. | O10: CN | P10: 94018000 | Q10: 44 | R10: 62 | S10: 56 | T10: 46 | U10: 58 | V10: 66 | W10: 13.8 | X10: 11.4 | Y10: 30° | Z10: Plus approved up to 25kg , Good Chocie 2015 by Folksam, Best cost Value - Bäst-i-test.se, Rullover approved, REACH tested
A11: Axkid Minikid Rosa | B11: 22140213 | C11: Rosa | D11: 7350057582404 | E11: 0-25KG | F11: Bilbarnstol ECE R44 | G11: - | I11: 25kg | J11: =$J$1 -> SEK / NOK | K11: =IF(J11="SEK / NOK",(VLOOKUP(B11,'RRP data'!A:E,2,FALSE)),(IF(J11="DKK",(VLOOKUP('Axkid Template - SE'!B11,'RRP data'!A:E,4,FALSE)),(IF(J11="EUR",(VLOOKUP(B11,'RRP data'!A:E,5,FALSE))))))) -> #N/A | L11: 1 | M11: 1 | N11: Den bakåtvända bilbarnstolen, Axkid Minikid 2018, är framtagen för att ge bästa möjliga säkerhet och komfort för både små och stora barn, och möjliggör bakåtvänt åkande så länge som möjligt. Nya Axkid Minikid levereras med det innovativa sidokrocksskyddet – ASIP (Axkid Side Impact Protection) som är framtaget tillsammans med ett erkänt krockinstitiut i Tyskland, och ger bästa möjliga skydd för barnet vid eventuell krock från sidan. ASIP ska användas på den sidan av bilbarnstolen som är ut mot bildörren, vid användning i mitten behöver inte ASIP användas. Stödbenet på bilbarnstolen Axkid Minikid har utvecklats och förbättrats, och kommer nu att kunna sträckas ut med enbart en knapp, som enklare går att komma åt. Klädseln har förbättrats och momentet att trä av och på klädseln har förenklats, så att möjligheten att tvätta klädseln blir smidigare. Nackstödet är tjockare och mer ombonat, för optimal komfort för barnet när de sover. Den unika funktionen med nackstödet och internselen, som justeras automatiskt efter barnets längd och storlek när du drar åt bältet, finns kvar med en tydligare nackstödsbroms. De självåtdragande underförankringsbanden gör installationen smidig, då bilbarnstolen vickas på plats. De fem främre lutningslägena möjliggör optimal lutning för just ditt barn, beroende på ålder och längd. Skulle det behövas ännu mer lutning är vår lutningskil ett bra komplement. Axkid Minikid är godkänd 0–25 kg (cirka 125 cm, 6 år) och har fått utmärkta omdömen av flera oberoende testinstitut. Den är Plusgodkänd upp till 25 kg, fått utmärkelsen ”Bra Val 2015” av Folksam, ”Bästa prisvärde” av Bäst-i-Test.se och är Rollover-godkänd av VCA. Axkid Minikid levereras alltid med en svart babydyna, för att ge bättre support för de allra minsta barnen. Axkid Minikid, 0–25 kg, ersätter inte babyskyddet. Vi rekommenderar alltid att börja med babyskyddet eftersom det är bäst anpassat för de allra minsta. När ditt barn växt ur babyskyddet är Axkid Minikid ett bra val för ditt barn att åka bakåtvänt i länge. | O11: CN | P11: 94018000 | Q11: 44 | R11: 62 | S11: 56 | T11: 46 | U11: 58 | V11: 66 | W11: 13.8 | X11: 11.4 | Y11: 30° | Z11: Plus approved up to 25kg , Good Chocie 2015 by Folksam, Best cost Value - Bäst-i-test.se, Rullover approved, REACH tested
A12: Axkid Minikid 2 Tar | B12: 22140216 | C12: Tar | D12: 7350057584354 | E12: 0-25KG | F12: Bilbarnstol ECE R44 | G12: - | I12: 25kg | J12: =$J$1 -> SEK / NOK | K12: =IF(J12="SEK / NOK",(VLOOKUP(B12,'RRP data'!A:E,2,FALSE)),(IF(J12="DKK",(VLOOKUP('Axkid Template - SE'!B12,'RRP data'!A:E,4,FALSE)),(IF(J12="EUR",(VLOOKUP(B12,'RRP data'!A:E,5,FALSE))))))) -> Axkid Minikid 2 Solid Tar | L12: 1 | M12: 1 | O12: CN | P12: 94018000 | Q12: 44 | R12: 62 | S12: 56 | T12: 46 | U12: 58 | V12: 66 | W12: 13.8 | X12: 11.4 | Y12: 30° | Z12: Plus approved up to 25kg , Good Chocie 2015 by Folksam, Best cost Value - Bäst-i-test.se, Rullover approved, REACH tested
A13: Axkid Minikid 2 Granite | B13: 22140217 | C13: Granite | D13: 7350057584361 | E13: 0-25KG | F13: Bilbarnstol ECE R44 | G13: - | I13: 25kg | J13: =$J$1 -> SEK / NOK | K13: =IF(J13="SEK / NOK",(VLOOKUP(B13,'RRP data'!A:E,2,FALSE)),(IF(J13="DKK",(VLOOKUP('Axkid Template - SE'!B21,'RRP data'!A:E,4,FALSE)),(IF(J13="EUR",(VLOOKUP(B13,'RRP data'!A:E,5,FALSE))))))) -> Axkid Minikid 2 Solid Granite | L13: 1 | M13: 1 | O13: CN | P13: 94018000 | Q13: 44 | R13: 62 | S13: 56 | T13: 46 | U13: 58 | V13: 66 | W13: 13.8 | X13: 11.4 | Y13: 30° | Z13: Plus approved up to 25kg , Good Chocie 2015 by Folksam, Best cost Value - Bäst-i-test.se, Rullover approved, REACH tested
A14: Axkid Minikid 2 Shellfish | B14: 22140218 | C14: Shellfish | D14: 7350057584378 | E14: 0-25KG | F14: Bilbarnstol ECE R44 | G14: - | I14: 25kg | J14: =$J$1 -> SEK / NOK | K14: =IF(J14="SEK / NOK",(VLOOKUP(B14,'RRP data'!A:E,2,FALSE)),(IF(J14="DKK",(VLOOKUP('Axkid Template - SE'!B38,'RRP data'!A:E,4,FALSE)),(IF(J14="EUR",(VLOOKUP(B14,'RRP data'!A:E,5,FALSE))))))) -> Axkid Minikid 2 Solid Shellfish | L14: 1 | M14: 1 | O14: CN | P14: 94018000 | Q14: 44 | R14: 62 | S14: 56 | T14: 46 | U14: 58 | V14: 66 | W14: 13.8 | X14: 11.4 | Y14: 30° | Z14: Plus approved up to 25kg , Good Chocie 2015 by Folksam, Best cost Value - Bäst-i-test.se, Rullover approved, REACH tested
A15: Axkid Minikid 2 Sea | B15: 22140219 | C15: Sea | D15: 7350057584385 | E15: 0-25KG | F15: Bilbarnstol ECE R44 | G15: - | I15: 25kg | J15: =$J$1 -> SEK / NOK | K15: =IF(J15="SEK / NOK",(VLOOKUP(B15,'RRP data'!A:E,2,FALSE)),(IF(J15="DKK",(VLOOKUP('Axkid Template - SE'!B39,'RRP data'!A:E,4,FALSE)),(IF(J15="EUR",(VLOOKUP(B15,'RRP data'!A:E,5,FALSE))))))) -> Axkid Minikid 2 Solid Sea | L15: 1 | M15: 1 | O15: CN | P15: 94018000 | Q15: 44 | R15: 62 | S15: 56 | T15: 46 | U15: 58 | V15: 66 | W15: 13.8 | X15: 11.4 | Y15: 30° | Z15: Plus approved up to 25kg , Good Chocie 2015 by Folksam, Best cost Value - Bäst-i-test.se, Rullover approved, REACH tested
A16: Axkid Minikid 2 Moss | B16: 22140220 | C16: Moss | D16: 7350057584392 | E16: 0-25KG | F16: Bilbarnstol ECE R44 | G16: - | I16: 25kg | J16: =$J$1 -> SEK / NOK | K16: =IF(J16="SEK / NOK",(VLOOKUP(B16,'RRP data'!A:E,2,FALSE)),(IF(J16="DKK",(VLOOKUP('Axkid Template - SE'!B40,'RRP data'!A:E,4,FALSE)),(IF(J16="EUR",(VLOOKUP(B16,'RRP data'!A:E,5,FALSE))))))) -> Axkid Minikid 2 Solid Moss | L16: 1 | M16: 1 | O16: CN | P16: 94018000 | Q16: 44 | R16: 62 | S16: 56 | T16: 46 | U16: 58 | V16: 66 | W16: 13.8 | X16: 11.4 | Y16: 30° | Z16: Plus approved up to 25kg , Good Chocie 2015 by Folksam, Best cost Value - Bäst-i-test.se, Rullover approved, REACH tested
A17: Axkid Minikid 2 Shell black | B17: 22140221 | C17: Shell black | D17: 7350057584408 | E17: 0-25KG | F17: Bilbarnstol ECE R44 | G17: - | I17: 25kg | J17: =$J$1 -> SEK / NOK | K17: =IF(J17="SEK / NOK",(VLOOKUP(B17,'RRP data'!A:E,2,FALSE)),(IF(J17="DKK",(VLOOKUP('Axkid Template - SE'!B41,'RRP data'!A:E,4,FALSE)),(IF(J17="EUR",(VLOOKUP(B17,'RRP data'!A:E,5,FALSE))))))) -> Axkid Minikid 2 Premium Shell black | L17: 1 | M17: 1 | O17: CN | P17: 94018000 | Q17: 44 | R17: 62 | S17: 56 | T17: 46 | U17: 58 | V17: 66 | W17: 13.8 | X17: 11.4 | Y17: 30° | Z17: Plus approved up to 25kg , Good Chocie 2015 by Folksam, Best cost Value - Bäst-i-test.se, Rullover approved, REACH tested
A18: Axkid Minikid 2 Granite Melange | B18: 22140222 | C18: Granite Melange | D18: 7350057584415 | E18: 0-25KG | F18: Bilbarnstol ECE R44 | G18: - | I18: 25kg | J18: =$J$1 -> SEK / NOK | K18: =IF(J18="SEK / NOK",(VLOOKUP(B18,'RRP data'!A:E,2,FALSE)),(IF(J18="DKK",(VLOOKUP('Axkid Template - SE'!B42,'RRP data'!A:E,4,FALSE)),(IF(J18="EUR",(VLOOKUP(B18,'RRP data'!A:E,5,FALSE))))))) -> Axkid Minikid 2 Premium Granite Melange | L18: 1 | M18: 1 | O18: CN | P18: 94018000 | Q18: 44 | R18: 62 | S18: 56 | T18: 46 | U18: 58 | V18: 66 | W18: 13.8 | X18: 11.4 | Y18: 30° | Z18: Plus approved up to 25kg , Good Chocie 2015 by Folksam, Best cost Value - Bäst-i-test.se, Rullover approved, REACH tested
A19: Axkid Minikid 2 Sky Grey | B19: 22140223 | C19: Sky Grey | D19: 7350057584422 | E19: 0-25KG | F19: Bilbarnstol ECE R44 | G19: - | I19: 25kg | J19: =$J$1 -> SEK / NOK | K19: =IF(J19="SEK / NOK",(VLOOKUP(B19,'RRP data'!A:E,2,FALSE)),(IF(J19="DKK",(VLOOKUP('Axkid Template - SE'!B43,'RRP data'!A:E,4,FALSE)),(IF(J19="EUR",(VLOOKUP(B19,'RRP data'!A:E,5,FALSE))))))) -> Axkid Minikid 2 Premium Sky Grey | L19: 1 | M19: 1 | O19: CN | P19: 94018000 | Q19: 44 | R19: 62 | S19: 56 | T19: 46 | U19: 58 | V19: 66 | W19: 13.8 | X19: 11.4 | Y19: 30° | Z19: Plus approved up to 25kg , Good Chocie 2015 by Folksam, Best cost Value - Bäst-i-test.se, Rullover approved, REACH tested
A20: Axkid Move Grå | B20: 22120102 | C20: Grå | D20: 7350057582411 | E20: 9-25KG | F20: Bilbarnstol ECE R44 | G20: - | I20: 25kg | J20: =$J$1 -> SEK / NOK | K20: =IF(J20="SEK / NOK",(VLOOKUP(B20,'RRP data'!A:E,2,FALSE)),(IF(J20="DKK",(VLOOKUP('Axkid Template - SE'!B20,'RRP data'!A:E,4,FALSE)),(IF(J20="EUR",(VLOOKUP(B20,'RRP data'!A:E,5,FALSE))))))) -> Axkid Move Grey | L20: 1 | M20: 1 | N20: Den bakåtvända bilbarnstolen Axkid Move är för dig som söker en prisvärd och säker lösning. Du kan låta ditt barn åka bakåtvänt länge, och du installerar den lätt med bilens trepunktsbälte. Axkid Move tar mycket liten plats i bilen, så du kan installera den i både små och stora bilar. Axkid Move levereras med det innovativa sidokrocksskyddet – ASIP (Axkid Side Impact Protection) som är framtaget tillsammans med ett erkänt krockinstitiut i Tyskland, och ger bästa möjliga skydd för barnet vid eventuell krock från sidan. ASIP ska användas på den sidan av bilbarnstolen som är ut mot bildörren, vid användning i mitten behöver inte ASIP användas. Stödbenet på Axkid Move sträcks ut med enbart en knapp på sidan av stödbenet, som enkelt går att komma åt. Lutningen på bilbarnstolen kan du ställa i två olika lägen med hjälp av det främre justerbara stödbenet och nackstödet har tre fasta lägen, allt för att ditt barn ska sitta tryggt och bekvämt. Skulle det behövas ännu mer lutning är vår lutningskil ett bra komplement. Axkid Move är godkänd 9–25 kg och har fått utmärkta omdömen av flera oberoende testinstitut. Den är Plusgodkänd upp till 25 kg, fått utmärkelsen ”Bra Val” av Folksam 2017 och är Rollover-godkänd av VCA. | O20: CN | P20: 94018000 | Q20: 44 | R20: 61 | S20: 56 | T20: 46 | U20: 58 | V20: 66 | W20: 11.6 | X20: 9.8 | Y20: 30° | Z20: Plus approved up to 25kg , Good Chocie 2017 by Folksam, Rullover approved, REACH tested
A21: Axkid Move Svart | B21: 22120103 | C21: Svart | D21: 7350057582183 | E21: 9-25KG | F21: Bilbarnstol ECE R44 | G21: - | I21: 25kg | J21: =$J$1 -> SEK / NOK | K21: =IF(J21="SEK / NOK",(VLOOKUP(B21,'RRP data'!A:E,2,FALSE)),(IF(J21="DKK",(VLOOKUP('Axkid Template - SE'!B21,'RRP data'!A:E,4,FALSE)),(IF(J21="EUR",(VLOOKUP(B21,'RRP data'!A:E,5,FALSE))))))) -> Axkid Move Black | L21: 1 | M21: 1 | N21: Den bakåtvända bilbarnstolen Axkid Move är för dig som söker en prisvärd och säker lösning. Du kan låta ditt barn åka bakåtvänt länge, och du installerar den lätt med bilens trepunktsbälte. Axkid Move tar mycket liten plats i bilen, så du kan installera den i både små och stora bilar. Axkid Move levereras med det innovativa sidokrocksskyddet – ASIP (Axkid Side Impact Protection) som är framtaget tillsammans med ett erkänt krockinstitiut i Tyskland, och ger bästa möjliga skydd för barnet vid eventuell krock från sidan. ASIP ska användas på den sidan av bilbarnstolen som är ut mot bildörren, vid användning i mitten behöver inte ASIP användas. Stödbenet på Axkid Move sträcks ut med enbart en knapp på sidan av stödbenet, som enkelt går att komma åt. Lutningen på bilbarnstolen kan du ställa i två olika lägen med hjälp av det främre justerbara stödbenet och nackstödet har tre fasta lägen, allt för att ditt barn ska sitta tryggt och bekvämt. Skulle det behövas ännu mer lutning är vår lutningskil ett bra komplement. Axkid Move är godkänd 9–25 kg och har fått utmärkta omdömen av flera oberoende testinstitut. Den är Plusgodkänd upp till 25 kg, fått utmärkelsen ”Bra Val” av Folksam 2017 och är Rollover-godkänd av VCA. | O21: CN | P21: 94018000 | Q21: 44 | R21: 61 | S21: 56 | T21: 46 | U21: 58 | V21: 66 | W21: 11.6 | X21: 9.8 | Y21: 30° | Z21: Plus approved up to 25kg , Good Chocie 2017 by Folksam, Rullover approved, REACH tested
A22: Axkid Modukid Infant Solid Tar | B22: 20040016 | C22: Tar
A23: Axkid Modukid Infant Solid Granite | B23: 20040017 | C23: Granite
A24: Axkid Modukid Infant Solid Shellfish | B24: 20040018 | C24: Shellfish
A25: Axkid Modukid Infant Solid Sea | B25: 20040019 | C25: Sea
A26: Axkid Modukid Infant Solid Moss | B26: 20040020 | C26: Moss
A27: Axkid Modukid Infant Premium Shell black | B27: 20040021 | C27: Shell black
A28: Axkid Modukid Infant Premium Granite Melange | B28: 20040022 | C28: Granite Melange
A29: Axkid Modukid Infant Premium Sky Grey | B29: 20040023 | C29: Sky Grey
A30: Axkid Modukid Seat Solid Tar | B30: 24100016 | C30: Tar
A31: Axkid Modukid Seat Solid Granite | B31: 24100017 | C31: Granite
A32: Axkid Modukid Seat Solid Shellfish | B32: 24100018 | C32: Shellfish
A33: Axkid Modukid Seat Solid Sea | B33: 24100019 | C33: Sea
... A37: Axkid Modukid Seat Premium Sky Grey | B37: 24100023 | C37: Sky Grey
