Workbook

Sheet One
A1: Garantieleistung - Axkid GmbH | F1: Datum:
A3: Axkid GmbH
A4: Birkenleiten 43
A5: 81543 München
A6: kundenservice@axkid.com
A9: Kunde
A10: Name | C10: Plz: | E10: Ort:
A11: Adresse
A13: Produkt
A14: Händler
A15: Reklanummer
A16: Seriennummer
A19: Aufwand | F19: =IF(SUM(F27:F45)=0,"",H19*Aufwand!C2) | H19: =IF(SUM(F27:F44)=0,"",SUM(G27:G44))
A20: Teile
A21: Reinigungspauschale (nach Zustand) Brutto
A22: Frachtkosten Brutto
A23: Enthaltene Mehrwertsteuer, 19% | F23: =IF(F24="","",F24-(F24/1.19))
A24: Garantie / Reparatur (inkl. MwSt.) | E24: Gesamt | F24: =IF(F19="","",SUM(F19:F22))
A26: Art. Nr | B26: Art. Bezeichnung | C26: Brutto VK | D26: One | E26: EAN | F26: Menge | G26: Aufwand
A27: 1101922 | B27: =VLOOKUP(A27,Ersatzteilpreiseliste!A:C,3,FALSE) -> Ersatzteil - Prallbügel ARB Komplett - Axkid One | C27: =VLOOKUP(A27,Ersatzteilpreiseliste!A:F,6,FALSE) -> 156 | D27: ü | E27: =VLOOKUP(A27,Ersatzteilpreiseliste!A:R,18,FALSE) -> 7350057584811 | G27: =IF(F27="","",H27) | H27: 3
A28: 1101924 | B28: =VLOOKUP(A28,Ersatzteilpreiseliste!A:C,3,FALSE) -> Ersatzteil - Spieldose Stützfuß - Axkid One | C28: =VLOOKUP(A28,Ersatzteilpreiseliste!A:F,6,FALSE) -> 24 | D28: ü | E28: =VLOOKUP(A28,Ersatzteilpreiseliste!A:R,18,FALSE) -> 7350057584828 | G28: =IF(F28="","",H28) | H28: 1
A29: 1101926 | B29: =VLOOKUP(A29,Ersatzteilpreiseliste!A:C,3,FALSE) -> Ersatzteil - Styropor Kopfstütze - Axkid One | C29: =VLOOKUP(A29,Ersatzteilpreiseliste!A:F,6,FALSE) -> 48 | D29: ü | E29: =VLOOKUP(A29,Ersatzteilpreiseliste!A:R,18,FALSE) -> 7350057584842 | G29: =IF(F29="","",H29) | H29: 1
A30: 1103019 | B30: =VLOOKUP(A30,Ersatzteilpreiseliste!A:C,3,FALSE) -> Ersatzteil - Abdeckung Stützfuß 2021- Axkid One | C30: =VLOOKUP(A30,Ersatzteilpreiseliste!A:F,6,FALSE) -> 8 | D30: ü | E30: =VLOOKUP(A30,Ersatzteilpreiseliste!A:R,18,FALSE) -> 7350057586464 | G30: =IF(F30="","",H30) | H30: 1
A31: 1103028 | B31: =VLOOKUP(A31,Ersatzteilpreiseliste!A:C,3,FALSE) -> Ersatzteil - ISOFIX Abstandhalter LH [10stk] - Axkid One | C31: =VLOOKUP(A31,Ersatzteilpreiseliste!A:F,6,FALSE) -> 42 | D31: ü | E31: =VLOOKUP(A31,Ersatzteilpreiseliste!A:R,18,FALSE) -> 7350057586501 | G31: =IF(F31="","",H31) | H31: 1
A32: 1103031 | B32: =VLOOKUP(A32,Ersatzteilpreiseliste!A:C,3,FALSE) -> Ersatzteil - ISOFIX Abstandhalter RH [10stk] - Axkid One | C32: =VLOOKUP(A32,Ersatzteilpreiseliste!A:F,6,FALSE) -> 42 | D32: ü | E32: =VLOOKUP(A32,Ersatzteilpreiseliste!A:R,18,FALSE) -> 7350057586525 | G32: =IF(F32="","",H32) | H32: 1
A33: 1102859 | B33: =VLOOKUP(A33,Ersatzteilpreiseliste!A:C,3,FALSE) -> Ersatzteil - ASIP Befestigung (LH+RH) - Axkid One | C33: =VLOOKUP(A33,Ersatzteilpreiseliste!A:F,6,FALSE) -> 12 | D33: ü | E33: =VLOOKUP(A33,Ersatzteilpreiseliste!A:R,18,FALSE) -> 7350057586426 | G33: =IF(F33="","",H33) | H33: 2
A34: 1103021 | B34: =VLOOKUP(A34,Ersatzteilpreiseliste!A:C,3,FALSE) -> Ersatzteil - Werkzeug ASIP - Axkid One | C34: =VLOOKUP(A34,Ersatzteilpreiseliste!A:F,6,FALSE) -> 18 | D34: ü | G34: =IF(F34="","",H34) | H34: 2
A35: 1101934 | B35: =VLOOKUP(A35,Ersatzteilpreiseliste!A:C,3,FALSE) -> Ersatzteil - Halterung Seitenabdeckung - Axkid One | C35: =VLOOKUP(A35,Ersatzteilpreiseliste!A:F,6,FALSE) -> 6 | D35: ü | E35: =VLOOKUP(A35,Ersatzteilpreiseliste!A:R,18,FALSE) -> 7350057584927 | G35: =IF(F35="","",H35) | H35: 2
A36: 1101927 | B36: =VLOOKUP(A36,Ersatzteilpreiseliste!A:C,3,FALSE) -> Ersatzteil - Verstellung Kopfstütze - Axkid One | C36: =VLOOKUP(A36,Ersatzteilpreiseliste!A:F,6,FALSE) -> 10 | D36: ü | E36: =VLOOKUP(A36,Ersatzteilpreiseliste!A:R,18,FALSE) -> 7350057584859 | G36: =IF(F36="","",H36) | H36: 4
A37: 1101925 | B37: =VLOOKUP(A37,Ersatzteilpreiseliste!A:C,3,FALSE) -> Ersatzteil - Drehknopf Prallbügel - Axkid One | C37: =VLOOKUP(A37,Ersatzteilpreiseliste!A:F,6,FALSE) -> 6 | D37: ü | E37: =VLOOKUP(A37,Ersatzteilpreiseliste!A:R,18,FALSE) -> 7350057584835 | G37: =IF(F37="","",H37) | H37: 1
A38: 1103343 | B38: =VLOOKUP(A38,Ersatzteilpreiseliste!A:C,3,FALSE) -> Ersatzteil - Recline Busching & Stop Screw - Axkid One | C38: =VLOOKUP(A38,Ersatzteilpreiseliste!A:F,6,FALSE) -> 6 | D38: ü | E38: =VLOOKUP(A38,Ersatzteilpreiseliste!A:R,18,FALSE) -> 7350057586792 | G38: =IF(F38="","",H38) | H38: 3
A39: 1101933 | B39: =VLOOKUP(A39,Ersatzteilpreiseliste!A:C,3,FALSE) -> Ersatzteil - Seitenabdeckung - Axkid One | C39: =VLOOKUP(A39,Ersatzteilpreiseliste!A:F,6,FALSE) -> 6 | D39: ü | E39: =VLOOKUP(A39,Ersatzteilpreiseliste!A:R,18,FALSE) -> 7350057584910 | G39: =IF(F39="","",H39) | H39: 2
A40: 1101936 | B40: =VLOOKUP(A40,Ersatzteilpreiseliste!A:C,3,FALSE) -> Ersatzteil - 5 Punkt Gurtsystem - Axkid One | C40: =VLOOKUP(A40,Ersatzteilpreiseliste!A:F,6,FALSE) -> 58 | D40: ü | E40: =VLOOKUP(A40,Ersatzteilpreiseliste!A:R,18,FALSE) -> 7350057584941 | G40: =IF(F40="","",H40) | H40: 4
A41: 1101987 | B41: =VLOOKUP(A41,Ersatzteilpreiseliste!A:C,3,FALSE) -> Ersatzteil - Aufkleber - Axkid One | C41: =VLOOKUP(A41,Ersatzteilpreiseliste!A:F,6,FALSE) -> 6 | D41: ü | E41: =VLOOKUP(A41,Ersatzteilpreiseliste!A:R,18,FALSE) -> 7350057584965 | G41: =IF(F41="","",H41) | H41: 1
A42: 1101928 | B42: =VLOOKUP(A42,Ersatzteilpreiseliste!A:C,3,FALSE) -> Ersatzteil - Verstellknopf Stützfuß - Axkid One | C42: =VLOOKUP(A42,Ersatzteilpreiseliste!A:F,6,FALSE) -> 6 | D42: ü | E42: =VLOOKUP(A42,Ersatzteilpreiseliste!A:R,18,FALSE) -> 7350057584866 | G42: =IF(F42="","",H42) | H42: 1
A43: 1103295 | B43: =VLOOKUP(A43,Ersatzteilpreiseliste!A:C,3,FALSE) -> Harness Friction Decrease - Axkid One | D43: ü | G43: =IF(F43="","",H43) | H43: 1
A44: 1101935 | B44: =VLOOKUP(A44,Ersatzteilpreiseliste!A:C,3,FALSE) -> Ersatzteil - Klettverschluss - Axkid One | C44: =VLOOKUP(A44,Ersatzteilpreiseliste!A:F,6,FALSE) -> 6 | D44: ü | E44: =VLOOKUP(A44,Ersatzteilpreiseliste!A:R,18,FALSE) -> 7350057584873 | G44: =IF(F44="","",H44) | H44: 1
G45: =IF(F45="","",H45)

Sheet Minikid 2
A1: Garantieleistung - Axkid GmbH | F1: Datum:
A3: Axkid GmbH
A4: Birkenleiten 43
A5: 81543 München
A6: kundenservice@axkid.com
A9: Kunde
A10: Name | C10: Plz: | E10: Ort:
A11: Adresse
A13: Produkt
A14: Händler
A15: Reklanummer
A16: Seriennummer
A19: Aufwand | F19: =IF(SUM(F27:F45)=0,"",H19*Aufwand!C2) -> 71.4 | H19: =IF(SUM(F27:F43)=0,"",SUM(G27:G43)) -> 4
A20: Teile
A21: Reinigungspauschale (nach Zustand) Brutto
A22: Frachtkosten Brutto
A23: Enthaltene Mehrwertsteuer, 19% | F23: =IF(F24="","",F24-(F24/1.19)) -> 11.4
A24: Garantie / Reparatur (inkl. MwSt.) | E24: Gesamt | F24: =IF(F19="","",SUM(F19:F22)) -> 71.4
A26: Art. Nr | B26: Art. Bezeichnung | C26: Brutto VK | D26: Minikid 2.0 | E26: EAN | F26: Menge | G26: Aufwand
A27: 1002108 | B27: =VLOOKUP(A27,Ersatzteilpreiseliste!A:C,3,FALSE) -> Ersatzteil - Schaumstoff Sitzfläche Geklebt | C27: =VLOOKUP(A27,Ersatzteilpreiseliste!A:F,6,FALSE) -> 8 | D27: ü | E27: =VLOOKUP(A27,Ersatzteilpreiseliste!A:R,18,FALSE) -> 7350057583746 | G27: =IF(F27="","",H27) | H27: 1
A28: 1006504 | B28: =VLOOKUP(A28,Ersatzteilpreiseliste!A:C,3,FALSE) -> Ersatzteil - Kopfstütze - Minikid 2 | C28: =VLOOKUP(A28,Ersatzteilpreiseliste!A:F,6,FALSE) -> 26 | D28: ü | E28: =VLOOKUP(A28,Ersatzteilpreiseliste!A:R,18,FALSE) -> 7350057583760 | G28: =IF(F28="","",H28) | H28: 2
A29: 1101197 | B29: =VLOOKUP(A29,Ersatzteilpreiseliste!A:C,3,FALSE) -> Ersatzteil - Kopfstütze Rückenplatte - Minikid, Modukid Seat, Rekid, Duofix & Kidzone | C29: =VLOOKUP(A29,Ersatzteilpreiseliste!A:F,6,FALSE) -> 20 | D29: ü | E29: =VLOOKUP(A29,Ersatzteilpreiseliste!A:R,18,FALSE) -> 7350057583807 | G29: =IF(F29="","",H29) | H29: 2
A30: 1002287 | B30: =VLOOKUP(A30,Ersatzteilpreiseliste!A:C,3,FALSE) -> Ersatzteil - Styropor [Links] - Minikid 2 | C30: =VLOOKUP(A30,Ersatzteilpreiseliste!A:F,6,FALSE) -> 14 | D30: ü | E30: =VLOOKUP(A30,Ersatzteilpreiseliste!A:R,18,FALSE) -> 7350057583814 | F30: 1 | G30: =IF(F30="","",H30) -> 2 | H30: 2
A31: 1002288 | B31: =VLOOKUP(A31,Ersatzteilpreiseliste!A:C,3,FALSE) -> Ersatzteil - Styropor [Rechts] - Minikid 2 | C31: =VLOOKUP(A31,Ersatzteilpreiseliste!A:F,6,FALSE) -> 14 | D31: ü | E31: =VLOOKUP(A31,Ersatzteilpreiseliste!A:R,18,FALSE) -> 7350057583821 | F31: 1 | G31: =IF(F31="","",H31) -> 2 | H31: 2
A32: 1002101 | B32: =VLOOKUP(A32,Ersatzteilpreiseliste!A:C,3,FALSE) -> Ersatzteil - Styropor [Rücken] - Minikid, Rekid, Duofix & Kidzone | C32: =VLOOKUP(A32,Ersatzteilpreiseliste!A:F,6,FALSE) -> 14 | D32: ü | E32: =VLOOKUP(A32,Ersatzteilpreiseliste!A:R,18,FALSE) -> 7350057583876 | G32: =IF(F32="","",H32) | H32: 2
A33: 1100939 | B33: =VLOOKUP(A33,Ersatzteilpreiseliste!A:C,3,FALSE) -> Ersatzteil - Gurtklemme [Blau] | C33: =VLOOKUP(A33,Ersatzteilpreiseliste!A:F,6,FALSE) -> 6 | D33: ü | E33: =VLOOKUP(A33,Ersatzteilpreiseliste!A:R,18,FALSE) -> 7350057583890 | G33: =IF(F33="","",H33) | H33: 1
A34: 1004445 | B34: =VLOOKUP(A34,Ersatzteilpreiseliste!A:C,3,FALSE) -> Ersatzteil - Stützfuß - Minikid 2 & Move | C34: =VLOOKUP(A34,Ersatzteilpreiseliste!A:F,6,FALSE) -> 60 | D34: ü | E34: =VLOOKUP(A34,Ersatzteilpreiseliste!A:R,18,FALSE) -> 7350057583913 | G34: =IF(F34="","",H34) | H34: 3
A35: 1101314 | B35: =VLOOKUP(A35,Ersatzteilpreiseliste!A:C,3,FALSE) -> Ersatzteil - Gurt für Stützfuß - Minikid 2 & Move | C35: =VLOOKUP(A35,Ersatzteilpreiseliste!A:F,6,FALSE) -> 6 | D35: ü | E35: =VLOOKUP(A35,Ersatzteilpreiseliste!A:R,18,FALSE) -> 7350057584187 | G35: =IF(F35="","",H35) | H35: 3
A36: 1003124 | B36: =VLOOKUP(A36,Ersatzteilpreiseliste!A:C,3,FALSE) -> Ersatzteil - 5 Punkt Gurtsystem Holmberg | C36: =VLOOKUP(A36,Ersatzteilpreiseliste!A:F,6,FALSE) -> 60 | D36: ü | E36: =VLOOKUP(A36,Ersatzteilpreiseliste!A:R,18,FALSE) -> 7350057583968 | G36: =IF(F36="","",H36) | H36: 3
A37: 1003400 | B37: =VLOOKUP(A37,Ersatzteilpreiseliste!A:C,3,FALSE) -> Ersatzteil - Gurtaufroller [Links] | C37: =VLOOKUP(A37,Ersatzteilpreiseliste!A:F,6,FALSE) -> 46 | D37: ü | E37: =VLOOKUP(A37,Ersatzteilpreiseliste!A:R,18,FALSE) -> 7350057584019 | G37: =IF(F37="","",H37) | H37: 1
A38: 1003409 | B38: =VLOOKUP(A38,Ersatzteilpreiseliste!A:C,3,FALSE) -> Ersatzteil - Gurtaufroller [Rechts] | C38: =VLOOKUP(A38,Ersatzteilpreiseliste!A:F,6,FALSE) -> 46 | D38: ü | E38: =VLOOKUP(A38,Ersatzteilpreiseliste!A:R,18,FALSE) -> 7350057584026 | G38: =IF(F38="","",H38) | H38: 1
A39: 1100816 | B39: =VLOOKUP(A39,Ersatzteilpreiseliste!A:C,3,FALSE) -> Ersatzteil - ASIP Befestigung - Minikid 2, Move, Modukid Seat | C39: =VLOOKUP(A39,Ersatzteilpreiseliste!A:F,6,FALSE) -> 10 | D39: ü | E39: =VLOOKUP(A39,Ersatzteilpreiseliste!A:R,18,FALSE) -> 7350057584064 | G39: =IF(F39="","",H39) | H39: 1
A40: 1100791 | B40: =VLOOKUP(A40,Ersatzteilpreiseliste!A:C,3,FALSE) -> Ersatzteil - Bremseinheit Kopfstütze - Modukid Seat, Minikid, Rekid, Duofix & Kidzone | C40: =VLOOKUP(A40,Ersatzteilpreiseliste!A:F,6,FALSE) -> 6 | D40: ü | E40: =VLOOKUP(A40,Ersatzteilpreiseliste!A:R,18,FALSE) -> 7350057584088 | G40: =IF(F40="","",H40) | H40: 2
A41: 1100834 | B41: =VLOOKUP(A41,Ersatzteilpreiseliste!A:C,3,FALSE) -> Ersatzteil - Spannrolle Kopfstütze - Minikid 2 & Modukid Seat | C41: =VLOOKUP(A41,Ersatzteilpreiseliste!A:F,6,FALSE) -> 26 | D41: ü | E41: =VLOOKUP(A41,Ersatzteilpreiseliste!A:R,18,FALSE) -> 7350057584095 | G41: =IF(F41="","",H41) | H41: 3
A42: 1100817 | B42: =VLOOKUP(A42,Ersatzteilpreiseliste!A:C,3,FALSE) -> Ersatzteil - Neigungsverstellung - Minikid | C42: =VLOOKUP(A42,Ersatzteilpreiseliste!A:F,6,FALSE) -> 32 | D42: ü | E42: =VLOOKUP(A42,Ersatzteilpreiseliste!A:R,18,FALSE) -> 7350057584040 | G42: =IF(F42="","",H42) | H42: 3
A43: 1003207 | B43: =VLOOKUP(A43,Ersatzteilpreiseliste!A:C,3,FALSE) -> Ersatzteil - Gurtabdeckung | C43: =VLOOKUP(A43,Ersatzteilpreiseliste!A:F,6,FALSE) -> 6 | D43: ü | E43: =VLOOKUP(A43,Ersatzteilpreiseliste!A:R,18,FALSE) -> 7350057583999 | G43: =IF(F43="","",H43) | H43: 1
A44: 1900028 | B44: Nieten | C44: =VLOOKUP(A44,Ersatzteilpreiseliste!A:F,6,FALSE) -> 0.2 | D44: ü | E44: =VLOOKUP(A44,Ersatzteilpreiseliste!A:R,18,FALSE) -> 7350057584101

Sheet Rekid
A1: Garantieleistung - Axkid GmbH | F1: Datum:
A3: Axkid GmbH
A4: Birkenleiten 43
A5: 81543 München
A6: kundenservice@axkid.com
A9: Kunde
A10: Name | C10: Plz: | E10: Ort:
A11: Adresse
A13: Produkt
A14: Händler
A15: Reklanummer
A16: Seriennummer
A19: Aufwand | F19: =IF(SUM(F27:F45)=0,"",H19*Aufwand!C2) | H19: =IF(SUM(F27:F43)=0,"",SUM(G27:G43))
A20: Teile
A21: Reinigungspauschale (nach Zustand) Brutto
A22: Frachtkosten Brutto
A23: Enthaltene Mehrwertsteuer, 19% | F23: =IF(F24="","",F24-(F24/1.19))
A24: Garantie / Reparatur (inkl. MwSt.) | E24: Gesamt | F24: =IF(F19="","",SUM(F19:F22))
A26: Art. Nr | B26: Art. Bezeichnung | C26: Brutto VK | D26: Rekid | E26: EAN | F26: Menge | G26: Aufwand
A27: 1002108 | B27: =VLOOKUP(A27,Ersatzteilpreiseliste!A:C,3,FALSE) -> Ersatzteil - Schaumstoff Sitzfläche Geklebt | C27: =VLOOKUP(A27,Ersatzteilpreiseliste!A:F,6,FALSE) -> 8 | D27: ü | E27: =VLOOKUP(A27,Ersatzteilpreiseliste!A:R,18,FALSE) -> 7350057583746 | G27: =IF(F27="","",H27) | H27: 1
A28: 1006003 | B28: =VLOOKUP(A28,Ersatzteilpreiseliste!A:C,3,FALSE) -> Ersatzteil - Kopfstütze - Minikid 1 & Rekid | C28: =VLOOKUP(A28,Ersatzteilpreiseliste!A:F,6,FALSE) -> 26 | D28: ü | E28: =VLOOKUP(A28,Ersatzteilpreiseliste!A:R,18,FALSE) -> 7350057583777 | G28: =IF(F28="","",H28) | H28: 2
A29: 1101197 | B29: =VLOOKUP(A29,Ersatzteilpreiseliste!A:C,3,FALSE) -> Ersatzteil - Kopfstütze Rückenplatte - Minikid, Modukid Seat, Rekid, Duofix & Kidzone | C29: =VLOOKUP(A29,Ersatzteilpreiseliste!A:F,6,FALSE) -> 20 | D29: ü | E29: =VLOOKUP(A29,Ersatzteilpreiseliste!A:R,18,FALSE) -> 7350057583807 | G29: =IF(F29="","",H29) | H29: 2
A30: 1002103 | B30: =VLOOKUP(A30,Ersatzteilpreiseliste!A:C,3,FALSE) -> Ersatzteil - Styropor [Links] - Minikid, Rekid, Duofix & Kidzone | C30: =VLOOKUP(A30,Ersatzteilpreiseliste!A:F,6,FALSE) -> 14 | D30: ü | E30: =VLOOKUP(A30,Ersatzteilpreiseliste!A:R,18,FALSE) -> 7350057583852 | G30: =IF(F30="","",H30) | H30: 2
A31: 1002104 | B31: =VLOOKUP(A31,Ersatzteilpreiseliste!A:C,3,FALSE) -> Ersatzteil - Styropor [Rechts] - Minikid, Rekid, Duofix & Kidzone | C31: =VLOOKUP(A31,Ersatzteilpreiseliste!A:F,6,FALSE) -> 14 | D31: ü | E31: =VLOOKUP(A31,Ersatzteilpreiseliste!A:R,18,FALSE) -> 7350057583869 | G31: =IF(F31="","",H31) | H31: 2
A32: 1002101 | B32: =VLOOKUP(A32,Ersatzteilpreiseliste!A:C,3,FALSE) -> Ersatzteil - Styropor [Rücken] - Minikid, Rekid, Duofix & Kidzone | C32: =VLOOKUP(A32,Ersatzteilpreiseliste!A:F,6,FALSE) -> 14 | D32: ü | E32: =VLOOKUP(A32,Ersatzteilpreiseliste!A:R,18,FALSE) -> 7350057583876 | G32: =IF(F32="","",H32) | H32: 2
A33: 1003215 | B33: =VLOOKUP(A33,Ersatzteilpreiseliste!A:C,3,FALSE) -> Gurtklemme schwarz | C33: =VLOOKUP(A33,Ersatzteilpreiseliste!A:F,6,FALSE) -> 6 | D33: ü | E33: =VLOOKUP(A33,Ersatzteilpreiseliste!A:R,18,FALSE) -> 7350057583906 | G33: =IF(F33="","",H33) | H33: 1
A34: 1004000 | B34: =VLOOKUP(A34,Ersatzteilpreiseliste!A:C,3,FALSE) -> Ersatzteil - Stützfuß - Minikid 1, Rekid, Wolmax, Duofix & Kidzone | C34: =VLOOKUP(A34,Ersatzteilpreiseliste!A:F,6,FALSE) -> 80 | D34: ü | E34: =VLOOKUP(A34,Ersatzteilpreiseliste!A:R,18,FALSE) -> 7350057583920 | G34: =IF(F34="","",H34) | H34: 3
A35: 1101315 | B35: =VLOOKUP(A35,Ersatzteilpreiseliste!A:C,3,FALSE) -> Ersatzteil - Gurt für Stützfuß - Minikid 1, Rekid, Wolmax, Duofix & Kidzone | C35: =VLOOKUP(A35,Ersatzteilpreiseliste!A:F,6,FALSE) -> 6 | D35: ü | E35: =VLOOKUP(A35,Ersatzteilpreiseliste!A:R,18,FALSE) -> 7350057584194 | G35: =IF(F35="","",H35) | H35: 3
A36: 1003124 | B36: =VLOOKUP(A36,Ersatzteilpreiseliste!A:C,3,FALSE) -> Ersatzteil - 5 Punkt Gurtsystem Holmberg | C36: =VLOOKUP(A36,Ersatzteilpreiseliste!A:F,6,FALSE) -> 60 | D36: ü | E36: =VLOOKUP(A36,Ersatzteilpreiseliste!A:R,18,FALSE) -> 7350057583968 | G36: =IF(F36="","",H36) | H36: 3
A37: 1003400 | B37: =VLOOKUP(A37,Ersatzteilpreiseliste!A:C,3,FALSE) -> Ersatzteil - Gurtaufroller [Links] | C37: =VLOOKUP(A37,Ersatzteilpreiseliste!A:F,6,FALSE) -> 46 | D37: ü | E37: =VLOOKUP(A37,Ersatzteilpreiseliste!A:R,18,FALSE) -> 7350057584019 | G37: =IF(F37="","",H37) | H37: 1
A38: 1003409 | B38: =VLOOKUP(A38,Ersatzteilpreiseliste!A:C,3,FALSE) -> Ersatzteil - Gurtaufroller [Rechts] | C38: =VLOOKUP(A38,Ersatzteilpreiseliste!A:F,6,FALSE) -> 46 | D38: ü | E38: =VLOOKUP(A38,Ersatzteilpreiseliste!A:R,18,FALSE) -> 7350057584026 | G38: =IF(F38="","",H38) | H38: 1
... A41: 1003207 | B41: =VLOOKUP(A41,Ersatzteilpreiseliste!A:C,3,FALSE) -> Ersatzteil - Gurtabdeckung | C41: =VLOOKUP(A41,Ersatzteilpreiseliste!A:F,6,FALSE) -> 6 | D41: ü | E41: =VLOOKUP(A41,Ersatzteilpreiseliste!A:R,18,FALSE) -> 7350057583999 | G41: =IF(F41="","",H41) | H41: 1
A42: 1900028 | B42: Nieten | C42: =VLOOKUP(A42,Ersatzteilpreiseliste!A:F,6,FALSE) -> 0.2 | D42: ü | E42: =VLOOKUP(A42,Ersatzteilpreiseliste!A:R,18,FALSE) -> 7350057584101

Sheet Move
A1: Garantieleistung - Axkid GmbH | F1: Datum:
A3: Axkid GmbH
A4: Birkenleiten 43
A5: 81543 München
A6: kundenservice@axkid.com
A9: Kunde
A10: Name | C10: Plz: | E10: Ort:
A11: Adresse
A13: Produkt
A14: Händler
A15: Reklanummer
A16: Seriennummer
A19: Aufwand | F19: =IF(SUM(F27:F45)=0,"",H19*Aufwand!C2) | H19: =IF(SUM(F27:F43)=0,"",SUM(G27:G43))
A20: Teile
A21: Reinigungspauschale (nach Zustand) Brutto
A22: Frachtkosten Brutto
A23: Enthaltene Mehrwertsteuer, 19% | F23: =IF(F24="","",F24-(F24/1.19))
A24: Garantie / Reparatur (inkl. MwSt.) | E24: Gesamt | F24: =IF(F19="","",SUM(F19:F22))
A26: Art. Nr | B26: Art. Bezeichnung | C26: Brutto VK | D26: Move | E26: EAN | F26: Menge | G26: Aufwand
A27: 1002108 | B27: =VLOOKUP(A27,Ersatzteilpreiseliste!A:C,3,FALSE) -> Ersatzteil - Schaumstoff Sitzfläche Geklebt | C27: =VLOOKUP(A27,Ersatzteilpreiseliste!A:F,6,FALSE) -> 8 | D27: ü | E27: =VLOOKUP(A27,Ersatzteilpreiseliste!A:R,18,FALSE) -> 7350057583746 | G27: =IF(F27="","",H27) | H27: 1
A28: 1101232 | B28: =VLOOKUP(A28,Ersatzteilpreiseliste!A:C,3,FALSE) -> Kopfstütze | C28: =VLOOKUP(A28,Ersatzteilpreiseliste!A:F,6,FALSE) -> 24 | D28: ü | E28: =VLOOKUP(A28,Ersatzteilpreiseliste!A:R,18,FALSE) -> 7350057583784 | G28: =IF(F28="","",H28) | H28: 2
A29: 1002118 | B29: =VLOOKUP(A29,Ersatzteilpreiseliste!A:C,3,FALSE) -> Ersatzteil - Styropor [Links] - Move & Wolmax | C29: =VLOOKUP(A29,Ersatzteilpreiseliste!A:F,6,FALSE) -> 14 | D29: ü | E29: =VLOOKUP(A29,Ersatzteilpreiseliste!A:R,18,FALSE) -> 7350057583838 | G29: =IF(F29="","",H29) | H29: 2
A30: 1002119 | B30: =VLOOKUP(A30,Ersatzteilpreiseliste!A:C,3,FALSE) -> Ersatzteil - Styropor [Rechts] - Move & Wolmax | C30: =VLOOKUP(A30,Ersatzteilpreiseliste!A:F,6,FALSE) -> 14 | D30: ü | E30: =VLOOKUP(A30,Ersatzteilpreiseliste!A:R,18,FALSE) -> 7350057583845 | G30: =IF(F30="","",H30) | H30: 2
A31: 1002117 | B31: =VLOOKUP(A31,Ersatzteilpreiseliste!A:C,3,FALSE) -> Ersatzteil - Styropor [Rücken] - Move & Wolmax | C31: =VLOOKUP(A31,Ersatzteilpreiseliste!A:F,6,FALSE) -> 14 | D31: ü | E31: =VLOOKUP(A31,Ersatzteilpreiseliste!A:R,18,FALSE) -> 7350057583883 | G31: =IF(F31="","",H31) | H31: 2
A32: 1100939 | B32: =VLOOKUP(A32,Ersatzteilpreiseliste!A:C,3,FALSE) -> Ersatzteil - Gurtklemme [Blau] | C32: =VLOOKUP(A32,Ersatzteilpreiseliste!A:F,6,FALSE) -> 6 | D32: ü | E32: =VLOOKUP(A32,Ersatzteilpreiseliste!A:R,18,FALSE) -> 7350057583890 | G32: =IF(F32="","",H32) | H32: 1
A33: 1004445 | B33: =VLOOKUP(A33,Ersatzteilpreiseliste!A:C,3,FALSE) -> Ersatzteil - Stützfuß - Minikid 2 & Move | C33: =VLOOKUP(A33,Ersatzteilpreiseliste!A:F,6,FALSE) -> 60 | D33: ü | E33: =VLOOKUP(A33,Ersatzteilpreiseliste!A:R,18,FALSE) -> 7350057583913 | G33: =IF(F33="","",H33) | H33: 3
A34: 1101314 | B34: =VLOOKUP(A34,Ersatzteilpreiseliste!A:C,3,FALSE) -> Ersatzteil - Gurt für Stützfuß - Minikid 2 & Move | C34: =VLOOKUP(A34,Ersatzteilpreiseliste!A:F,6,FALSE) -> 6 | D34: ü | E34: =VLOOKUP(A34,Ersatzteilpreiseliste!A:R,18,FALSE) -> 7350057584187 | G34: =IF(F34="","",H34) | H34: 3
A35: 1003124 | B35: =VLOOKUP(A35,Ersatzteilpreiseliste!A:C,3,FALSE) -> Ersatzteil - 5 Punkt Gurtsystem Holmberg | C35: =VLOOKUP(A35,Ersatzteilpreiseliste!A:F,6,FALSE) -> 60 | D35: ü | E35: =VLOOKUP(A35,Ersatzteilpreiseliste!A:R,18,FALSE) -> 7350057583968 | G35: =IF(F35="","",H35) | H35: 3
A36: 1003207 | B36: =VLOOKUP(A36,Ersatzteilpreiseliste!A:C,3,FALSE) -> Ersatzteil - Gurtabdeckung | C36: =VLOOKUP(A36,Ersatzteilpreiseliste!A:F,6,FALSE) -> 6 | D36: ü | E36: =VLOOKUP(A36,Ersatzteilpreiseliste!A:R,18,FALSE) -> 7350057583999 | G36: =IF(F36="","",H36) | H36: 1
A37: 1900028 | B37: Nieten | C37: =VLOOKUP(A37,Ersatzteilpreiseliste!A:F,6,FALSE) -> 0.2 | D37: ü | E37: =VLOOKUP(A37,Ersatzteilpreiseliste!A:R,18,FALSE) -> 7350057584101

Sheet Modukid Seat
A1: Garantieleistung - Axkid GmbH | F1: Datum:
A3: Axkid GmbH
A4: Birkenleiten 43
A5: 81543 München
A6: kundenservice@axkid.com
A9: Kunde
A10: Name | C10: Plz: | E10: Ort:
A11: Adresse
A13: Produkt
A14: Händler
A15: Reklanummer
A16: Seriennummer
A19: Aufwand | F19: =IF(SUM(F27:F45)=0,"",H19*Aufwand!C2) | H19: =IF(SUM(F27:F43)=0,"",SUM(G27:G43))
A20: Teile
A21: Reinigungspauschale (nach Zustand) Brutto
A22: Frachtkosten Brutto
A23: Enthaltene Mehrwertsteuer, 19% | F23: =IF(F24="","",F24-(F24/1.19))
A24: Garantie / Reparatur (inkl. MwSt.) | E24: Gesamt | F24: =IF(F19="","",SUM(F19:F22))
A26: Art. Nr | B26: Art. Bezeichnung | C26: Brutto VK | D26: Modukid Seat | E26: EAN | F26: Menge | G26: Aufwand
A27: 1002321 | B27: =VLOOKUP(A27,Ersatzteilpreiseliste!A:C,3,FALSE) -> Ersatzteil - Schaumstoff Sitzfläche Geklebt - Modukid Seat | C27: =VLOOKUP(A27,Ersatzteilpreiseliste!A:F,6,FALSE) -> 8 | D27: ü | E27: =VLOOKUP(A27,Ersatzteilpreiseliste!A:R,18,FALSE) -> 7350057583739 | G27: =IF(F27="","",H27) | H27: 1
A28: 1100815 | B28: =VLOOKUP(A28,Ersatzteilpreiseliste!A:C,3,FALSE) -> Kopfstütze | C28: =VLOOKUP(A28,Ersatzteilpreiseliste!A:F,6,FALSE) -> 24 | D28: ü | E28: =VLOOKUP(A28,Ersatzteilpreiseliste!A:R,18,FALSE) -> 7350057583753 | G28: =IF(F28="","",H28) | H28: 2
A29: 1101197 | B29: =VLOOKUP(A29,Ersatzteilpreiseliste!A:C,3,FALSE) -> Ersatzteil - Kopfstütze Rückenplatte - Minikid, Modukid Seat, Rekid, Duofix & Kidzone | C29: =VLOOKUP(A29,Ersatzteilpreiseliste!A:F,6,FALSE) -> 20 | D29: ü | E29: =VLOOKUP(A29,Ersatzteilpreiseliste!A:R,18,FALSE) -> 7350057583807 | G29: =IF(F29="","",H29) | H29: 2
A30: 1002101 | B30: =VLOOKUP(A30,Ersatzteilpreiseliste!A:C,3,FALSE) -> Ersatzteil - Styropor [Rücken] - Minikid, Rekid, Duofix & Kidzone | C30: =VLOOKUP(A30,Ersatzteilpreiseliste!A:F,6,FALSE) -> 14 | D30: ü | E30: =VLOOKUP(A30,Ersatzteilpreiseliste!A:R,18,FALSE) -> 7350057583876 | G30: =IF(F30="","",H30) | H30: 2
A31: 1100810 | B31: =VLOOKUP(A31,Ersatzteilpreiseliste!A:C,3,FALSE) -> Ersatzteil - 5 Punkt Gurtsystem Shield - Modukid | C31: =VLOOKUP(A31,Ersatzteilpreiseliste!A:F,6,FALSE) -> 40 | D31: ü | E31: =VLOOKUP(A31,Ersatzteilpreiseliste!A:R,18,FALSE) -> 7350057583951 | G31: =IF(F31="","",H31) | H31: 3
A32: 1100859 | B32: =VLOOKUP(A32,Ersatzteilpreiseliste!A:C,3,FALSE) -> Ersatzteil - ASIP Befestigung - Modukid Seat | C32: =VLOOKUP(A32,Ersatzteilpreiseliste!A:F,6,FALSE) -> 10 | D32: ü | E32: =VLOOKUP(A32,Ersatzteilpreiseliste!A:R,18,FALSE) -> 7350057584071 | G32: =IF(F32="","",H32) | H32: 1
A33: 1100791 | B33: =VLOOKUP(A33,Ersatzteilpreiseliste!A:C,3,FALSE) -> Ersatzteil - Bremseinheit Kopfstütze - Modukid Seat, Minikid, Rekid, Duofix & Kidzone | C33: =VLOOKUP(A33,Ersatzteilpreiseliste!A:F,6,FALSE) -> 6 | D33: ü | E33: =VLOOKUP(A33,Ersatzteilpreiseliste!A:R,18,FALSE) -> 7350057584088 | G33: =IF(F33="","",H33) | H33: 2
A34: 1100834 | B34: =VLOOKUP(A34,Ersatzteilpreiseliste!A:C,3,FALSE) -> Ersatzteil - Spannrolle Kopfstütze - Minikid 2 & Modukid Seat | C34: =VLOOKUP(A34,Ersatzteilpreiseliste!A:F,6,FALSE) -> 26 | D34: ü | E34: =VLOOKUP(A34,Ersatzteilpreiseliste!A:R,18,FALSE) -> 7350057584095 | G34: =IF(F34="","",H34) | H34: 2
A35: 1900028 | B35: Nieten | C35: =VLOOKUP(A35,Ersatzteilpreiseliste!A:F,6,FALSE) -> 0.2 | D35: ü | E35: =VLOOKUP(A35,Ersatzteilpreiseliste!A:R,18,FALSE) -> 7350057584101

Sheet Modukid Infant
A1: Garantieleistung - Axkid GmbH | F1: Datum:
A3: Axkid GmbH
A4: Birkenleiten 43
A5: 81543 München
A6: kundenservice@axkid.com
A9: Kunde
A10: Name | C10: Plz: | E10: Ort:
A11: Adresse
A13: Produkt
A14: Händler
A15: Reklanummer
A16: Seriennummer
A19: Aufwand | F19: =IF(SUM(F27:F45)=0,"",H19*Aufwand!C2) | H19: =IF(SUM(F27:F43)=0,"",SUM(G27:G43))
A20: Teile
A21: Reinigungspauschale (nach Zustand) Brutto
A22: Frachtkosten Brutto
A23: Enthaltene Mehrwertsteuer, 19% | F23: =IF(F24="","",F24-(F24/1.19))
A24: Garantie / Reparatur (inkl. MwSt.) | E24: Gesamt | F24: =IF(F19="","",SUM(F19:F22))
A26: Art. Nr | B26: Art. Bezeichnung | C26: Brutto VK | D26: Modukid Infant | E26: EAN | F26: Menge | G26: Aufwand
A27: 1100813 | B27: =VLOOKUP(A27,Ersatzteilpreiseliste!A:C,3,FALSE) -> 3 Punkt Gurt - Shield | C27: =VLOOKUP(A27,Ersatzteilpreiseliste!A:F,6,FALSE) -> 40 | D27: ü | E27: =VLOOKUP(A27,Ersatzteilpreiseliste!A:R,18,FALSE) -> 7350057583975 | G27: =IF(F27="","",H27) | H27: 3
A28: 1900028 | B28: Nieten | C28: =VLOOKUP(A28,Ersatzteilpreiseliste!A:F,6,FALSE) -> 0.2 | D28: ü | E28: =VLOOKUP(A28,Ersatzteilpreiseliste!A:R,18,FALSE) -> 7350057584101

Sheet Minikid 1
A1: Garantieleistung - Axkid GmbH | F1: Datum:
A3: Axkid GmbH
A4: Birkenleiten 43
A5: 81543 München
A6: kundenservice@axkid.com
A9: Kunde
A10: Name | C10: Plz: | E10: Ort:
A11: Adresse
A13: Produkt
A14: Händler
A15: Reklanummer
A16: Seriennummer
A19: Aufwand | F19: =IF(SUM(F27:F45)=0,"",H19*Aufwand!C2) | H19: =IF(SUM(F27:F43)=0,"",SUM(G27:G43))
A20: Teile
A21: Reinigungspauschale (nach Zustand) Brutto
A22: Frachtkosten Brutto
A23: Enthaltene Mehrwertsteuer, 19% | F23: =IF(F24="","",F24-(F24/1.19))
A24: Garantie / Reparatur (inkl. MwSt.) | E24: Gesamt | F24: =IF(F19="","",SUM(F19:F22))
A26: Art. Nr | B26: Art. Bezeichnung | C26: Brutto VK | D26: Minikid 1.0 | E26: EAN | F26: Menge | G26: Aufwand
A27: 1002108 | B27: =VLOOKUP(A27,Ersatzteilpreiseliste!A:C,3,FALSE) -> Ersatzteil - Schaumstoff Sitzfläche Geklebt | C27: =VLOOKUP(A27,Ersatzteilpreiseliste!A:F,6,FALSE) -> 8 | D27: ü | E27: =VLOOKUP(A27,Ersatzteilpreiseliste!A:R,18,FALSE) -> 7350057583746 | G27: =IF(F27="","",H27) | H27: 1
A28: 1006003 | B28: =VLOOKUP(A28,Ersatzteilpreiseliste!A:C,3,FALSE) -> Ersatzteil - Kopfstütze - Minikid 1 & Rekid | C28: =VLOOKUP(A28,Ersatzteilpreiseliste!A:F,6,FALSE) -> 26 | D28: ü | E28: =VLOOKUP(A28,Ersatzteilpreiseliste!A:R,18,FALSE) -> 7350057583777 | G28: =IF(F28="","",H28) | H28: 2
A29: 1101197 | B29: =VLOOKUP(A29,Ersatzteilpreiseliste!A:C,3,FALSE) -> Ersatzteil - Kopfstütze Rückenplatte - Minikid, Modukid Seat, Rekid, Duofix & Kidzone | C29: =VLOOKUP(A29,Ersatzteilpreiseliste!A:F,6,FALSE) -> 20 | D29: ü | E29: =VLOOKUP(A29,Ersatzteilpreiseliste!A:R,18,FALSE) -> 7350057583807 | G29: =IF(F29="","",H29) | H29: 2
A30: 1002103 | B30: =VLOOKUP(A30,Ersatzteilpreiseliste!A:C,3,FALSE) -> Ersatzteil - Styropor [Links] - Minikid, Rekid, Duofix & Kidzone | C30: =VLOOKUP(A30,Ersatzteilpreiseliste!A:F,6,FALSE) -> 14 | D30: ü | E30: =VLOOKUP(A30,Ersatzteilpreiseliste!A:R,18,FALSE) -> 7350057583852 | G30: =IF(F30="","",H30) | H30: 2
A31: 1002104 | B31: =VLOOKUP(A31,Ersatzteilpreiseliste!A:C,3,FALSE) -> Ersatzteil - Styropor [Rechts] - Minikid, Rekid, Duofix & Kidzone | C31: =VLOOKUP(A31,Ersatzteilpreiseliste!A:F,6,FALSE) -> 14 | D31: ü | E31: =VLOOKUP(A31,Ersatzteilpreiseliste!A:R,18,FALSE) -> 7350057583869 | G31: =IF(F31="","",H31) | H31: 2
A32: 1002101 | B32: =VLOOKUP(A32,Ersatzteilpreiseliste!A:C,3,FALSE) -> Ersatzteil - Styropor [Rücken] - Minikid, Rekid, Duofix & Kidzone | C32: =VLOOKUP(A32,Ersatzteilpreiseliste!A:F,6,FALSE) -> 14 | D32: ü | E32: =VLOOKUP(A32,Ersatzteilpreiseliste!A:R,18,FALSE) -> 7350057583876 | G32: =IF(F32="","",H32) | H32: 2
A33: 1003215 | B33: =VLOOKUP(A33,Ersatzteilpreiseliste!A:C,3,FALSE) -> Gurtklemme schwarz | C33: =VLOOKUP(A33,Ersatzteilpreiseliste!A:F,6,FALSE) -> 6 | D33: ü | E33: =VLOOKUP(A33,Ersatzteilpreiseliste!A:R,18,FALSE) -> 7350057583906 | G33: =IF(F33="","",H33) | H33: 1
A34: 1004000 | B34: =VLOOKUP(A34,Ersatzteilpreiseliste!A:C,3,FALSE) -> Ersatzteil - Stützfuß - Minikid 1, Rekid, Wolmax, Duofix & Kidzone | C34: =VLOOKUP(A34,Ersatzteilpreiseliste!A:F,6,FALSE) -> 80 | D34: ü | E34: =VLOOKUP(A34,Ersatzteilpreiseliste!A:R,18,FALSE) -> 7350057583920 | G34: =IF(F34="","",H34) | H34: 3
A35: 1101315 | B35: =VLOOKUP(A35,Ersatzteilpreiseliste!A:C,3,FALSE) -> Ersatzteil - Gurt für Stützfuß - Minikid 1, Rekid, Wolmax, Duofix & Kidzone | C35: =VLOOKUP(A35,Ersatzteilpreiseliste!A:F,6,FALSE) -> 6 | D35: ü | E35: =VLOOKUP(A35,Ersatzteilpreiseliste!A:R,18,FALSE) -> 7350057584194 | G35: =IF(F35="","",H35) | H35: 3
A36: 1003124 | B36: =VLOOKUP(A36,Ersatzteilpreiseliste!A:C,3,FALSE) -> Ersatzteil - 5 Punkt Gurtsystem Holmberg | C36: =VLOOKUP(A36,Ersatzteilpreiseliste!A:F,6,FALSE) -> 60 | D36: ü | E36: =VLOOKUP(A36,Ersatzteilpreiseliste!A:R,18,FALSE) -> 7350057583968 | G36: =IF(F36="","",H36) | H36: 3
A37: 1003400 | B37: =VLOOKUP(A37,Ersatzteilpreiseliste!A:C,3,FALSE) -> Ersatzteil - Gurtaufroller [Links] | C37: =VLOOKUP(A37,Ersatzteilpreiseliste!A:F,6,FALSE) -> 46 | D37: ü | E37: =VLOOKUP(A37,Ersatzteilpreiseliste!A:R,18,FALSE) -> 7350057584019 | G37: =IF(F37="","",H37) | H37: 1
A38: 1003409 | B38: =VLOOKUP(A38,Ersatzteilpreiseliste!A:C,3,FALSE) -> Ersatzteil - Gurtaufroller [Rechts] | C38: =VLOOKUP(A38,Ersatzteilpreiseliste!A:F,6,FALSE) -> 46 | D38: ü | E38: =VLOOKUP(A38,Ersatzteilpreiseliste!A:R,18,FALSE) -> 7350057584026 | G38: =IF(F38="","",H38) | H38: 1
... A42: 1003207 | B42: =VLOOKUP(A42,Ersatzteilpreiseliste!A:C,3,FALSE) -> Ersatzteil - Gurtabdeckung | C42: =VLOOKUP(A42,Ersatzteilpreiseliste!A:F,6,FALSE) -> 6 | D42: ü | E42: =VLOOKUP(A42,Ersatzteilpreiseliste!A:R,18,FALSE) -> 7350057583999 | G42: =IF(F42="","",H42) | H42: 1
A43: 1900028 | B43: Nieten | C43: =VLOOKUP(A43,Ersatzteilpreiseliste!A:F,6,FALSE) -> 0.2 | D43: ü | E43: =VLOOKUP(A43,Ersatzteilpreiseliste!A:R,18,FALSE) -> 7350057584101 | G43: =IF(F43="","",H43)

Sheet Wolmax
A1: Garantieleistung - Axkid GmbH | F1: Datum:
A3: Axkid GmbH
A4: Birkenleiten 43
A5: 81543 München
A6: kundenservice@axkid.com
A9: Kunde
A10: Name | C10: Plz: | E10: Ort:
A11: Adresse
A13: Produkt
A14: Händler
A15: Reklanummer
A16: Seriennummer
A19: Aufwand | F19: =IF(SUM(F27:F45)=0,"",H19*Aufwand!C2) | H19: =IF(SUM(F27:F43)=0,"",SUM(G27:G43))
A20: Teile
A21: Reinigungspauschale (nach Zustand) Brutto
A22: Frachtkosten Brutto
A23: Enthaltene Mehrwertsteuer, 19% | F23: =IF(F24="","",F24-(F24/1.19))
A24: Garantie / Reparatur (inkl. MwSt.) | E24: Gesamt | F24: =IF(F19="","",SUM(F19:F22))
A26: Art. Nr | B26: Art. Bezeichnung | C26: Brutto VK | D26: Wolmax | E26: EAN | F26: Menge | G26: Aufwand
A27: 1002108 | B27: =VLOOKUP(A27,Ersatzteilpreiseliste!A:C,3,FALSE) -> Ersatzteil - Schaumstoff Sitzfläche Geklebt | C27: =VLOOKUP(A27,Ersatzteilpreiseliste!A:F,6,FALSE) -> 8 | D27: ü | E27: =VLOOKUP(A27,Ersatzteilpreiseliste!A:R,18,FALSE) -> 7350057583746 | G27: =IF(F27="","",H27) | H27: 1
A28: 1101232 | B28: =VLOOKUP(A28,Ersatzteilpreiseliste!A:C,3,FALSE) -> Kopfstütze | C28: =VLOOKUP(A28,Ersatzteilpreiseliste!A:F,6,FALSE) -> 24 | D28: ü | E28: =VLOOKUP(A28,Ersatzteilpreiseliste!A:R,18,FALSE) -> 7350057583784 | G28: =IF(F28="","",H28) | H28: 2
A29: 1002118 | B29: =VLOOKUP(A29,Ersatzteilpreiseliste!A:C,3,FALSE) -> Ersatzteil - Styropor [Links] - Move & Wolmax | C29: =VLOOKUP(A29,Ersatzteilpreiseliste!A:F,6,FALSE) -> 14 | D29: ü | E29: =VLOOKUP(A29,Ersatzteilpreiseliste!A:R,18,FALSE) -> 7350057583838 | G29: =IF(F29="","",H29) | H29: 2
A30: 1002119 | B30: =VLOOKUP(A30,Ersatzteilpreiseliste!A:C,3,FALSE) -> Ersatzteil - Styropor [Rechts] - Move & Wolmax | C30: =VLOOKUP(A30,Ersatzteilpreiseliste!A:F,6,FALSE) -> 14 | D30: ü | E30: =VLOOKUP(A30,Ersatzteilpreiseliste!A:R,18,FALSE) -> 7350057583845 | G30: =IF(F30="","",H30) | H30: 2
A31: 1002117 | B31: =VLOOKUP(A31,Ersatzteilpreiseliste!A:C,3,FALSE) -> Ersatzteil - Styropor [Rücken] - Move & Wolmax | C31: =VLOOKUP(A31,Ersatzteilpreiseliste!A:F,6,FALSE) -> 14 | D31: ü | E31: =VLOOKUP(A31,Ersatzteilpreiseliste!A:R,18,FALSE) -> 7350057583883 | G31: =IF(F31="","",H31) | H31: 2
A32: 1003215 | B32: =VLOOKUP(A32,Ersatzteilpreiseliste!A:C,3,FALSE) -> Gurtklemme schwarz | C32: =VLOOKUP(A32,Ersatzteilpreiseliste!A:F,6,FALSE) -> 6 | D32: ü | E32: =VLOOKUP(A32,Ersatzteilpreiseliste!A:R,18,FALSE) -> 7350057583906 | G32: =IF(F32="","",H32) | H32: 1
A33: 1004000 | B33: =VLOOKUP(A33,Ersatzteilpreiseliste!A:C,3,FALSE) -> Ersatzteil - Stützfuß - Minikid 1, Rekid, Wolmax, Duofix & Kidzone | C33: =VLOOKUP(A33,Ersatzteilpreiseliste!A:F,6,FALSE) -> 80 | D33: ü | E33: =VLOOKUP(A33,Ersatzteilpreiseliste!A:R,18,FALSE) -> 7350057583920 | G33: =IF(F33="","",H33) | H33: 3
A34: 1101315 | B34: =VLOOKUP(A34,Ersatzteilpreiseliste!A:C,3,FALSE) -> Ersatzteil - Gurt für Stützfuß - Minikid 1, Rekid, Wolmax, Duofix & Kidzone | C34: =VLOOKUP(A34,Ersatzteilpreiseliste!A:F,6,FALSE) -> 6 | D34: ü | E34: =VLOOKUP(A34,Ersatzteilpreiseliste!A:R,18,FALSE) -> 7350057584194 | G34: =IF(F34="","",H34) | H34: 3
A35: 1003124 | B35: =VLOOKUP(A35,Ersatzteilpreiseliste!A:C,3,FALSE) -> Ersatzteil - 5 Punkt Gurtsystem Holmberg | C35: =VLOOKUP(A35,Ersatzteilpreiseliste!A:F,6,FALSE) -> 60 | D35: ü | E35: =VLOOKUP(A35,Ersatzteilpreiseliste!A:R,18,FALSE) -> 7350057583968 | G35: =IF(F35="","",H35) | H35: 3
A36: 1003207 | B36: =VLOOKUP(A36,Ersatzteilpreiseliste!A:C,3,FALSE) -> Ersatzteil - Gurtabdeckung | C36: =VLOOKUP(A36,Ersatzteilpreiseliste!A:F,6,FALSE) -> 6 | D36: ü | E36: =VLOOKUP(A36,Ersatzteilpreiseliste!A:R,18,FALSE) -> 7350057583999 | G36: =IF(F36="","",H36) | H36: 1
A37: 1900028 | B37: Nieten | C37: =VLOOKUP(A37,Ersatzteilpreiseliste!A:F,6,FALSE) -> 0.2 | D37: ü | E37: =VLOOKUP(A37,Ersatzteilpreiseliste!A:R,18,FALSE) -> 7350057584101

Sheet Duofix
A1: Garantieleistung - Axkid GmbH | F1: Datum:
A3: Axkid GmbH
A4: Birkenleiten 43
A5: 81543 München
A6: kundenservice@axkid.com
A9: Kunde
A10: Name | C10: Plz: | E10: Ort:
A11: Adresse
A13: Produkt
A14: Händler
A15: Reklanummer
A16: Seriennummer
A19: Aufwand | F19: =IF(SUM(F27:F45)=0,"",H19*Aufwand!C2) | H19: =IF(SUM(F27:F43)=0,"",SUM(G27:G43))
A20: Teile
A21: Reinigungspauschale (nach Zustand) Brutto
A22: Frachtkosten Brutto
A23: Enthaltene Mehrwertsteuer, 19% | F23: =IF(F24="","",F24-(F24/1.19))
A24: Garantie / Reparatur (inkl. MwSt.) | E24: Gesamt | F24: =IF(F19="","",SUM(F19:F22))
A26: Art. Nr | B26: Art. Bezeichnung | C26: Brutto VK | D26: Duofix | E26: EAN | F26: Menge | G26: Aufwand
A27: 1002108 | B27: =VLOOKUP(A27,Ersatzteilpreiseliste!A:C,3,FALSE) -> Ersatzteil - Schaumstoff Sitzfläche Geklebt | C27: =VLOOKUP(A27,Ersatzteilpreiseliste!A:F,6,FALSE) -> 8 | D27: ü | E27: =VLOOKUP(A27,Ersatzteilpreiseliste!A:R,18,FALSE) -> 7350057583746 | G27: =IF(F27="","",H27) | H27: 1
A28: 1006000 | B28: =VLOOKUP(A28,Ersatzteilpreiseliste!A:C,3,FALSE) -> Ersatzteil - Kopfstütze - Duofix & Kidzofix | C28: =VLOOKUP(A28,Ersatzteilpreiseliste!A:F,6,FALSE) -> 26 | D28: ü | E28: =VLOOKUP(A28,Ersatzteilpreiseliste!A:R,18,FALSE) -> 7350057583791 | G28: =IF(F28="","",H28) | H28: 2
A29: 1101197 | B29: =VLOOKUP(A29,Ersatzteilpreiseliste!A:C,3,FALSE) -> Ersatzteil - Kopfstütze Rückenplatte - Minikid, Modukid Seat, Rekid, Duofix & Kidzone | C29: =VLOOKUP(A29,Ersatzteilpreiseliste!A:F,6,FALSE) -> 20 | D29: ü | E29: =VLOOKUP(A29,Ersatzteilpreiseliste!A:R,18,FALSE) -> 7350057583807 | G29: =IF(F29="","",H29) | H29: 2
A30: 1002103 | B30: =VLOOKUP(A30,Ersatzteilpreiseliste!A:C,3,FALSE) -> Ersatzteil - Styropor [Links] - Minikid, Rekid, Duofix & Kidzone | C30: =VLOOKUP(A30,Ersatzteilpreiseliste!A:F,6,FALSE) -> 14 | D30: ü | E30: =VLOOKUP(A30,Ersatzteilpreiseliste!A:R,18,FALSE) -> 7350057583852 | G30: =IF(F30="","",H30) | H30: 2
A31: 1002104 | B31: =VLOOKUP(A31,Ersatzteilpreiseliste!A:C,3,FALSE) -> Ersatzteil - Styropor [Rechts] - Minikid, Rekid, Duofix & Kidzone | C31: =VLOOKUP(A31,Ersatzteilpreiseliste!A:F,6,FALSE) -> 14 | D31: ü | E31: =VLOOKUP(A31,Ersatzteilpreiseliste!A:R,18,FALSE) -> 7350057583869 | G31: =IF(F31="","",H31) | H31: 2
A32: 1002101 | B32: =VLOOKUP(A32,Ersatzteilpreiseliste!A:C,3,FALSE) -> Ersatzteil - Styropor [Rücken] - Minikid, Rekid, Duofix & Kidzone | C32: =VLOOKUP(A32,Ersatzteilpreiseliste!A:F,6,FALSE) -> 14 | D32: ü | E32: =VLOOKUP(A32,Ersatzteilpreiseliste!A:R,18,FALSE) -> 7350057583876 | G32: =IF(F32="","",H32) | H32: 2
A33: 1003215 | B33: =VLOOKUP(A33,Ersatzteilpreiseliste!A:C,3,FALSE) -> Gurtklemme schwarz | C33: =VLOOKUP(A33,Ersatzteilpreiseliste!A:F,6,FALSE) -> 6 | D33: ü | E33: =VLOOKUP(A33,Ersatzteilpreiseliste!A:R,18,FALSE) -> 7350057583906 | G33: =IF(F33="","",H33) | H33: 1
A34: 1004000 | B34: =VLOOKUP(A34,Ersatzteilpreiseliste!A:C,3,FALSE) -> Ersatzteil - Stützfuß - Minikid 1, Rekid, Wolmax, Duofix & Kidzone | C34: =VLOOKUP(A34,Ersatzteilpreiseliste!A:F,6,FALSE) -> 80 | D34: ü | E34: =VLOOKUP(A34,Ersatzteilpreiseliste!A:R,18,FALSE) -> 7350057583920 | G34: =IF(F34="","",H34) | H34: 3
A35: 1101315 | B35: =VLOOKUP(A35,Ersatzteilpreiseliste!A:C,3,FALSE) -> Ersatzteil - Gurt für Stützfuß - Minikid 1, Rekid, Wolmax, Duofix & Kidzone | C35: =VLOOKUP(A35,Ersatzteilpreiseliste!A:F,6,FALSE) -> 6 | D35: ü | E35: =VLOOKUP(A35,Ersatzteilpreiseliste!A:R,18,FALSE) -> 7350057584194 | G35: =IF(F35="","",H35) | H35: 3
A36: 1003124 | B36: =VLOOKUP(A36,Ersatzteilpreiseliste!A:C,3,FALSE) -> Ersatzteil - 5 Punkt Gurtsystem Holmberg | C36: =VLOOKUP(A36,Ersatzteilpreiseliste!A:F,6,FALSE) -> 60 | D36: ü | E36: =VLOOKUP(A36,Ersatzteilpreiseliste!A:R,18,FALSE) -> 7350057583968 | G36: =IF(F36="","",H36) | H36: 3
A37: 1003400 | B37: =VLOOKUP(A37,Ersatzteilpreiseliste!A:C,3,FALSE) -> Ersatzteil - Gurtaufroller [Links] | C37: =VLOOKUP(A37,Ersatzteilpreiseliste!A:F,6,FALSE) -> 46 | D37: ü | E37: =VLOOKUP(A37,Ersatzteilpreiseliste!A:R,18,FALSE) -> 7350057584019 | G37: =IF(F37="","",H37) | H37: 1
A38: 1003409 | B38: =VLOOKUP(A38,Ersatzteilpreiseliste!A:C,3,FALSE) -> Ersatzteil - Gurtaufroller [Rechts] | C38: =VLOOKUP(A38,Ersatzteilpreiseliste!A:F,6,FALSE) -> 46 | D38: ü | E38: =VLOOKUP(A38,Ersatzteilpreiseliste!A:R,18,FALSE) -> 7350057584026 | G38: =IF(F38="","",H38) | H38: 1
A39: 1003207 | B39: =VLOOKUP(A39,Ersatzteilpreiseliste!A:C,3,FALSE) -> Ersatzteil - Gurtabdeckung | C39: =VLOOKUP(A39,Ersatzteilpreiseliste!A:F,6,FALSE) -> 6 | D39: ü | E39: =VLOOKUP(A39,Ersatzteilpreiseliste!A:R,18,FALSE) -> 7350057583999 | G39: =IF(F39="","",H39) | H39: 1
A40: 1900028 | B40: Nieten | C40: =VLOOKUP(A40,Ersatzteilpreiseliste!A:F,6,FALSE) -> 0.2 | D40: ü | E40: =VLOOKUP(A40,Ersatzteilpreiseliste!A:R,18,FALSE) -> 7350057584101

Sheet Kidzone
A1: Garantieleistung - Axkid GmbH | F1: Datum:
A3: Axkid GmbH
A4: Birkenleiten 43
A5: 81543 München
A6: kundenservice@axkid.com
A9: Kunde
A10: Name | C10: Plz: | E10: Ort:
A11: Adresse
A13: Produkt
A14: Händler
A15: Reklanummer
A16: Seriennummer
A19: Aufwand | F19: =IF(SUM(F27:F45)=0,"",H19*Aufwand!C2) | H19: =IF(SUM(F27:F43)=0,"",SUM(G27:G43))
A20: Teile
A21: Reinigungspauschale (nach Zustand) Brutto
A22: Frachtkosten Brutto
A23: Enthaltene Mehrwertsteuer, 19% | F23: =IF(F24="","",F24-(F24/1.19))
A24: Garantie / Reparatur (inkl. MwSt.) | E24: Gesamt | F24: =IF(F19="","",SUM(F19:F22))
A26: Art. Nr | B26: Art. Bezeichnung | C26: Brutto VK | D26: Kidzone | E26: EAN | F26: Menge | G26: Aufwand
A27: 1002108 | B27: =VLOOKUP(A27,Ersatzteilpreiseliste!A:C,3,FALSE) -> Ersatzteil - Schaumstoff Sitzfläche Geklebt | C27: =VLOOKUP(A27,Ersatzteilpreiseliste!A:F,6,FALSE) -> 8 | D27: ü | E27: =VLOOKUP(A27,Ersatzteilpreiseliste!A:R,18,FALSE) -> 7350057583746 | G27: =IF(F27="","",H27) | H27: 1
A28: 1006000 | B28: =VLOOKUP(A28,Ersatzteilpreiseliste!A:C,3,FALSE) -> Ersatzteil - Kopfstütze - Duofix & Kidzofix | C28: =VLOOKUP(A28,Ersatzteilpreiseliste!A:F,6,FALSE) -> 26 | D28: ü | E28: =VLOOKUP(A28,Ersatzteilpreiseliste!A:R,18,FALSE) -> 7350057583791 | G28: =IF(F28="","",H28) | H28: 2
A29: 1101197 | B29: =VLOOKUP(A29,Ersatzteilpreiseliste!A:C,3,FALSE) -> Ersatzteil - Kopfstütze Rückenplatte - Minikid, Modukid Seat, Rekid, Duofix & Kidzone | C29: =VLOOKUP(A29,Ersatzteilpreiseliste!A:F,6,FALSE) -> 20 | D29: ü | E29: =VLOOKUP(A29,Ersatzteilpreiseliste!A:R,18,FALSE) -> 7350057583807 | G29: =IF(F29="","",H29) | H29: 2
A30: 1002103 | B30: =VLOOKUP(A30,Ersatzteilpreiseliste!A:C,3,FALSE) -> Ersatzteil - Styropor [Links] - Minikid, Rekid, Duofix & Kidzone | C30: =VLOOKUP(A30,Ersatzteilpreiseliste!A:F,6,FALSE) -> 14 | D30: ü | E30: =VLOOKUP(A30,Ersatzteilpreiseliste!A:R,18,FALSE) -> 7350057583852 | G30: =IF(F30="","",H30) | H30: 2
A31: 1002104 | B31: =VLOOKUP(A31,Ersatzteilpreiseliste!A:C,3,FALSE) -> Ersatzteil - Styropor [Rechts] - Minikid, Rekid, Duofix & Kidzone | C31: =VLOOKUP(A31,Ersatzteilpreiseliste!A:F,6,FALSE) -> 14 | D31: ü | E31: =VLOOKUP(A31,Ersatzteilpreiseliste!A:R,18,FALSE) -> 7350057583869 | G31: =IF(F31="","",H31) | H31: 2
A32: 1002101 | B32: =VLOOKUP(A32,Ersatzteilpreiseliste!A:C,3,FALSE) -> Ersatzteil - Styropor [Rücken] - Minikid, Rekid, Duofix & Kidzone | C32: =VLOOKUP(A32,Ersatzteilpreiseliste!A:F,6,FALSE) -> 14 | D32: ü | E32: =VLOOKUP(A32,Ersatzteilpreiseliste!A:R,18,FALSE) -> 7350057583876 | G32: =IF(F32="","",H32) | H32: 2
A33: 1003215 | B33: =VLOOKUP(A33,Ersatzteilpreiseliste!A:C,3,FALSE) -> Gurtklemme schwarz | C33: =VLOOKUP(A33,Ersatzteilpreiseliste!A:F,6,FALSE) -> 6 | D33: ü | E33: =VLOOKUP(A33,Ersatzteilpreiseliste!A:R,18,FALSE) -> 7350057583906 | G33: =IF(F33="","",H33) | H33: 1
A34: 1004000 | B34: =VLOOKUP(A34,Ersatzteilpreiseliste!A:C,3,FALSE) -> Ersatzteil - Stützfuß - Minikid 1, Rekid, Wolmax, Duofix & Kidzone | C34: =VLOOKUP(A34,Ersatzteilpreiseliste!A:F,6,FALSE) -> 80 | D34: ü | E34: =VLOOKUP(A34,Ersatzteilpreiseliste!A:R,18,FALSE) -> 7350057583920 | G34: =IF(F34="","",H34) | H34: 3
A35: 1101315 | B35: =VLOOKUP(A35,Ersatzteilpreiseliste!A:C,3,FALSE) -> Ersatzteil - Gurt für Stützfuß - Minikid 1, Rekid, Wolmax, Duofix & Kidzone | C35: =VLOOKUP(A35,Ersatzteilpreiseliste!A:F,6,FALSE) -> 6 | D35: ü | E35: =VLOOKUP(A35,Ersatzteilpreiseliste!A:R,18,FALSE) -> 7350057584194 | G35: =IF(F35="","",H35) | H35: 3
A36: 1003124 | B36: =VLOOKUP(A36,Ersatzteilpreiseliste!A:C,3,FALSE) -> Ersatzteil - 5 Punkt Gurtsystem Holmberg | C36: =VLOOKUP(A36,Ersatzteilpreiseliste!A:F,6,FALSE) -> 60 | D36: ü | E36: =VLOOKUP(A36,Ersatzteilpreiseliste!A:R,18,FALSE) -> 7350057583968 | G36: =IF(F36="","",H36) | H36: 3
A37: 1003207 | B37: =VLOOKUP(A37,Ersatzteilpreiseliste!A:C,3,FALSE) -> Ersatzteil - Gurtabdeckung | C37: =VLOOKUP(A37,Ersatzteilpreiseliste!A:F,6,FALSE) -> 6 | D37: ü | E37: =VLOOKUP(A37,Ersatzteilpreiseliste!A:R,18,FALSE) -> 7350057583999 | G37: =IF(F37="","",H37) | H37: 1
A38: 1900028 | B38: Nieten | C38: =VLOOKUP(A38,Ersatzteilpreiseliste!A:F,6,FALSE) -> 0.2 | D38: ü | E38: =VLOOKUP(A38,Ersatzteilpreiseliste!A:R,18,FALSE) -> 7350057584101

Sheet Ersatzteilpreiseliste
A1: Ersatzteile
A2: Art. Nr | B2: Part name | C2: Artikel | D2: Netto EK | E2: Netto VK | F2: Brutto VK | G2: Axkid ONE | H2: Axkid ONE + | I2: Modukid Seat | J2: Modukid Infant | K2: Minikid 2.0 | L2: Minikid 1.0 | M2: Rekid | N2: Move | O2: Wolmax | P2: Duofix | Q2: Kidzone | R2: EAN | S2: Box Size（cm） | T2: Gross Weight | U2: N.T Weight
A3: 1002101 | B3: EPS Back support (Minikid) | C3: Ersatzteil - Styropor [Rücken] - Minikid, Rekid, Duofix & Kidzone | D3: 7 | E3: =F3/1.19 -> 11.764706 | F3: =D3*2 -> 14 | I3: ü | K3: ü | L3: ü | M3: ü | P3: ü | Q3: ü | R3: 7350057583876 | S3: 10X12X18 | T3: 0.62 | U3: 0.55
A4: 1002103 | B4: 1002103 | C4: Ersatzteil - Styropor [Links] - Minikid, Rekid, Duofix & Kidzone | D4: 7 | E4: =F4/1.19 -> 11.764706 | F4: =D4*2 -> 14 | L4: ü | M4: ü | P4: ü | Q4: ü | R4: 7350057583852 | S4: 10X12X18 | T4: 0.46 | U4: 0.39
A5: 1002104 | B5: EPS seat right (Minikid 1.0) | C5: Ersatzteil - Styropor [Rechts] - Minikid, Rekid, Duofix & Kidzone | D5: 7 | E5: =F5/1.19 -> 11.764706 | F5: =D5*2 -> 14 | L5: ü | M5: ü | P5: ü | Q5: ü | R5: 7350057583869 | S5: 10X12X18 | T5: 0.62 | U5: 0.55
A6: 1002108 | B6: Seat cushion fixed | C6: Ersatzteil - Schaumstoff Sitzfläche Geklebt | D6: 4 | E6: =F6/1.19 -> 6.7226891 | F6: =D6*2 -> 8 | K6: ü | L6: ü | M6: ü | N6: ü | O6: ü | P6: ü | Q6: ü | R6: 7350057583746 | S6: 48X32X22 | T6: 0.5 | U6: 0.14
A7: 1002112 | B7: Seat cushion | C7: Ersatzteil - Schaumstoff Sitzfläche | D7: 3 | E7: =F7/1.19 -> 5.0420168 | F7: =D7*2 -> 6 | I7: ü | K7: ü | L7: ü | M7: ü | N7: ü | O7: ü | P7: ü | Q7: ü | R7: 7350057583722 | S7: 40X40X50 | T7: 3 | U7: 2.2
A8: 1002117 | B8: EPS Back support (Move, Wolmax) | C8: Ersatzteil - Styropor [Rücken] - Move & Wolmax | D8: 7 | E8: =F8/1.19 -> 11.764706 | F8: =D8*2 -> 14 | N8: ü | O8: ü | R8: 7350057583883 | S8: 10X12X18 | T8: 0.32 | U8: 0.22
A9: 1002118 | B9: EPS seat left (Move, Wolmax) | C9: Ersatzteil - Styropor [Links] - Move & Wolmax | D9: 7 | E9: =F9/1.19 -> 11.764706 | F9: =D9*2 -> 14 | N9: ü | O9: ü | R9: 7350057583838 | S9: 23X13X16.5 | T9: 1.16 | U9: 1
A10: 1002119 | B10: EPS seat right (Move, Wolmax) | C10: Ersatzteil - Styropor [Rechts] - Move & Wolmax | D10: 7 | E10: =F10/1.19 -> 11.764706 | F10: =D10*2 -> 14 | N10: ü | O10: ü | R10: 7350057583845 | S10: 47X18X24 | T10: 14.5 | U10: 13.9
A11: 1002201 | B11: Support leg holder | C11: Stützfußhalter | D11: 2 | E11: =F11/1.19 -> 3.3613445 | F11: =D11*2 -> 4 | P11: ü | Q11: ü | R11: 7350057584002 | S11: 57X24.5X28 | T11: 2.6 | U11: 2.5
A12: 1002202 | B12: Textile cover christmas tree | C12: Ersatzteil - Tannenbaum | D12: 3 | E12: =F12/1.19 -> 5.0420168 | F12: =D12*2 -> 6 | K12: ü | L12: ü | M12: ü | N12: ü | O12: ü | P12: ü | Q12: ü | R12: 7350057583395 | S12: 29X18X12 | T12: 0.7 | U12: 0.5
A13: 1002220 | B13: Rubber Handle (Modukid Infant) | C13: Tragegriff | D13: 0 | E13: =F13/1.19 -> 0 | F13: =D13*2 -> 0 | J13: ü | R13: 7350057585146
A14: 1002287 | B14: EPS seat left (Minikid 2.0) | C14: Ersatzteil - Styropor [Links] - Minikid 2 | D14: 7 | E14: =F14/1.19 -> 11.764706 | F14: =D14*2 -> 14 | K14: ü | R14: 7350057583814 | S14: 57X24.5X28 | T14: 0.83 | U14: 0.34
A15: 1002288 | B15: EPS seat right (Minikid 2.0) | C15: Ersatzteil - Styropor [Rechts] - Minikid 2 | D15: 7 | E15: =F15/1.19 -> 11.764706 | F15: =D15*2 -> 14 | K15: ü | R15: 7350057583821 | S15: 23X13X16.5 | T15: 1.16 | U15: 1
A16: 1002321 | B16: Seat cushion fixed (Modukid) | C16: Ersatzteil - Schaumstoff Sitzfläche Geklebt - Modukid Seat | D16: 4 | E16: =F16/1.19 -> 6.7226891 | F16: =D16*2 -> 8 | I16: ü | R16: 7350057583739 | S16: 38X40X22 | T16: 3.45 | U16: 3
A17: 1003124 | B17: 5-point harness (Holmbergs) + 4 rivets | C17: Ersatzteil - 5 Punkt Gurtsystem Holmberg | D17: 30 | E17: =F17/1.19 -> 50.420168 | F17: =D17*2 -> 60 | K17: ü | L17: ü | M17: ü | N17: ü | O17: ü | P17: ü | Q17: ü | R17: 7350057583968 | S17: 23X13X16.5 | T17: 2.52 | U17: 2.38
A18: 1003126 | B18: Harness adjuster strap (Holmbergs) | C18: Verstellriemen - Holmberg | D18: 5 | E18: =F18/1.19 -> 8.4033613 | F18: =D18*2 -> 10 | K18: ü | L18: ü | M18: ü | N18: ü | O18: ü | P18: ü | Q18: ü | R18: 7350057583982 | S18: 34X35X20 | T18: 1.8 | U18: 1.4
A19: 1003207 | B19: Harness adjuster cover + 2 rivets | C19: Ersatzteil - Gurtabdeckung | D19: 3 | E19: =F19/1.19 -> 5.0420168 | F19: =D19*2 -> 6 | K19: ü | L19: ü | M19: ü | N19: ü | O19: ü | P19: ü | Q19: ü | R19: 7350057583999 | S19: 34X35X28 | T19: 2.12 | U19: 1.72
A20: 1003215 | B20: Belt clip black | C20: Gurtklemme schwarz | D20: 3 | E20: =F20/1.19 -> 5.0420168 | F20: =D20*2 -> 6 | L20: ü | M20: ü | O20: ü | P20: ü | Q20: ü | R20: 7350057583906 | S20: 23X13X16.5 | T20: 1.23 | U20: 1.1
A21: 1003400 | B21: Side retractor Left | C21: Ersatzteil - Gurtaufroller [Links] | D21: 23 | E21: =F21/1.19 -> 38.655462 | F21: =D21*2 -> 46 | K21: ü | L21: ü | M21: ü | P21: ü | R21: 7350057584019 | S21: 10X12X18 | T21: 0.16 | U21: 0.12
A22: 1003409 | B22: Side retractor Right | C22: Ersatzteil - Gurtaufroller [Rechts] | D22: 23 | E22: =F22/1.19 -> 38.655462 | F22: =D22*2 -> 46 | K22: ü | L22: ü | M22: ü | P22: ü | R22: 7350057584026 | S22: 10X12X18 | T22: 0.14 | U22: 0.1
A23: 1004000 | B23: Support leg (Minikid 1.0) | C23: Ersatzteil - Stützfuß - Minikid 1, Rekid, Wolmax, Duofix & Kidzone | D23: 40 | E23: =F23/1.19 -> 67.226891 | F23: =D23*2 -> 80 | L23: ü | M23: ü | O23: ü | P23: ü | Q23: ü | R23: 7350057583920 | S23: 10X12X18 | T23: 0.6 | U23: 0.55
A24: 1004102 | B24: Support leg rubber foot (old) | C24: Ersatzteil - Gummifuß - Minikid 1 & Rekid | D24: 3 | E24: =F24/1.19 -> 5.0420168 | F24: =D24*2 -> 6 | L24: ü | M24: ü | O24: ü | P24: ü | Q24: ü | R24: 7350057583944 | S24: 29X18X20 | T24: 4.5 | U24: 4.25
A25: 1004445 | B25: Support leg (Minikid 2.0) | C25: Ersatzteil - Stützfuß - Minikid 2 & Move | D25: 30 | E25: =F25/1.19 -> 50.420168 | F25: =D25*2 -> 60 | K25: ü | N25: ü | R25: 7350057583913 | S25: 29X18X20 | T25: 1.25 | U25: 1.12
A26: 1004453 | B26: Support leg rubber foot (new) | C26: Ersatzteil - Gummifuß - Minikid 2 & Move | D26: 3 | E26: =F26/1.19 -> 5.0420168 | F26: =D26*2 -> 6 | K26: ü | N26: ü | R26: 7350057583937 | S26: 29X18X20 | T26: 1.06 | U26: 0.84
A27: 1005204 | B27: Isofix LH Modukid Base | C27: Isofix Base | D27: 0 | E27: =F27/1.19 -> 0 | F27: =D27*2 -> 0 | I27: ü | J27: ü | R27: 7350057584231
A28: 1005205 | B28: Isofix RH Modukid Base | C28: Isofix Base | D28: 0 | E28: =F28/1.19 -> 0 | F28: =D28*2 -> 0 | I28: ü | J28: ü | R28: 7350057584248
A29: 1006000 | B29: Head support Unit (Duofix, Kidzone) | C29: Ersatzteil - Kopfstütze - Duofix & Kidzofix | D29: 13 | E29: =F29/1.19 -> 21.848739 | F29: =D29*2 -> 26 | P29: ü | Q29: ü | R29: 7350057583791 | S29: 26X33X22 | T29: 0.32 | U29: 0.11
A30: 1006003 | B30: Head support Unit (Minikid 1.0, Rekid) | C30: Ersatzteil - Kopfstütze - Minikid 1 & Rekid | D30: 13 | E30: =F30/1.19 -> 21.848739 | F30: =D30*2 -> 26 | L30: ü | M30: ü | R30: 7350057583777 | S30: 57X25X28 | T30: 0.63 | U30: 0.17
A31: 1006504 | B31: Head support Unit (Minikid 2.0) | C31: Ersatzteil - Kopfstütze - Minikid 2 | D31: 13 | E31: =F31/1.19 -> 21.848739 | F31: =D31*2 -> 26 | K31: ü | R31: 7350057583760 | S31: 57X25X28 | T31: 0.63 | U31: 0.17
A32: 1007215 | B32: Textile cover attachment pin | C32: Ersatzteil - Strohhalm | D32: 3 | E32: =F32/1.19 -> 5.0420168 | F32: =D32*2 -> 6 | I32: ü | K32: ü | L32: ü | M32: ü | N32: ü | O32: ü | P32: ü | Q32: ü | R32: 7350057583388 | S32: 23X13X16.5 | T32: 0.5 | U32: 0.36
A33: 1100710 | B33: Cover Red (Modukid) | C33: Bezug rot | D33: 40 | E33: =F33/1.19 -> 67.226891 | F33: =D33*2 -> 80 | I33: ü | R33: 7350057583012 | S33: 40X40X50 | T33: 3.7 | U33: 2.95
A34: 1100711 | B34: Textile cover head support (Modu) | C34: Bezug Kopfstütze | D34: 8 | E34: =F34/1.19 -> 13.445378 | F34: =D34*2 -> 16 | I34: ü | R34: 7350057583654 | S34: 29X18X20 | T34: 0.6 | U34: 0.4
A35: 1100714 | B35: Textile cover buckle Red (Modu, Mini) | C35: Ersatzteil - Gurtschlosspolster - Minikid 2 & Modukid Seat [Rot] | D35: 3 | E35: =F35/1.19 -> 5.0420168 | F35: =D35*2 -> 6 | I35: ü | K35: ü | R35: 7350057583562 | S35: 10X12X18 | T35: 0.23 | U35: 0.17
A36: 1100715 | B36: Headrest insert Black (Modukid) | C36: Kopfstützen Einlage schwarz | D36: 5 | E36: =F36/1.19 -> 8.4033613 | F36: =D36*2 -> 10 | I36: ü | R36: 7350057584170 | S36: 40X40X50 | T36: 3 | U36: 2.2
A37: 1100733 | B37: Cover Red (Modukid Infant) | C37: Bezug rot | D37: 40 | E37: =F37/1.19 -> 67.226891 | F37: =D37*2 -> 80 | J37: ü | R37: 7350057583067 | S37: 40X40X50 | T37: 2.25 | U37: 1.5
A38: 1100734 | B38: Sunscreen Black | C38: Zubehör - Sonnenschutz - Modukid Infant [Schwarz] | D38: 7 | E38: =F38/1.19 -> 11.764706 | F38: =D38*2 -> 14 | J38: ü | R38: 7350057584118 | S38: 44X27X23.5 | T38: 7.3 | U38: 6.85
A39: 1100735 | B39: Shoulder pads Black (Modukid Infant) | C39: Schulterpolster schwarz | D39: 3 | E39: =F39/1.19 -> 5.0420168 | F39: =D39*2 -> 6 | J39: ü | R39: 7350057583456 | S39: 29X18X12 | T39: 0.7 | U39: 0.5
A40: 1100736 | B40: Textile cover buckle Black (Modu Infant) | C40: Gurtschlosspolster schwarz | D40: 2 | E40: =F40/1.19 -> 3.3613445 | F40: =D40*2 -> 4 | J40: ü | R40: 7350057583630 | S40: 29X18X20 | T40: 0.62 | U40: 0.41
...

Sheet Aufwand
A1: Aufwand-Klasse | B1: Betrag Netto | C1: Betrag Brutto
A2: 1 | B2: =A2*B7 -> 15 | C2: =B2*1.19 -> 17.85
A3: 2 | B3: =A3*B7 -> 30 | C3: =B3*1.19 -> 35.7
A4: 3 | B4: =A4*B7 -> 45 | C4: =B4*1.19 -> 53.55
A5: 4 | B5: =A5*B7 -> 60 | C5: =B5*1.19 -> 71.4
A7: Pauschale aufwand | B7: 15 | C7: =B7*1.19 -> 17.85

Sheet USD GBP
A1: Axkid spare parts
A2: Art. Nr | B2: Part name | C2: USD | D2: GBP (dist) | E2: GBP (ret) | F2: Modukid Seat | G2: Modukid Infant | H2: Minikid (2018) | I2: Minikid (2017 and earlier) | J2: Rekid | K2: Move | L2: Wolmax | M2: Duofix | N2: Kidzone | O2: Babyfix
A3: 1100710 | B3: Cover Red | C3: 28 | D3: 13 | E3: 22 | F3: ü
A4: 1100836 | B4: Cover Grey | C4: 28 | D4: 13 | E4: 22 | F4: ü
A5: 1100841 | B5: Cover Black | C5: 28 | D5: 13 | E5: 22 | F5: ü
A6: 1100846 | B6: Cover Petrol | C6: 28 | D6: 13 | E6: 22 | F6: ü
A7: 1100851 | B7: Cover Pink | C7: 28 | D7: 13 | E7: 22 | F7: ü
A8: 1100733 | B8: Cover Red | C8: 28 | D8: 13 | E8: 22 | G8: ü
A9: 1100824 | B9: Cover Grey | C9: 28 | D9: 13 | E9: 22 | G9: ü
A10: 1100827 | B10: Cover Black | C10: 28 | D10: 13 | E10: 22 | G10: ü
A11: 1100829 | B11: Cover Petrol | C11: 28 | D11: 13 | E11: 22 | G11: ü
A12: 1100831 | B12: Cover Pink | C12: 28 | D12: 13 | E12: 22 | G12: ü
A13: 1100961 | B13: Cover Red | C13: 28 | D13: 13 | E13: 22 | H13: ü
A14: 1101176 | B14: Cover Grey | C14: 28 | D14: 13 | E14: 22 | H14: ü
A15: 1101177 | B15: Cover Black | C15: 28 | D15: 13 | E15: 22 | H15: ü
A16: 1101178 | B16: Cover Blue | C16: 28 | D16: 13 | E16: 22 | H16: ü
A17: 1101179 | B17: Cover Green | C17: 28 | D17: 13 | E17: 22 | H17: ü
A18: 1101180 | B18: Cover Petrol | C18: 28 | D18: 13 | E18: 22 | H18: ü
A19: 1101181 | B19: Cover Pink | C19: 28 | D19: 13 | E19: 22 | H19: ü
A20: 1101216 | B20: Cover Red | C20: 28 | D20: 13 | E20: 22 | I20: ü
A21: 1101217 | B21: Cover Grey | C21: 28 | D21: 13 | E21: 22 | I21: ü
A22: 1101218 | B22: Cover Black | C22: 28 | D22: 13 | E22: 22 | I22: ü
A23: 1101219 | B23: Cover Petrol | C23: 28 | D23: 13 | E23: 22 | I23: ü
A24: 1101220 | B24: Cover Green | C24: 28 | D24: 13 | E24: 22 | I24: ü
A25: 1101221 | B25: Cover Red | C25: 28 | D25: 13 | E25: 22 | J25: ü
A26: 1101222 | B26: Cover Grey | C26: 28 | D26: 13 | E26: 22 | J26: ü
A27: 1101223 | B27: Cover Black | C27: 28 | D27: 13 | E27: 22 | J27: ü
A28: 1101224 | B28: Cover Petrol | C28: 28 | D28: 13 | E28: 22 | J28: ü
A29: 1101225 | B29: Cover Grey | C29: 28 | D29: 13 | E29: 22 | K29: ü
A30: 1101226 | B30: Cover Black | C30: 28 | D30: 13 | E30: 22 | K30: ü
A31: 1101227 | B31: Cover Black | C31: 28 | D31: 13 | E31: 22 | L31: ü
A32: 1101236 | B32: Cover Red | C32: 28 | D32: 13 | E32: 22 | M32: ü
A33: 1101237 | B33: Cover Grey | C33: 28 | D33: 13 | E33: 22 | M33: ü
A34: 1101228 | B34: Cover Black | C34: 28 | D34: 13 | E34: 22 | M34: ü
A35: 1101238 | B35: Cover Petrol | C35: 28 | D35: 13 | E35: 22 | M35: ü
A36: 1101239 | B36: Cover Red | C36: 28 | D36: 13 | E36: 22 | N36: ü
A37: 1101240 | B37: Cover Grey | C37: 28 | D37: 13 | E37: 22 | N37: ü
A38: 1101229 | B38: Cover Black | C38: 28 | D38: 13 | E38: 22 | N38: ü
A39: 1101241 | B39: Cover Petrol | C39: 28 | D39: 13 | E39: 22 | N39: ü
A40: 1007215 | B40: Textile cover attachment pin | C40: 1 | D40: 0.5 | E40: 1 | F40: ü | H40: ü | I40: ü | J40: ü | K40: ü | L40: ü | M40: ü | N40: ü
...
