Workbook

Sheet Ersatzteilpreisliste
A1: ERSATZTEILE
A2: Art. Nr | B2: Part name | C2: Artikel | D2: Netto EK | E2: Netto VK | F2: Brutto VK | G2: Axkid ONE | H2: Axkid ONE + | I2: Minikid 2.0 | J2: Move | K2: Rekid | L2: Modukid Seat | M2: Modukid Infant | N2: Minikid 1.0 | O2: Wolmax | P2: Duofix | Q2: Kidzone | R2: EAN | S2: Box Size（cm） | T2: Gross Weight | U2: N.T Weight
A3: 1002101 | B3: EPS Back support (Minikid) | C3: =VLOOKUP(A3,Artikeldaten!A:B,2,0) -> Styropor [Rücken] - Minikid, Rekid, Duofix & Kidzone | D3: 7 | E3: =F3/1.19 -> 11.764706 | F3: =D3*2 -> 14 | I3: ü | K3: ü | L3: ü | N3: ü | P3: ü | Q3: ü | R3: 7350057583876 | S3: 10X12X18 | T3: 0.62 | U3: 0.55
A4: 1002103 | B4: 1002103 | C4: =VLOOKUP(A4,Artikeldaten!A:B,2,0) -> Styropor [Links] - Minikid, Rekid, Duofix & Kidzone | D4: 7 | E4: =F4/1.19 -> 11.764706 | F4: =D4*2 -> 14 | K4: ü | N4: ü | P4: ü | Q4: ü | R4: 7350057583852 | S4: 10X12X18 | T4: 0.46 | U4: 0.39
A5: 1002104 | B5: EPS seat right (Minikid 1.0) | C5: =VLOOKUP(A5,Artikeldaten!A:B,2,0) -> Styropor [Rechts] - Minikid, Rekid, Duofix & Kidzone | D5: 7 | E5: =F5/1.19 -> 11.764706 | F5: =D5*2 -> 14 | K5: ü | N5: ü | P5: ü | Q5: ü | R5: 7350057583869 | S5: 10X12X18 | T5: 0.62 | U5: 0.55
A6: 1002108 | B6: Seat cushion fixed | C6: =VLOOKUP(A6,Artikeldaten!A:B,2,0) -> Schaumstoff Sitzfläche Geklebt | D6: 4 | E6: =F6/1.19 -> 6.7226891 | F6: =D6*2 -> 8 | I6: ü | J6: ü | K6: ü | N6: ü | O6: ü | P6: ü | Q6: ü | R6: 7350057583746 | S6: 48X32X22 | T6: 0.5 | U6: 0.14
A7: 1002112 | B7: Seat cushion | C7: =VLOOKUP(A7,Artikeldaten!A:B,2,0) -> Schaumstoff Sitzfläche | D7: 3 | E7: =F7/1.19 -> 5.0420168 | F7: =D7*2 -> 6 | I7: ü | J7: ü | K7: ü | L7: ü | N7: ü | O7: ü | P7: ü | Q7: ü | R7: 7350057583722 | S7: 40X40X50 | T7: 3 | U7: 2.2
A8: 1002117 | B8: EPS Back support (Move, Wolmax) | C8: =VLOOKUP(A8,Artikeldaten!A:B,2,0) -> Styropor [Rücken] - Move & Wolmax | D8: 7 | E8: =F8/1.19 -> 11.764706 | F8: =D8*2 -> 14 | J8: ü | O8: ü | R8: 7350057583883 | S8: 10X12X18 | T8: 0.32 | U8: 0.22
A9: 1002118 | B9: EPS seat left (Move, Wolmax) | C9: =VLOOKUP(A9,Artikeldaten!A:B,2,0) -> Styropor [Links] - Move & Wolmax | D9: 7 | E9: =F9/1.19 -> 11.764706 | F9: =D9*2 -> 14 | J9: ü | O9: ü | R9: 7350057583838 | S9: 23X13X16.5 | T9: 1.16 | U9: 1
A10: 1002119 | B10: EPS seat right (Move, Wolmax) | C10: =VLOOKUP(A10,Artikeldaten!A:B,2,0) -> Styropor [Rechts] - Move & Wolmax | D10: 7 | E10: =F10/1.19 -> 11.764706 | F10: =D10*2 -> 14 | J10: ü | O10: ü | R10: 7350057583845 | S10: 47X18X24 | T10: 14.5 | U10: 13.9
A11: 1002202 | B11: Textile cover christmas tree | C11: =VLOOKUP(A11,Artikeldaten!A:B,2,0) -> Tannenbaum | D11: 3 | E11: =F11/1.19 -> 5.0420168 | F11: =D11*2 -> 6 | I11: ü | J11: ü | K11: ü | N11: ü | O11: ü | P11: ü | Q11: ü | R11: 7350057583395 | S11: 29X18X12 | T11: 0.7 | U11: 0.5
A12: 1002287 | B12: EPS seat left (Minikid 2.0) | C12: =VLOOKUP(A12,Artikeldaten!A:B,2,0) -> Styropor [Links] - Minikid 2 | D12: 7 | E12: =F12/1.19 -> 11.764706 | F12: =D12*2 -> 14 | I12: ü | R12: 7350057583814 | S12: 57X24.5X28 | T12: 0.83 | U12: 0.34
A13: 1002288 | B13: EPS seat right (Minikid 2.0) | C13: =VLOOKUP(A13,Artikeldaten!A:B,2,0) -> Styropor [Rechts] - Minikid 2 | D13: 7 | E13: =F13/1.19 -> 11.764706 | F13: =D13*2 -> 14 | I13: ü | R13: 7350057583821 | S13: 23X13X16.5 | T13: 1.16 | U13: 1
A14: 1002321 | B14: Seat cushion fixed (Modukid) | C14: =VLOOKUP(A14,Artikeldaten!A:B,2,0) -> Schaumstoff Sitzfläche Geklebt - Modukid Seat | D14: 4 | E14: =F14/1.19 -> 6.7226891 | F14: =D14*2 -> 8 | L14: ü | R14: 7350057583739 | S14: 38X40X22 | T14: 3.45 | U14: 3
A15: 1003124 | B15: 5-point harness (Holmbergs) + 4 rivets | C15: =VLOOKUP(A15,Artikeldaten!A:B,2,0) -> 5 Punkt Gurtsystem Holmberg | D15: 30 | E15: =F15/1.19 -> 50.420168 | F15: =D15*2 -> 60 | I15: ü | J15: ü | K15: ü | N15: ü | O15: ü | P15: ü | Q15: ü | R15: 7350057583968 | S15: 23X13X16.5 | T15: 2.52 | U15: 2.38
A16: 1003207 | B16: Harness adjuster cover + 2 rivets | C16: =VLOOKUP(A16,Artikeldaten!A:B,2,0) -> Gurtabdeckung | D16: 3 | E16: =F16/1.19 -> 5.0420168 | F16: =D16*2 -> 6 | I16: ü | J16: ü | K16: ü | N16: ü | O16: ü | P16: ü | Q16: ü | R16: 7350057583999 | S16: 34X35X28 | T16: 2.12 | U16: 1.72
A17: 1003400 | B17: Side retractor Left | C17: =VLOOKUP(A17,Artikeldaten!A:B,2,0) -> Gurtaufroller [Links] | D17: 23 | E17: =F17/1.19 -> 38.655462 | F17: =D17*2 -> 46 | I17: ü | K17: ü | N17: ü | P17: ü | R17: 7350057584019 | S17: 10X12X18 | T17: 0.16 | U17: 0.12
A18: 1003409 | B18: Side retractor Right | C18: =VLOOKUP(A18,Artikeldaten!A:B,2,0) -> Gurtaufroller [Rechts] | D18: 23 | E18: =F18/1.19 -> 38.655462 | F18: =D18*2 -> 46 | I18: ü | K18: ü | N18: ü | P18: ü | R18: 7350057584026 | S18: 10X12X18 | T18: 0.14 | U18: 0.1
A19: 1004000 | B19: Support leg (Minikid 1.0) | C19: =VLOOKUP(A19,Artikeldaten!A:B,2,0) -> Stützfuß - Minikid 1, Rekid, Wolmax, Duofix & Kidzone | D19: 40 | E19: =F19/1.19 -> 67.226891 | F19: =D19*2 -> 80 | K19: ü | N19: ü | O19: ü | P19: ü | Q19: ü | R19: 7350057583920 | S19: 10X12X18 | T19: 0.6 | U19: 0.55
A20: 1004102 | B20: Support leg rubber foot (old) | C20: =VLOOKUP(A20,Artikeldaten!A:B,2,0) -> Gummifuß - Minikid 1 & Rekid | D20: 3 | E20: =F20/1.19 -> 5.0420168 | F20: =D20*2 -> 6 | K20: ü | N20: ü | O20: ü | P20: ü | Q20: ü | R20: 7350057583944 | S20: 29X18X20 | T20: 4.5 | U20: 4.25
A21: 1004445 | B21: Support leg (Minikid 2.0) | C21: =VLOOKUP(A21,Artikeldaten!A:B,2,0) -> Stützfuß - Minikid 2 & Move | D21: 30 | E21: =F21/1.19 -> 50.420168 | F21: =D21*2 -> 60 | I21: ü | J21: ü | R21: 7350057583913 | S21: 29X18X20 | T21: 1.25 | U21: 1.12
A22: 1004453 | B22: Support leg rubber foot (new) | C22: =VLOOKUP(A22,Artikeldaten!A:B,2,0) -> Gummifuß - Minikid 2 & Move | D22: 3 | E22: =F22/1.19 -> 5.0420168 | F22: =D22*2 -> 6 | I22: ü | J22: ü | R22: 7350057583937 | S22: 29X18X20 | T22: 1.06 | U22: 0.84
A23: 1006000 | B23: Head support Unit (Duofix, Kidzone) | C23: =VLOOKUP(A23,Artikeldaten!A:B,2,0) -> Kopfstütze - Duofix & Kidzofix | D23: 13 | E23: =F23/1.19 -> 21.848739 | F23: =D23*2 -> 26 | P23: ü | Q23: ü | R23: 7350057583791 | S23: 26X33X22 | T23: 0.32 | U23: 0.11
A24: 1006003 | B24: Head support Unit (Minikid 1.0, Rekid) | C24: =VLOOKUP(A24,Artikeldaten!A:B,2,0) -> Kopfstütze - Minikid 1 & Rekid | D24: 13 | E24: =F24/1.19 -> 21.848739 | F24: =D24*2 -> 26 | K24: ü | N24: ü | R24: 7350057583777 | S24: 57X25X28 | T24: 0.63 | U24: 0.17
A25: 1006504 | B25: Head support Unit (Minikid 2.0) | C25: =VLOOKUP(A25,Artikeldaten!A:B,2,0) -> Kopfstütze - Minikid 2 | D25: 13 | E25: =F25/1.19 -> 21.848739 | F25: =D25*2 -> 26 | I25: ü | R25: 7350057583760 | S25: 57X25X28 | T25: 0.63 | U25: 0.17
A26: 1007215 | B26: Textile cover attachment pin | C26: =VLOOKUP(A26,Artikeldaten!A:B,2,0) -> Strohhalm | D26: 3 | E26: =F26/1.19 -> 5.0420168 | F26: =D26*2 -> 6 | I26: ü | J26: ü | K26: ü | L26: ü | N26: ü | O26: ü | P26: ü | Q26: ü | R26: 7350057583388 | S26: 23X13X16.5 | T26: 0.5 | U26: 0.36
A27: 1100714 | B27: Textile cover buckle Red (Modu, Mini) | C27: =VLOOKUP(A27,Artikeldaten!A:B,2,0) -> Gurtschlosspolster - Minikid 2 & Modukid Seat [Rot] | D27: 3 | E27: =F27/1.19 -> 5.0420168 | F27: =D27*2 -> 6 | I27: ü | L27: ü | R27: 7350057583562 | S27: 10X12X18 | T27: 0.23 | U27: 0.17
A28: 1100734 | B28: Sunscreen Black | C28: =VLOOKUP(A28,Artikeldaten!A:B,2,0) -> Sonnenschutz - Modukid Infant [Schwarz] | D28: 7 | E28: =F28/1.19 -> 11.764706 | F28: =D28*2 -> 14 | M28: ü | R28: 7350057584118 | S28: 44X27X23.5 | T28: 7.3 | U28: 6.85
A29: 1100737 | B29: Headrest insert Black | C29: =VLOOKUP(A29,Artikeldaten!A:B,2,0) -> Kopfstützen Einlage - Modukid Infant [Schwarz] | D29: 5 | E29: =F29/1.19 -> 8.4033613 | F29: =D29*2 -> 10 | M29: ü | R29: 7350057584125 | S29: 10X12X18 | T29: 0.4 | U29: 0.34
A30: 1100738 | B30: Baby insert Black | C30: =VLOOKUP(A30,Artikeldaten!A:B,2,0) -> Inlay - Modukid Infant [Schwarz] | D30: 8 | E30: =F30/1.19 -> 13.445378 | F30: =D30*2 -> 16 | M30: ü | R30: 7350057584132
A31: 1100739 | B31: Baby cushion Black | C31: =VLOOKUP(A31,Artikeldaten!A:B,2,0) -> Schaustoff Sitzfläche - Modukid Infant [Schwarz] | D31: 4 | E31: =F31/1.19 -> 6.7226891 | F31: =D31*2 -> 8 | M31: ü | R31: 7350057584149
A32: 1100791 | B32: Head support brake unit | C32: =VLOOKUP(A32,Artikeldaten!A:B,2,0) -> Bremseinheit Kopfstütze - Modukid Seat, Minikid, Rekid, Duofix & Kidzone | D32: 3 | E32: =F32/1.19 -> 5.0420168 | F32: =D32*2 -> 6 | I32: ü | K32: ü | L32: ü | N32: ü | P32: ü | Q32: ü | R32: 7350057584088 | S32: 29X18X20 | T32: 0.5 | U32: 0.29
A33: 1100810 | B33: 5-point harness | C33: =VLOOKUP(A33,Artikeldaten!A:B,2,0) -> 5 Punkt Gurtsystem Shield - Modukid | D33: 20 | E33: =F33/1.19 -> 33.613445 | F33: =D33*2 -> 40 | L33: ü | R33: 7350057583951 | S33: 29X18X20 | T33: 4.5 | U33: 4.25
A34: 1100813 | B34: 3-point harness | C34: =VLOOKUP(A34,Artikeldaten!A:B,2,0) -> 3 Punkt Gurtsystem - Shield | D34: 20 | E34: =F34/1.19 -> 33.613445 | F34: =D34*2 -> 40 | M34: ü | R34: 7350057583975 | S34: 34X35X20 | T34: 4.8 | U34: 4.4
A35: 1100815 | B35: Head support Unit (Modukid) | C35: =VLOOKUP(A35,Artikeldaten!A:B,2,0) -> Kopfstütze - Modukid | D35: 12 | E35: =F35/1.19 -> 20.168067 | F35: =D35*2 -> 24 | L35: ü | R35: 7350057583753 | S35: 48X32X22 | T35: 0.5 | U35: 0.14
A36: 1100816 | B36: ASIP connector + 2 rivets | C36: =VLOOKUP(A36,Artikeldaten!A:B,2,0) -> ASIP Befestigung - Minikid 2, Move, Modukid Seat | D36: 5 | E36: =F36/1.19 -> 8.4033613 | F36: =D36*2 -> 10 | I36: ü | J36: ü | R36: 7350057584064 | S36: 29X18X20 | T36: 0.61 | U36: 0.4
A37: 1100817 | B37: Angle adjuster + 6 rivets | C37: =VLOOKUP(A37,Artikeldaten!A:B,2,0) -> Neigungsverstellung - Minikid | D37: 16 | E37: =F37/1.19 -> 26.890756 | F37: =D37*2 -> 32 | I37: ü | N37: ü | R37: 7350057584040 | S37: 23X13X16.5 | T37: 2 | U37: 1.83
A38: 1100834 | B38: Head support retractor system | C38: =VLOOKUP(A38,Artikeldaten!A:B,2,0) -> Spannrolle Kopfstütze - Minikid 2 & Modukid Seat | D38: 13 | E38: =F38/1.19 -> 21.848739 | F38: =D38*2 -> 26 | I38: ü | L38: ü | R38: 7350057584095 | S38: 29X18X4 | T38: 1.6 | U38: 1.55
A39: 1100839 | B39: Textile cover buckle Grey (Modu, Mini) | C39: =VLOOKUP(A39,Artikeldaten!A:B,2,0) -> Gurtschlosspolster - Minikid 2 & Modukid Seat [Grau] | D39: 3 | E39: =F39/1.19 -> 5.0420168 | F39: =D39*2 -> 6 | I39: ü | L39: ü | R39: 7350057583579 | S39: 29X18X20 | T39: 0.67 | U39: 0.45
A40: 1100844 | B40: Textile cover buckle Black (Modu, Mini) | C40: =VLOOKUP(A40,Artikeldaten!A:B,2,0) -> Gurtschlosspolster - Minikid 2 & Modukid Seat [Schwarz] | D40: 3 | E40: =F40/1.19 -> 5.0420168 | F40: =D40*2 -> 6 | I40: ü | K40: ü | L40: ü | N40: ü | P40: ü | Q40: ü | R40: 7350057583586 | S40: 29X18X20 | T40: 0.67 | U40: 0.45
...

Sheet Artikeldaten
A1: Artikelnummer | B1: Artikel
A2: 1002101 | B2: Styropor [Rücken] - Minikid, Rekid, Duofix & Kidzone
A3: 1002103 | B3: Styropor [Links] - Minikid, Rekid, Duofix & Kidzone
A4: 1002104 | B4: Styropor [Rechts] - Minikid, Rekid, Duofix & Kidzone
A5: 1002108 | B5: Schaumstoff Sitzfläche Geklebt
A6: 1002112 | B6: Schaumstoff Sitzfläche
A7: 1002117 | B7: Styropor [Rücken] - Move & Wolmax
A8: 1002118 | B8: Styropor [Links] - Move & Wolmax
A9: 1002119 | B9: Styropor [Rechts] - Move & Wolmax
A10: 1002202 | B10: Tannenbaum
A11: 1002287 | B11: Styropor [Links] - Minikid 2
A12: 1002288 | B12: Styropor [Rechts] - Minikid 2
A13: 1002321 | B13: Schaumstoff Sitzfläche Geklebt - Modukid Seat
... A247: 27040122 | B247: Axkid Bigkid 2 Premium Granite Melange [Grau]
A248: 27040122_2 | B248: Kopie
A249: 27040122XX | B249: Nicht verwenden
A250: 30100002 | B250: Kinderwagen - Life Grau
A251: 30100003 | B251: Kinderwagen - Life Schwarz
A252: 31409 | B252: Leihsitz Minikid ID 31409
A253: 332957 | B253: Leihsitz - Minikid 2 Granite [Grau]
A254: 50566 | B254: Leihsitz Minikid ID 50566
A255: 51977 | B255: Leihsitz Minikid ID 51977
A256: 52125 | B256: Leihsitz Minikid ID 52125
A257: 52141 | B257: Leihsitz Minikid ID 52141
A258: 52216 | B258: Leihsitz Minikid ID 52216
A259: 52237 | B259: Leihsitz Minikid ID 52237
A260: 52380 | B260: Leihsitz Minikid ID 52380
A261: 60929 | B261: Leihsitz Minikid ID 60929
... A325: 990098 | B325: Styropor rechts Move
A326: COVER SAMPLES | B326: Cover samples 2020
A327: DEMOSITZ | B327: Demositz - Axkid Training Seat 3 Punkt Gurt & Isofix
A328: DEMOSITZ 1 | B328: Demositz - Axkid Training Seat 3 Punkt Gurt & Isofix Teil 1(2)
A329: DEMOSITZ 2 | B329: Demositz - Axkid Training Seat 3 Punkt Gurt & Isofix Teil 2(2)
A330: DIREKTVERSAND | B330: Direktversand Endkunde
A331: LÖSCHEN1 | B331: Löschen
A332: LÖSCHEN2 | B332: Löschen
A333: MINDERMENGENZ D | B333: Mindermengenzuschlag
A334: MINDERMENGENZ EU | B334: Mindermengenzuschlag EU
A335: ONE C BRICK MELANGE | B335: Autositz Axkid One C Brick Melange - [Beige]
A336: ONE C GRANITE MELANG | B336: Autositz Axkid One C Granite Melange - [Grau]
...
