Workbook
Name Ersatzteile: Table5[]
Name issue_selector: DATA!#REF!
Name Kostanpflichtig: Table4[Bitte wählen]
Name Nachkauf: Table53[]
Name product_selector: Kostenvoranschlag!$C$6

Sheet Kostenvoranschlag
B1: Kostenvoranschlag | G1: Version 1.1
B3: Händler*in
B4: Kundenname
B5: Seriennummer:
B6: Sitz: | C6: Bitte wählen
B7: Ersatzteil(e):
F9: Ersatzteilkosten: | G9: =IF(C7="Kostenfrei",0,SUM(I18:I39)) -> 0
F10: Aufwand: | G10: =SUM(G18:G39) -> 0
F11: Reinigungspauschale:
F12: Lieferkosten:
F13: Gesamt: | G13: =SUM(G9:G12) -> 0
F14: Enthaltene MwSt.19% | G14: =G13-(G13/1.19) -> 0
A17: Nr | B17: Artikelnummer | C17: Beschreibung | D17: UVP | E17: Menge | F17: Aufwand | G17: Kosten | I17: Ersatzteil
A18: 1 | B18: {=IFERROR(_xlfn.LET(_xlpm.X,INDIRECT("data["&product_selector&"]"),INDEX(_xlfn._xlws.SORT(_xlfn.UNIQUE(_xlfn._xlws.FILTER(_xlpm.X,_xlpm.X<>""))),Table3[[#This Row],[Nr]])),"")} | C18: =IFERROR(_xlfn.XLOOKUP(Table3[[#This Row],[Artikelnummer]],'Sitze & Ersatzteile'!A:A,'Sitze & Ersatzteile'!B:B),"") | D18: =_xlfn.IFNA(_xlfn.XLOOKUP(Table3[[#This Row],[Artikelnummer]],'Sitze & Ersatzteile'!A:A,'Sitze & Ersatzteile'!C:C),0) -> 0 | F18: =IFERROR(_xlfn.XLOOKUP(Table3[[#This Row],[Artikelnummer]],'Sitze & Ersatzteile'!A:A,'Sitze & Ersatzteile'!D:D),0) -> 0 | G18: {=_xlfn.IFS(E18=0,0,F18=0,0,E18>0,F18*DATA!B$29)} -> 0 | I18: =IFERROR(E18*D18,"") -> 0
A19: 2 | B19: {=IFERROR(_xlfn.LET(_xlpm.X,INDIRECT("data["&product_selector&"]"),INDEX(_xlfn._xlws.SORT(_xlfn.UNIQUE(_xlfn._xlws.FILTER(_xlpm.X,_xlpm.X<>""))),Table3[[#This Row],[Nr]])),"")} | C19: =IFERROR(_xlfn.XLOOKUP(Table3[[#This Row],[Artikelnummer]],'Sitze & Ersatzteile'!A:A,'Sitze & Ersatzteile'!B:B),"") | D19: =_xlfn.IFNA(_xlfn.XLOOKUP(Table3[[#This Row],[Artikelnummer]],'Sitze & Ersatzteile'!A:A,'Sitze & Ersatzteile'!C:C),0) -> 0 | F19: =IFERROR(_xlfn.XLOOKUP(Table3[[#This Row],[Artikelnummer]],'Sitze & Ersatzteile'!A:A,'Sitze & Ersatzteile'!D:D),0) -> 0 | G19: {=_xlfn.IFS(E19=0,0,F19=0,0,E19>0,F19*DATA!B$29)} -> 0 | I19: =IFERROR(E19*D19,"") -> 0
A20: 3 | B20: {=IFERROR(_xlfn.LET(_xlpm.X,INDIRECT("data["&product_selector&"]"),INDEX(_xlfn._xlws.SORT(_xlfn.UNIQUE(_xlfn._xlws.FILTER(_xlpm.X,_xlpm.X<>""))),Table3[[#This Row],[Nr]])),"")} | C20: =IFERROR(_xlfn.XLOOKUP(Table3[[#This Row],[Artikelnummer]],'Sitze & Ersatzteile'!A:A,'Sitze & Ersatzteile'!B:B),"") | D20: =_xlfn.IFNA(_xlfn.XLOOKUP(Table3[[#This Row],[Artikelnummer]],'Sitze & Ersatzteile'!A:A,'Sitze & Ersatzteile'!C:C),0) -> 0 | F20: =IFERROR(_xlfn.XLOOKUP(Table3[[#This Row],[Artikelnummer]],'Sitze & Ersatzteile'!A:A,'Sitze & Ersatzteile'!D:D),0) -> 0 | G20: {=_xlfn.IFS(E20=0,0,F20=0,0,E20>0,F20*DATA!B$29)} -> 0 | I20: =IFERROR(E20*D20,"") -> 0
A21: 4 | B21: {=IFERROR(_xlfn.LET(_xlpm.X,INDIRECT("data["&product_selector&"]"),INDEX(_xlfn._xlws.SORT(_xlfn.UNIQUE(_xlfn._xlws.FILTER(_xlpm.X,_xlpm.X<>""))),Table3[[#This Row],[Nr]])),"")} | C21: =IFERROR(_xlfn.XLOOKUP(Table3[[#This Row],[Artikelnummer]],'Sitze & Ersatzteile'!A:A,'Sitze & Ersatzteile'!B:B),"") | D21: =_xlfn.IFNA(_xlfn.XLOOKUP(Table3[[#This Row],[Artikelnummer]],'Sitze & Ersatzteile'!A:A,'Sitze & Ersatzteile'!C:C),0) -> 0 | F21: =IFERROR(_xlfn.XLOOKUP(Table3[[#This Row],[Artikelnummer]],'Sitze & Ersatzteile'!A:A,'Sitze & Ersatzteile'!D:D),0) -> 0 | G21: {=_xlfn.IFS(E21=0,0,F21=0,0,E21>0,F21*DATA!B$29)} -> 0 | I21: =IFERROR(E21*D21,"") -> 0
A22: 5 | B22: {=IFERROR(_xlfn.LET(_xlpm.X,INDIRECT("data["&product_selector&"]"),INDEX(_xlfn._xlws.SORT(_xlfn.UNIQUE(_xlfn._xlws.FILTER(_xlpm.X,_xlpm.X<>""))),Table3[[#This Row],[Nr]])),"")} | C22: =IFERROR(_xlfn.XLOOKUP(Table3[[#This Row],[Artikelnummer]],'Sitze & Ersatzteile'!A:A,'Sitze & Ersatzteile'!B:B),"") | D22: =_xlfn.IFNA(_xlfn.XLOOKUP(Table3[[#This Row],[Artikelnummer]],'Sitze & Ersatzteile'!A:A,'Sitze & Ersatzteile'!C:C),0) -> 0 | F22: =IFERROR(_xlfn.XLOOKUP(Table3[[#This Row],[Artikelnummer]],'Sitze & Ersatzteile'!A:A,'Sitze & Ersatzteile'!D:D),0) -> 0 | G22: {=_xlfn.IFS(E22=0,0,F22=0,0,E22>0,F22*DATA!B$29)} -> 0 | I22: =IFERROR(E22*D22,"") -> 0
A23: 6 | B23: {=IFERROR(_xlfn.LET(_xlpm.X,INDIRECT("data["&product_selector&"]"),INDEX(_xlfn._xlws.SORT(_xlfn.UNIQUE(_xlfn._xlws.FILTER(_xlpm.X,_xlpm.X<>""))),Table3[[#This Row],[Nr]])),"")} | C23: =IFERROR(_xlfn.XLOOKUP(Table3[[#This Row],[Artikelnummer]],'Sitze & Ersatzteile'!A:A,'Sitze & Ersatzteile'!B:B),"") | D23: =_xlfn.IFNA(_xlfn.XLOOKUP(Table3[[#This Row],[Artikelnummer]],'Sitze & Ersatzteile'!A:A,'Sitze & Ersatzteile'!C:C),0) -> 0 | F23: =IFERROR(_xlfn.XLOOKUP(Table3[[#This Row],[Artikelnummer]],'Sitze & Ersatzteile'!A:A,'Sitze & Ersatzteile'!D:D),0) -> 0 | G23: {=_xlfn.IFS(E23=0,0,F23=0,0,E23>0,F23*DATA!B$29)} -> 0 | I23: =IFERROR(E23*D23,"") -> 0
A24: 7 | B24: {=IFERROR(_xlfn.LET(_xlpm.X,INDIRECT("data["&product_selector&"]"),INDEX(_xlfn._xlws.SORT(_xlfn.UNIQUE(_xlfn._xlws.FILTER(_xlpm.X,_xlpm.X<>""))),Table3[[#This Row],[Nr]])),"")} | C24: =IFERROR(_xlfn.XLOOKUP(Table3[[#This Row],[Artikelnummer]],'Sitze & Ersatzteile'!A:A,'Sitze & Ersatzteile'!B:B),"") | D24: =_xlfn.IFNA(_xlfn.XLOOKUP(Table3[[#This Row],[Artikelnummer]],'Sitze & Ersatzteile'!A:A,'Sitze & Ersatzteile'!C:C),0) -> 0 | F24: =IFERROR(_xlfn.XLOOKUP(Table3[[#This Row],[Artikelnummer]],'Sitze & Ersatzteile'!A:A,'Sitze & Ersatzteile'!D:D),0) -> 0 | G24: {=_xlfn.IFS(E24=0,0,F24=0,0,E24>0,F24*DATA!B$29)} -> 0 | I24: =IFERROR(E24*D24,"") -> 0
A25: 8 | B25: {=IFERROR(_xlfn.LET(_xlpm.X,INDIRECT("data["&product_selector&"]"),INDEX(_xlfn._xlws.SORT(_xlfn.UNIQUE(_xlfn._xlws.FILTER(_xlpm.X,_xlpm.X<>""))),Table3[[#This Row],[Nr]])),"")} | C25: =IFERROR(_xlfn.XLOOKUP(Table3[[#This Row],[Artikelnummer]],'Sitze & Ersatzteile'!A:A,'Sitze & Ersatzteile'!B:B),"") | D25: =_xlfn.IFNA(_xlfn.XLOOKUP(Table3[[#This Row],[Artikelnummer]],'Sitze & Ersatzteile'!A:A,'Sitze & Ersatzteile'!C:C),0) -> 0 | F25: =IFERROR(_xlfn.XLOOKUP(Table3[[#This Row],[Artikelnummer]],'Sitze & Ersatzteile'!A:A,'Sitze & Ersatzteile'!D:D),0) -> 0 | G25: {=_xlfn.IFS(E25=0,0,F25=0,0,E25>0,F25*DATA!B$29)} -> 0 | I25: =IFERROR(E25*D25,"") -> 0
A26: 9 | B26: {=IFERROR(_xlfn.LET(_xlpm.X,INDIRECT("data["&product_selector&"]"),INDEX(_xlfn._xlws.SORT(_xlfn.UNIQUE(_xlfn._xlws.FILTER(_xlpm.X,_xlpm.X<>""))),Table3[[#This Row],[Nr]])),"")} | C26: =IFERROR(_xlfn.XLOOKUP(Table3[[#This Row],[Artikelnummer]],'Sitze & Ersatzteile'!A:A,'Sitze & Ersatzteile'!B:B),"") | D26: =_xlfn.IFNA(_xlfn.XLOOKUP(Table3[[#This Row],[Artikelnummer]],'Sitze & Ersatzteile'!A:A,'Sitze & Ersatzteile'!C:C),0) -> 0 | F26: =IFERROR(_xlfn.XLOOKUP(Table3[[#This Row],[Artikelnummer]],'Sitze & Ersatzteile'!A:A,'Sitze & Ersatzteile'!D:D),0) -> 0 | G26: {=_xlfn.IFS(E26=0,0,F26=0,0,E26>0,F26*DATA!B$29)} -> 0 | I26: =IFERROR(E26*D26,"") -> 0
A27: 10 | B27: {=IFERROR(_xlfn.LET(_xlpm.X,INDIRECT("data["&product_selector&"]"),INDEX(_xlfn._xlws.SORT(_xlfn.UNIQUE(_xlfn._xlws.FILTER(_xlpm.X,_xlpm.X<>""))),Table3[[#This Row],[Nr]])),"")} | C27: =IFERROR(_xlfn.XLOOKUP(Table3[[#This Row],[Artikelnummer]],'Sitze & Ersatzteile'!A:A,'Sitze & Ersatzteile'!B:B),"") | D27: =_xlfn.IFNA(_xlfn.XLOOKUP(Table3[[#This Row],[Artikelnummer]],'Sitze & Ersatzteile'!A:A,'Sitze & Ersatzteile'!C:C),0) -> 0 | F27: =IFERROR(_xlfn.XLOOKUP(Table3[[#This Row],[Artikelnummer]],'Sitze & Ersatzteile'!A:A,'Sitze & Ersatzteile'!D:D),0) -> 0 | G27: {=_xlfn.IFS(E27=0,0,F27=0,0,E27>0,F27*DATA!B$29)} -> 0 | I27: =IFERROR(E27*D27,"") -> 0
A28: 11 | B28: {=IFERROR(_xlfn.LET(_xlpm.X,INDIRECT("data["&product_selector&"]"),INDEX(_xlfn._xlws.SORT(_xlfn.UNIQUE(_xlfn._xlws.FILTER(_xlpm.X,_xlpm.X<>""))),Table3[[#This Row],[Nr]])),"")} | C28: =IFERROR(_xlfn.XLOOKUP(Table3[[#This Row],[Artikelnummer]],'Sitze & Ersatzteile'!A:A,'Sitze & Ersatzteile'!B:B),"") | D28: =_xlfn.IFNA(_xlfn.XLOOKUP(Table3[[#This Row],[Artikelnummer]],'Sitze & Ersatzteile'!A:A,'Sitze & Ersatzteile'!C:C),0) -> 0 | F28: =IFERROR(_xlfn.XLOOKUP(Table3[[#This Row],[Artikelnummer]],'Sitze & Ersatzteile'!A:A,'Sitze & Ersatzteile'!D:D),0) -> 0 | G28: {=_xlfn.IFS(E28=0,0,F28=0,0,E28>0,F28*DATA!B$29)} -> 0 | I28: =IFERROR(E28*D28,"") -> 0
A29: 12 | B29: {=IFERROR(_xlfn.LET(_xlpm.X,INDIRECT("data["&product_selector&"]"),INDEX(_xlfn._xlws.SORT(_xlfn.UNIQUE(_xlfn._xlws.FILTER(_xlpm.X,_xlpm.X<>""))),Table3[[#This Row],[Nr]])),"")} | C29: =IFERROR(_xlfn.XLOOKUP(Table3[[#This Row],[Artikelnummer]],'Sitze & Ersatzteile'!A:A,'Sitze & Ersatzteile'!B:B),"") | D29: =_xlfn.IFNA(_xlfn.XLOOKUP(Table3[[#This Row],[Artikelnummer]],'Sitze & Ersatzteile'!A:A,'Sitze & Ersatzteile'!C:C),0) -> 0 | F29: =IFERROR(_xlfn.XLOOKUP(Table3[[#This Row],[Artikelnummer]],'Sitze & Ersatzteile'!A:A,'Sitze & Ersatzteile'!D:D),0) -> 0 | G29: {=_xlfn.IFS(E29=0,0,F29=0,0,E29>0,F29*DATA!B$29)} -> 0 | I29: =IFERROR(E29*D29,"") -> 0
... A41: 24 | B41: {=IFERROR(_xlfn.LET(_xlpm.X,INDIRECT("data["&product_selector&"]"),INDEX(_xlfn._xlws.SORT(_xlfn.UNIQUE(_xlfn._xlws.FILTER(_xlpm.X,_xlpm.X<>""))),Table3[[#This Row],[Nr]])),"")} | C41: =IFERROR(_xlfn.XLOOKUP(Table3[[#This Row],[Artikelnummer]],'Sitze & Ersatzteile'!A:A,'Sitze & Ersatzteile'!B:B),"") | D41: =_xlfn.IFNA(_xlfn.XLOOKUP(Table3[[#This Row],[Artikelnummer]],'Sitze & Ersatzteile'!A:A,'Sitze & Ersatzteile'!C:C),0) -> 0 | F41: =IFERROR(_xlfn.XLOOKUP(Table3[[#This Row],[Artikelnummer]],'Sitze & Ersatzteile'!A:A,'Sitze & Ersatzteile'!D:D),0) -> 0 | G41: {=_xlfn.IFS(E41=0,0,F41=0,0,E41>0,F41*DATA!B$29)} -> 0 | I41: =IFERROR(E41*D41,"") -> 0

Sheet Sitze & Ersatzteile
A1: Axkid ONE ONE2 | C1: UVP | D1: Aufwand
A2: 1103898 | B2: =_xlfn.XLOOKUP(A2,Ersatzteilpreisliste!A:A,Ersatzteilpreisliste!B:B) -> Kopfstütze + Styropor EPS - ONE2 | C2: =_xlfn.XLOOKUP(A2,Ersatzteilpreisliste!A:A,Ersatzteilpreisliste!C:C) -> 24 | D2: =_xlfn.XLOOKUP(A2,Ersatzteilpreisliste!A:A,Ersatzteilpreisliste!D:D) -> 1
A3: 1103343 | B3: =_xlfn.XLOOKUP(A3,Ersatzteilpreisliste!A:A,Ersatzteilpreisliste!B:B) -> Recline Bushing + Stop Screw - ONE ONE2 | C3: =_xlfn.XLOOKUP(A3,Ersatzteilpreisliste!A:A,Ersatzteilpreisliste!C:C) -> 3 | D3: =_xlfn.XLOOKUP(A3,Ersatzteilpreisliste!A:A,Ersatzteilpreisliste!D:D) -> 3
A4: 1103295 | B4: =_xlfn.XLOOKUP(A4,Ersatzteilpreisliste!A:A,Ersatzteilpreisliste!B:B) -> Anti Friction Kit + Schulterpolster - ONE | C4: =_xlfn.XLOOKUP(A4,Ersatzteilpreisliste!A:A,Ersatzteilpreisliste!C:C) -> 21 | D4: =_xlfn.XLOOKUP(A4,Ersatzteilpreisliste!A:A,Ersatzteilpreisliste!D:D) -> 1
A5: 1103031 | B5: =_xlfn.XLOOKUP(A5,Ersatzteilpreisliste!A:A,Ersatzteilpreisliste!B:B) -> ISOFIX Abstandhalter [RH] 10stk - ONE ONE2 | C5: =_xlfn.XLOOKUP(A5,Ersatzteilpreisliste!A:A,Ersatzteilpreisliste!C:C) -> 21 | D5: =_xlfn.XLOOKUP(A5,Ersatzteilpreisliste!A:A,Ersatzteilpreisliste!D:D) -> 1
A6: 1103028 | B6: =_xlfn.XLOOKUP(A6,Ersatzteilpreisliste!A:A,Ersatzteilpreisliste!B:B) -> ISOFIX Abstandhalter [LH] 10stk - ONE ONE2 | C6: =_xlfn.XLOOKUP(A6,Ersatzteilpreisliste!A:A,Ersatzteilpreisliste!C:C) -> 21 | D6: =_xlfn.XLOOKUP(A6,Ersatzteilpreisliste!A:A,Ersatzteilpreisliste!D:D) -> 1
A7: 1103019 | B7: =_xlfn.XLOOKUP(A7,Ersatzteilpreisliste!A:A,Ersatzteilpreisliste!B:B) -> Stützfuß Abdeckung - ONE ONE2 | C7: =_xlfn.XLOOKUP(A7,Ersatzteilpreisliste!A:A,Ersatzteilpreisliste!C:C) -> 4 | D7: =_xlfn.XLOOKUP(A7,Ersatzteilpreisliste!A:A,Ersatzteilpreisliste!D:D) -> 1
A8: 1102859 | B8: =_xlfn.XLOOKUP(A8,Ersatzteilpreisliste!A:A,Ersatzteilpreisliste!B:B) -> ASIP Befestigung (LH+RH) - ONE ONE2 | C8: =_xlfn.XLOOKUP(A8,Ersatzteilpreisliste!A:A,Ersatzteilpreisliste!C:C) -> 6 | D8: =_xlfn.XLOOKUP(A8,Ersatzteilpreisliste!A:A,Ersatzteilpreisliste!D:D) -> 2
A9: 1102238 | B9: =_xlfn.XLOOKUP(A9,Ersatzteilpreisliste!A:A,Ersatzteilpreisliste!B:B) -> Kopfstütze Mutter - ONE | C9: =_xlfn.XLOOKUP(A9,Ersatzteilpreisliste!A:A,Ersatzteilpreisliste!C:C) -> 1 | D9: =_xlfn.XLOOKUP(A9,Ersatzteilpreisliste!A:A,Ersatzteilpreisliste!D:D) -> 1
A10: 1101986 | B10: =_xlfn.XLOOKUP(A10,Ersatzteilpreisliste!A:A,Ersatzteilpreisliste!B:B) -> ISOFIX Connectoren (LH+RH) - ONE | C10: =_xlfn.XLOOKUP(A10,Ersatzteilpreisliste!A:A,Ersatzteilpreisliste!C:C) -> 33 | D10: =_xlfn.XLOOKUP(A10,Ersatzteilpreisliste!A:A,Ersatzteilpreisliste!D:D) -> 1
A11: 1101936 | B11: =_xlfn.XLOOKUP(A11,Ersatzteilpreisliste!A:A,Ersatzteilpreisliste!B:B) -> 5 Punkt Gurtsystem - ONE ONE2 | C11: =_xlfn.XLOOKUP(A11,Ersatzteilpreisliste!A:A,Ersatzteilpreisliste!C:C) -> 30 | D11: =_xlfn.XLOOKUP(A11,Ersatzteilpreisliste!A:A,Ersatzteilpreisliste!D:D) -> 4
A12: 1101935 | B12: =_xlfn.XLOOKUP(A12,Ersatzteilpreisliste!A:A,Ersatzteilpreisliste!B:B) -> Klettverschluss - ONE ONE2 | C12: =_xlfn.XLOOKUP(A12,Ersatzteilpreisliste!A:A,Ersatzteilpreisliste!C:C) -> 3 | D12: =_xlfn.XLOOKUP(A12,Ersatzteilpreisliste!A:A,Ersatzteilpreisliste!D:D) -> 1
A13: 1101934 | B13: =_xlfn.XLOOKUP(A13,Ersatzteilpreisliste!A:A,Ersatzteilpreisliste!B:B) -> Halterung Seitenabdeckung - ONE | C13: =_xlfn.XLOOKUP(A13,Ersatzteilpreisliste!A:A,Ersatzteilpreisliste!C:C) -> 3 | D13: =_xlfn.XLOOKUP(A13,Ersatzteilpreisliste!A:A,Ersatzteilpreisliste!D:D) -> 2
... A23: 1101921 | B23: =_xlfn.XLOOKUP(A23,Ersatzteilpreisliste!A:A,Ersatzteilpreisliste!B:B) -> Stützfuß Komplett - ONE ONE2 | C23: =_xlfn.XLOOKUP(A23,Ersatzteilpreisliste!A:A,Ersatzteilpreisliste!C:C) -> 70 | D23: =_xlfn.XLOOKUP(A23,Ersatzteilpreisliste!A:A,Ersatzteilpreisliste!D:D) -> 1
A24: ISOFIX | B24: =_xlfn.XLOOKUP(A24,Ersatzteilpreisliste!A:A,Ersatzteilpreisliste!B:B) -> Reinigung - ISOFIX | C24: =_xlfn.XLOOKUP(A24,Ersatzteilpreisliste!A:A,Ersatzteilpreisliste!C:C) -> 0 | D24: =_xlfn.XLOOKUP(A24,Ersatzteilpreisliste!A:A,Ersatzteilpreisliste!D:D) -> 2
A25: SLED | B25: =_xlfn.XLOOKUP(A25,Ersatzteilpreisliste!A:A,Ersatzteilpreisliste!B:B) -> Reinigung - Schiebefunktion | C25: =_xlfn.XLOOKUP(A25,Ersatzteilpreisliste!A:A,Ersatzteilpreisliste!C:C) -> 0 | D25: =_xlfn.XLOOKUP(A25,Ersatzteilpreisliste!A:A,Ersatzteilpreisliste!D:D) -> 2
A27: Axkid Minikid 3 | C27: UVP | D27: Aufwand
A28: 1104796 | B28: =_xlfn.XLOOKUP(A28,Ersatzteilpreisliste!A:A,Ersatzteilpreisliste!B:B) -> Kopfstütze Aufroller & Clip - MK3 | C28: =_xlfn.XLOOKUP(A28,Ersatzteilpreisliste!A:A,Ersatzteilpreisliste!C:C) -> 25 | D28: =_xlfn.XLOOKUP(A28,Ersatzteilpreisliste!A:A,Ersatzteilpreisliste!D:D) -> 1
A29: 1103706 | B29: =_xlfn.XLOOKUP(A29,Ersatzteilpreisliste!A:A,Ersatzteilpreisliste!B:B) -> BUSHINGS + HOUSING SUPPORT LEG (MK3) | C29: =_xlfn.XLOOKUP(A29,Ersatzteilpreisliste!A:A,Ersatzteilpreisliste!C:C) -> 3 | D29: =_xlfn.XLOOKUP(A29,Ersatzteilpreisliste!A:A,Ersatzteilpreisliste!D:D) -> 1
A30: 1103703 | B30: =_xlfn.XLOOKUP(A30,Ersatzteilpreisliste!A:A,Ersatzteilpreisliste!B:B) -> Aufkleber - MK3 | C30: =_xlfn.XLOOKUP(A30,Ersatzteilpreisliste!A:A,Ersatzteilpreisliste!C:C) -> 1.5 | D30: =_xlfn.XLOOKUP(A30,Ersatzteilpreisliste!A:A,Ersatzteilpreisliste!D:D) -> 1
A31: 1103702 | B31: =_xlfn.XLOOKUP(A31,Ersatzteilpreisliste!A:A,Ersatzteilpreisliste!B:B) -> HANGTAGS + MANUAL + PACKAGING - MK3 | C31: =_xlfn.XLOOKUP(A31,Ersatzteilpreisliste!A:A,Ersatzteilpreisliste!C:C) -> 20 | D31: =_xlfn.XLOOKUP(A31,Ersatzteilpreisliste!A:A,Ersatzteilpreisliste!D:D) -> 1
A32: 1103693 | B32: =_xlfn.XLOOKUP(A32,Ersatzteilpreisliste!A:A,Ersatzteilpreisliste!B:B) -> Kopfstütze Bremseinheit - MK3 | C32: =_xlfn.XLOOKUP(A32,Ersatzteilpreisliste!A:A,Ersatzteilpreisliste!C:C) -> 10 | D32: =_xlfn.XLOOKUP(A32,Ersatzteilpreisliste!A:A,Ersatzteilpreisliste!D:D) -> 1
A33: 1103688 | B33: =_xlfn.XLOOKUP(A33,Ersatzteilpreisliste!A:A,Ersatzteilpreisliste!B:B) -> Klettverschluss - MK3 | C33: =_xlfn.XLOOKUP(A33,Ersatzteilpreisliste!A:A,Ersatzteilpreisliste!C:C) -> 4 | D33: =_xlfn.XLOOKUP(A33,Ersatzteilpreisliste!A:A,Ersatzteilpreisliste!D:D) -> 1
A34: 1103686 | B34: =_xlfn.XLOOKUP(A34,Ersatzteilpreisliste!A:A,Ersatzteilpreisliste!B:B) -> Stützfuß Knopf - MK3 | C34: =_xlfn.XLOOKUP(A34,Ersatzteilpreisliste!A:A,Ersatzteilpreisliste!C:C) -> 3 | D34: =_xlfn.XLOOKUP(A34,Ersatzteilpreisliste!A:A,Ersatzteilpreisliste!D:D) -> 1
A35: 1103685 | B35: =_xlfn.XLOOKUP(A35,Ersatzteilpreisliste!A:A,Ersatzteilpreisliste!B:B) -> Stützfuß Gurtband - MK3 | C35: =_xlfn.XLOOKUP(A35,Ersatzteilpreisliste!A:A,Ersatzteilpreisliste!C:C) -> 3 | D35: =_xlfn.XLOOKUP(A35,Ersatzteilpreisliste!A:A,Ersatzteilpreisliste!D:D) -> 1
A36: 1103684 | B36: =_xlfn.XLOOKUP(A36,Ersatzteilpreisliste!A:A,Ersatzteilpreisliste!B:B) -> Stützfuß Komplett - MK3 | C36: =_xlfn.XLOOKUP(A36,Ersatzteilpreisliste!A:A,Ersatzteilpreisliste!C:C) -> 8 | D36: =_xlfn.XLOOKUP(A36,Ersatzteilpreisliste!A:A,Ersatzteilpreisliste!D:D) -> 1
A37: 1103681 | B37: =_xlfn.XLOOKUP(A37,Ersatzteilpreisliste!A:A,Ersatzteilpreisliste!B:B) -> Styropor EPS [LH+RH] - MK3 | C37: =_xlfn.XLOOKUP(A37,Ersatzteilpreisliste!A:A,Ersatzteilpreisliste!C:C) -> 17 | D37: =_xlfn.XLOOKUP(A37,Ersatzteilpreisliste!A:A,Ersatzteilpreisliste!D:D) -> 1
A38: 1103651 | B38: =_xlfn.XLOOKUP(A38,Ersatzteilpreisliste!A:A,Ersatzteilpreisliste!B:B) -> Gurtklemme + Schrauben - MK3 | C38: =_xlfn.XLOOKUP(A38,Ersatzteilpreisliste!A:A,Ersatzteilpreisliste!C:C) -> 7.5 | D38: =_xlfn.XLOOKUP(A38,Ersatzteilpreisliste!A:A,Ersatzteilpreisliste!D:D) -> 1
A39: 1103650 | B39: =_xlfn.XLOOKUP(A39,Ersatzteilpreisliste!A:A,Ersatzteilpreisliste!B:B) -> Gurtklemme - MK3 | C39: =_xlfn.XLOOKUP(A39,Ersatzteilpreisliste!A:A,Ersatzteilpreisliste!C:C) -> 6 | D39: =_xlfn.XLOOKUP(A39,Ersatzteilpreisliste!A:A,Ersatzteilpreisliste!D:D) -> 1
... A48: 1103639 | B48: =_xlfn.XLOOKUP(A48,Ersatzteilpreisliste!A:A,Ersatzteilpreisliste!B:B) -> Kopfstütze Hebel Bremseinheit - MK3 | C48: =_xlfn.XLOOKUP(A48,Ersatzteilpreisliste!A:A,Ersatzteilpreisliste!C:C) -> 5 | D48: =_xlfn.XLOOKUP(A48,Ersatzteilpreisliste!A:A,Ersatzteilpreisliste!D:D) -> 1
A50: Axkid Minikid 2 | C50: UVP | D50: Aufwand
A51: 1101314 | B51: =_xlfn.XLOOKUP(A51,Ersatzteilpreisliste!A:A,Ersatzteilpreisliste!B:B) -> Stützfuß Gurtband - MK2 MV | C51: =_xlfn.XLOOKUP(A51,Ersatzteilpreisliste!A:A,Ersatzteilpreisliste!C:C) -> 3 | D51: =_xlfn.XLOOKUP(A51,Ersatzteilpreisliste!A:A,Ersatzteilpreisliste!D:D) -> 3
A52: 1101279 | B52: =_xlfn.XLOOKUP(A52,Ersatzteilpreisliste!A:A,Ersatzteilpreisliste!B:B) -> Absatz & Nieten - MK2 | C52: =_xlfn.XLOOKUP(A52,Ersatzteilpreisliste!A:A,Ersatzteilpreisliste!C:C) -> 13 | D52: =_xlfn.XLOOKUP(A52,Ersatzteilpreisliste!A:A,Ersatzteilpreisliste!D:D) -> 1
A53: 1100939 | B53: =_xlfn.XLOOKUP(A53,Ersatzteilpreisliste!A:A,Ersatzteilpreisliste!B:B) -> Gurtklemme [Blau] - MK2 MV | C53: =_xlfn.XLOOKUP(A53,Ersatzteilpreisliste!A:A,Ersatzteilpreisliste!C:C) -> 3 | D53: =_xlfn.XLOOKUP(A53,Ersatzteilpreisliste!A:A,Ersatzteilpreisliste!D:D) -> 1
A54: 1100834 | B54: =_xlfn.XLOOKUP(A54,Ersatzteilpreisliste!A:A,Ersatzteilpreisliste!B:B) -> Kopfstütze Spannrolle - MK2 MDS | C54: =_xlfn.XLOOKUP(A54,Ersatzteilpreisliste!A:A,Ersatzteilpreisliste!C:C) -> 13 | D54: =_xlfn.XLOOKUP(A54,Ersatzteilpreisliste!A:A,Ersatzteilpreisliste!D:D) -> 3
A55: 1100817 | B55: =_xlfn.XLOOKUP(A55,Ersatzteilpreisliste!A:A,Ersatzteilpreisliste!B:B) -> Neigungsverstellung - MK1 MK2 | C55: =_xlfn.XLOOKUP(A55,Ersatzteilpreisliste!A:A,Ersatzteilpreisliste!C:C) -> 16 | D55: =_xlfn.XLOOKUP(A55,Ersatzteilpreisliste!A:A,Ersatzteilpreisliste!D:D) -> 3
A56: 1100816 | B56: =_xlfn.XLOOKUP(A56,Ersatzteilpreisliste!A:A,Ersatzteilpreisliste!B:B) -> ASIP Befestigung - MK2 MV | C56: =_xlfn.XLOOKUP(A56,Ersatzteilpreisliste!A:A,Ersatzteilpreisliste!C:C) -> 5 | D56: =_xlfn.XLOOKUP(A56,Ersatzteilpreisliste!A:A,Ersatzteilpreisliste!D:D) -> 1
A57: 1006504 | B57: =_xlfn.XLOOKUP(A57,Ersatzteilpreisliste!A:A,Ersatzteilpreisliste!B:B) -> Kopfstütze - MK2 | C57: =_xlfn.XLOOKUP(A57,Ersatzteilpreisliste!A:A,Ersatzteilpreisliste!C:C) -> 19 | D57: =_xlfn.XLOOKUP(A57,Ersatzteilpreisliste!A:A,Ersatzteilpreisliste!D:D) -> 2
A58: 1004453 | B58: =_xlfn.XLOOKUP(A58,Ersatzteilpreisliste!A:A,Ersatzteilpreisliste!B:B) -> Gummifuß - MK2 MV | C58: =_xlfn.XLOOKUP(A58,Ersatzteilpreisliste!A:A,Ersatzteilpreisliste!C:C) -> 3 | D58: =_xlfn.XLOOKUP(A58,Ersatzteilpreisliste!A:A,Ersatzteilpreisliste!D:D) -> 1
A59: 1004445 | B59: =_xlfn.XLOOKUP(A59,Ersatzteilpreisliste!A:A,Ersatzteilpreisliste!B:B) -> Stützfuß Komplett - MK2 MV | C59: =_xlfn.XLOOKUP(A59,Ersatzteilpreisliste!A:A,Ersatzteilpreisliste!C:C) -> 30 | D59: =_xlfn.XLOOKUP(A59,Ersatzteilpreisliste!A:A,Ersatzteilpreisliste!D:D) -> 3
...

Sheet Nachkauf
A1: Nr. | B1: Beschreibung | C1: UVP | D1: EK Netto
A2: 1102856 | B2: Bezug Kopfstütze [Brick Melange] - ONE ONE2 | C2: 13 | D2: =(Table53[[#This Row],[UVP]]/1.19)*(1-G$2) -> 6.5546218 | F2: Marge: | G2: 0.4
A3: 1102852 | B3: Bezug Kopfstütze [Granite Melange] - ONE ONE2 | C3: 13 | D3: =(Table53[[#This Row],[UVP]]/1.19)*(1-G$2) -> 6.5546218
A4: 1103690 | B4: Bezug Kopfstütze [Granite] - MK3 | C4: 13 | D4: =(Table53[[#This Row],[UVP]]/1.19)*(1-G$2) -> 6.5546218
A5: 1101244 | B5: Bezug Kopfstütze [Schwarz] - MK1 | C5: 13 | D5: =(Table53[[#This Row],[UVP]]/1.19)*(1-G$2) -> 6.5546218
A6: 1100960 | B6: Bezug Kopfstütze [Schwarz] - MK2 | C6: 13 | D6: =(Table53[[#This Row],[UVP]]/1.19)*(1-G$2) -> 6.5546218
A7: 1101247 | B7: Bezug Kopfstütze [Schwarz] - WM | C7: 13 | D7: =(Table53[[#This Row],[UVP]]/1.19)*(1-G$2) -> 6.5546218
A8: 1103689 | B8: Bezug Kopfstütze [Tar] - MK3 | C8: 13 | D8: =(Table53[[#This Row],[UVP]]/1.19)*(1-G$2) -> 6.5546218
A9: 1101938 | B9: Bezug Kopfstütze [Tar] - ONE ONE2 | C9: 13 | D9: =(Table53[[#This Row],[UVP]]/1.19)*(1-G$2) -> 6.5546218
A10: 1102854 | B10: Bezug Kopfstütze [Tile Melange] - ONE ONE2 | C10: 13 | D10: =(Table53[[#This Row],[UVP]]/1.19)*(1-G$2) -> 6.5546218
A11: 1104118 | B11: Bezug Kopfstütze 2022 [Granite Melange] - MK2 | C11: 13 | D11: =(Table53[[#This Row],[UVP]]/1.19)*(1-G$2) -> 6.5546218
A12: 1104133 | B12: Bezug Kopfstütze 2022 [Shell Black] - MK2 | C12: 13 | D12: =(Table53[[#This Row],[UVP]]/1.19)*(1-G$2) -> 6.5546218
A13: 1104117 | B13: Bezug Kopfstütze 2022 [Tar] - MK2 | C13: 13 | D13: =(Table53[[#This Row],[UVP]]/1.19)*(1-G$2) -> 6.5546218
A14: 1104151 | B14: Bezug Kopfstütze 2022 [Tar] - MK2 | C14: 13 | D14: =(Table53[[#This Row],[UVP]]/1.19)*(1-G$2) -> 6.5546218
... A121: 1104139 | B121: Stoffbezug 2022 [Tar] - WM | C121: 99.9 | D121: =(Table53[[#This Row],[UVP]]/1.19)*(1-G$2) -> 50.369748

Sheet Ersatzteilpreisliste
A1: Nr. | B1: Beschreibung | C1: UVP | D1: Aufwand
A2: 1100813 | B2: 3 Punkt Gurtsystem - Shield | C2: 20 | D2: 1
A3: 1103643 | B3: 5 Punkt Gurtsystem - MK3 | C3: 35 | D3: 1
A4: 1101936 | B4: 5 Punkt Gurtsystem - ONE ONE2 | C4: 30 | D4: 4
A5: 1003124 | B5: 5 Punkt Gurtsystem Holmberg - MK1 MK2 RK MV WM DF KZ | C5: 30 | D5: 3
A6: 1100810 | B6: 5 Punkt Gurtsystem Shield - MDS | C6: 20 | D6: 1
A7: 1103681 | B7: Styropor EPS [LH+RH] - MK3 | C7: 17 | D7: 1
A8: 1102002 | B8: Abdeckung Spieldose [Akustisches Signal] - ONE ONE2 | C8: 3 | D8: 1
A9: 1101279 | B9: Absatz & Nieten - MK2 | C9: 13 | D9: 1
A10: 1103295 | B10: Anti Friction Kit + Schulterpolster - ONE | C10: 21 | D10: 1
A11: 1101932 | B11: ARB Abdeckung (RH+LH) - ONE ONE2 | C11: 3 | D11: 1
A12: 1101925 | B12: ARB Drehknopf - ONE ONE2 | C12: 3 | D12: 1
A13: 1101922 | B13: ARB Komplett - ONE ONE2 | C13: 78 | D13: 3
... A97: 1002117 | B97: Styropor EPS [Rücken] - MV WM | C97: 7 | D97: 1
A98: ISOFIX | B98: Reinigung - ISOFIX | C98: 0 | D98: 2
A99: SLED | B99: Reinigung - Schiebefunktion | C99: 0 | D99: 2

Sheet DATA
A1: Bitte wählen | B1: Axkid ONE / ONE 2 | C1: Axkid Minikid 3 | D1: Axkid Minikid 2 | E1: Axkid Minikid 2 (2022/23) | F1: Axkid Move | G1: Axkid Rekid
B2: 1103898 | C2: 1104796 | D2: 1101314 | E2: 1006003 | F2: 1101314 | G2: 1101315
B3: 1103343 | C3: 1103706 | D3: 1101279 | E3: 1101314 | F3: 1101232 | G3: 1101281
B4: 1103295 | C4: 1103703 | D4: 1100939 | E4: 1101279 | F4: 1100939 | G4: 1101197
B5: 1103031 | C5: 1103702 | D5: 1100834 | E5: 1100939 | F5: 1100816 | G5: 1100791
B6: 1103028 | C6: 1103693 | D6: 1100817 | E6: 1100834 | F6: 1007215 | G6: 1007215
B7: 1103019 | C7: 1103688 | D7: 1100816 | E7: 1100817 | F7: 1004453 | G7: 1006003
B8: 1102859 | C8: 1103686 | D8: 1006504 | E8: 1100816 | F8: 1004445 | G8: 1004102
B9: 1102238 | C9: 1103685 | D9: 1004453 | E9: 1004453 | F9: 1003207 | G9: 1004000
B10: 1101986 | C10: 1103684 | D10: 1004445 | E10: 1004445 | F10: 1003126 | G10: 1003409
B11: 1101936 | C11: 1103681 | D11: 1003409 | E11: 1003409 | F11: 1003124 | G11: 1003400
B12: 1101935 | C12: 1103651 | D12: 1003400 | E12: 1003400 | F12: 1002202 | G12: 1003207
B13: 1101934 | C13: 1103650 | D13: 1003207 | E13: 1003207 | F13: 1002119 | G13: 1003126
... B18: 1101927 | C18: 1103643 | D18: 1002202 | E18: 1002202 | F18: 1900028 | G18: 1002104
B19: 1101926 | C19: 1103642 | D19: 1002112 | E19: 1002112 | G19: 1002103
B20: 1101925 | C20: 1103641 | D20: 1002108 | E20: 1002108 | G20: 1002101
B21: 1101924 | C21: 1103693 | D21: 1900028 | E21: 1900028 | G21: 1900028
B22: 1101922 | C22: 1103639 | D22: 1100791 | E22: 1100791
B23: 1101921
B24: ISOFIX
B25: SLED
A29: Aufwand | B29: 17.85
D30: Bitte wählen
D31: Kostenpflichtig
D32: Kostenfrei
