Workbook

Sheet Fixkosten-Variable Kosten
A1: Fixkosten & Variable Kosten – Monatsübersicht
A2: Zahltag = Tag im Monat (z.B. 1, 5, 28). Fixkosten: Betrag nur im ersten Monat eintragen – läuft automatisch weiter, bis du ihn überschreibst. Variable Kosten: jeden Monat manuell eintragen.
C3: 2026 | D3: Juli | E3: August | J3: Janaur 2027 | L3: März
A4: Zahltag | B4: Ausgabe | C4: Typ | D4: Monat 1 | E4: Monat 2 | F4: Monat 3 | G4: Monat 4 | H4: Monat 5 | I4: Monat 6 | J4: Monat 7 | K4: Monat 8 | L4: Monat 9 | M4: Monat 10 | N4: Monat 11 | O4: Monat 12 | P4: Monat 13 | Q4: Monat 14 | R4: Monat 15 | S4: Monat 16 | T4: Monat 17 | U4: Monat 18 | V4: Monat 19 | W4: Monat 20 | X4: Monat 21 | Y4: Monat 22 | Z4: Monat 23 | AA4: Monat 24 | AB4: Monat 25 | AC4: Monat 26 | AD4: Monat 27 | AE4: Monat 28 | AF4: Monat 29 | AG4: Monat 30 | AH4: Monat 31 | AI4: Monat 32 | AJ4: Monat 33 | AK4: Monat 34
A5: 1. | B5: Claude Code | C5: Fix | D5: 17.99 | E5: =IF(C5="Fix",D5,"") -> 17.99 | F5: =IF(C5="Fix",E5,"") -> 17.99 | G5: =IF(C5="Fix",F5,"") -> 17.99 | H5: =IF(C5="Fix",G5,"") -> 17.99 | I5: =IF(C5="Fix",H5,"") -> 17.99 | J5: =IF(C5="Fix",I5,"") -> 17.99 | K5: =IF(C5="Fix",J5,"") -> 17.99 | L5: =IF(C5="Fix",K5,"") -> 17.99 | M5: =IF(C5="Fix",L5,"") -> 17.99 | N5: =IF(C5="Fix",M5,"") -> 17.99 | O5: =IF(C5="Fix",N5,"") -> 17.99 | P5: =IF(C5="Fix",O5,"") -> 17.99 | Q5: =IF(C5="Fix",P5,"") -> 17.99 | R5: =IF(C5="Fix",Q5,"") -> 17.99 | S5: =IF(C5="Fix",R5,"") -> 17.99 | T5: =IF(C5="Fix",S5,"") -> 17.99 | U5: =IF(C5="Fix",T5,"") -> 17.99 | V5: =IF(C5="Fix",U5,"") -> 17.99 | W5: =IF(C5="Fix",V5,"") -> 17.99 | X5: =IF(C5="Fix",W5,"") -> 17.99 | Y5: =IF(C5="Fix",X5,"") -> 17.99 | Z5: =IF(C5="Fix",Y5,"") -> 17.99 | AA5: =IF(C5="Fix",Z5,"") -> 17.99 | AB5: =IF(C5="Fix",AA5,"") -> 17.99 | AC5: =IF(C5="Fix",AB5,"") -> 17.99 | AD5: =IF(C5="Fix",AC5,"") -> 17.99 | AE5: =IF(C5="Fix",AD5,"") -> 17.99 | AF5: =IF(C5="Fix",AE5,"") -> 17.99 | AG5: =IF(C5="Fix",AF5,"") -> 17.99 | AH5: =IF(C5="Fix",AG5,"") -> 17.99 | AI5: =IF(C5="Fix",AH5,"") -> 17.99 | AJ5: =IF(C5="Fix",AI5,"") -> 17.99 | AK5: =IF(C5="Fix",AJ5,"") -> 17.99
A6: 2. | B6: Rechtsschutz | C6: Fix | D6: 68.65 | E6: =IF(C6="Fix",D6,"") -> 68.65 | F6: =IF(C6="Fix",E6,"") -> 68.65 | G6: =IF(C6="Fix",F6,"") -> 68.65 | H6: =IF(C6="Fix",G6,"") -> 68.65 | I6: =IF(C6="Fix",H6,"") -> 68.65 | J6: =IF(C6="Fix",I6,"") -> 68.65 | K6: =IF(C6="Fix",J6,"") -> 68.65 | L6: =IF(C6="Fix",K6,"") -> 68.65 | M6: =IF(C6="Fix",L6,"") -> 68.65 | N6: =IF(C6="Fix",M6,"") -> 68.65 | O6: =IF(C6="Fix",N6,"") -> 68.65 | P6: =IF(C6="Fix",O6,"") -> 68.65 | Q6: =IF(C6="Fix",P6,"") -> 68.65 | R6: =IF(C6="Fix",Q6,"") -> 68.65 | S6: =IF(C6="Fix",R6,"") -> 68.65 | T6: =IF(C6="Fix",S6,"") -> 68.65 | U6: =IF(C6="Fix",T6,"") -> 68.65 | V6: =IF(C6="Fix",U6,"") -> 68.65 | W6: =IF(C6="Fix",V6,"") -> 68.65 | X6: =IF(C6="Fix",W6,"") -> 68.65 | Y6: =IF(C6="Fix",X6,"") -> 68.65 | Z6: =IF(C6="Fix",Y6,"") -> 68.65 | AA6: =IF(C6="Fix",Z6,"") -> 68.65 | AB6: =IF(C6="Fix",AA6,"") -> 68.65 | AC6: =IF(C6="Fix",AB6,"") -> 68.65 | AD6: =IF(C6="Fix",AC6,"") -> 68.65 | AE6: =IF(C6="Fix",AD6,"") -> 68.65 | AF6: =IF(C6="Fix",AE6,"") -> 68.65 | AG6: =IF(C6="Fix",AF6,"") -> 68.65 | AH6: =IF(C6="Fix",AG6,"") -> 68.65 | AI6: =IF(C6="Fix",AH6,"") -> 68.65 | AJ6: =IF(C6="Fix",AI6,"") -> 68.65 | AK6: =IF(C6="Fix",AJ6,"") -> 68.65
A7: 2. | B7: Grover | C7: Fix | D7: 24.9 | E7: =IF(C7="Fix",D7,"") -> 24.9 | F7: =IF(C7="Fix",E7,"") -> 24.9 | G7: =IF(C7="Fix",F7,"") -> 24.9 | H7: =IF(C7="Fix",G7,"") -> 24.9 | I7: =IF(C7="Fix",H7,"") -> 24.9 | J7: =IF(C7="Fix",I7,"") -> 24.9 | K7: =IF(C7="Fix",J7,"") -> 24.9 | L7: =IF(C7="Fix",K7,"") -> 24.9 | M7: =IF(C7="Fix",L7,"") -> 24.9 | N7: =IF(C7="Fix",M7,"") -> 24.9 | O7: =IF(C7="Fix",N7,"") -> 24.9 | P7: =IF(C7="Fix",O7,"") -> 24.9 | Q7: =IF(C7="Fix",P7,"") -> 24.9 | R7: =IF(C7="Fix",Q7,"") -> 24.9 | S7: =IF(C7="Fix",R7,"") -> 24.9 | T7: =IF(C7="Fix",S7,"") -> 24.9 | U7: =IF(C7="Fix",T7,"") -> 24.9 | V7: =IF(C7="Fix",U7,"") -> 24.9 | W7: =IF(C7="Fix",V7,"") -> 24.9 | X7: =IF(C7="Fix",W7,"") -> 24.9 | Y7: =IF(C7="Fix",X7,"") -> 24.9 | Z7: =IF(C7="Fix",Y7,"") -> 24.9 | AA7: =IF(C7="Fix",Z7,"") -> 24.9 | AB7: =IF(C7="Fix",AA7,"") -> 24.9 | AC7: =IF(C7="Fix",AB7,"") -> 24.9 | AD7: =IF(C7="Fix",AC7,"") -> 24.9 | AE7: =IF(C7="Fix",AD7,"") -> 24.9 | AF7: =IF(C7="Fix",AE7,"") -> 24.9 | AG7: =IF(C7="Fix",AF7,"") -> 24.9 | AH7: =IF(C7="Fix",AG7,"") -> 24.9 | AI7: =IF(C7="Fix",AH7,"") -> 24.9 | AJ7: =IF(C7="Fix",AI7,"") -> 24.9 | AK7: =IF(C7="Fix",AJ7,"") -> 24.9
A8: 3. | B8: Vers. Leasing | C8: Fix | D8: 24.9 | E8: =IF(C8="Fix",D8,"") -> 24.9 | F8: =IF(C8="Fix",E8,"") -> 24.9 | G8: =IF(C8="Fix",F8,"") -> 24.9 | H8: =IF(C8="Fix",G8,"") -> 24.9 | I8: =IF(C8="Fix",H8,"") -> 24.9 | J8: =IF(C8="Fix",I8,"") -> 24.9 | K8: =IF(C8="Fix",J8,"") -> 24.9 | L8: =IF(C8="Fix",K8,"") -> 24.9 | M8: =IF(C8="Fix",L8,"") -> 24.9 | N8: =IF(C8="Fix",M8,"") -> 24.9 | O8: =IF(C8="Fix",N8,"") -> 24.9 | P8: =IF(C8="Fix",O8,"") -> 24.9 | Q8: =IF(C8="Fix",P8,"") -> 24.9 | R8: =IF(C8="Fix",Q8,"") -> 24.9 | S8: =IF(C8="Fix",R8,"") -> 24.9 | T8: =IF(C8="Fix",S8,"") -> 24.9 | U8: =IF(C8="Fix",T8,"") -> 24.9 | V8: =IF(C8="Fix",U8,"") -> 24.9 | W8: =IF(C8="Fix",V8,"") -> 24.9 | X8: =IF(C8="Fix",W8,"") -> 24.9 | Y8: =IF(C8="Fix",X8,"") -> 24.9 | Z8: =IF(C8="Fix",Y8,"") -> 24.9 | AA8: =IF(C8="Fix",Z8,"") -> 24.9 | AB8: =IF(C8="Fix",AA8,"") -> 24.9 | AC8: =IF(C8="Fix",AB8,"") -> 24.9 | AD8: =IF(C8="Fix",AC8,"") -> 24.9 | AE8: =IF(C8="Fix",AD8,"") -> 24.9 | AF8: =IF(C8="Fix",AE8,"") -> 24.9 | AG8: =IF(C8="Fix",AF8,"") -> 24.9 | AH8: =IF(C8="Fix",AG8,"") -> 24.9 | AI8: =IF(C8="Fix",AH8,"") -> 24.9 | AJ8: =IF(C8="Fix",AI8,"") -> 24.9 | AK8: =IF(C8="Fix",AJ8,"") -> 24.9
A9: 3. | B9: Taxi Werbung | C9: Fix | D9: 202.42 | E9: =IF(C9="Fix",D9,"") -> 202.42 | F9: =IF(C9="Fix",E9,"") -> 202.42 | G9: =IF(C9="Fix",F9,"") -> 202.42 | H9: =IF(C9="Fix",G9,"") -> 202.42 | I9: =IF(C9="Fix",H9,"") -> 202.42 | J9: =IF(C9="Fix",I9,"") -> 202.42 | K9: =IF(C9="Fix",J9,"") -> 202.42 | L9: =IF(C9="Fix",K9,"") -> 202.42 | M9: =IF(C9="Fix",L9,"") -> 202.42 | N9: =IF(C9="Fix",M9,"") -> 202.42 | O9: =IF(C9="Fix",N9,"") -> 202.42 | P9: =IF(C9="Fix",O9,"") -> 202.42 | Q9: =IF(C9="Fix",P9,"") -> 202.42 | R9: =IF(C9="Fix",Q9,"") -> 202.42 | S9: =IF(C9="Fix",R9,"") -> 202.42 | T9: =IF(C9="Fix",S9,"") -> 202.42 | U9: =IF(C9="Fix",T9,"") -> 202.42 | V9: =IF(C9="Fix",U9,"") -> 202.42 | W9: =IF(C9="Fix",V9,"") -> 202.42 | X9: =IF(C9="Fix",W9,"") -> 202.42 | Y9: =IF(C9="Fix",X9,"") -> 202.42 | Z9: =IF(C9="Fix",Y9,"") -> 202.42 | AA9: =IF(C9="Fix",Z9,"") -> 202.42 | AB9: =IF(C9="Fix",AA9,"") -> 202.42 | AC9: =IF(C9="Fix",AB9,"") -> 202.42 | AD9: =IF(C9="Fix",AC9,"") -> 202.42 | AE9: =IF(C9="Fix",AD9,"") -> 202.42 | AF9: =IF(C9="Fix",AE9,"") -> 202.42 | AG9: =IF(C9="Fix",AF9,"") -> 202.42 | AH9: =IF(C9="Fix",AG9,"") -> 202.42 | AI9: =IF(C9="Fix",AH9,"") -> 202.42 | AJ9: =IF(C9="Fix",AI9,"") -> 202.42 | AK9: =IF(C9="Fix",AJ9,"") -> 202.42
A10: 4. | B10: IT Recht | C10: Fix | D10: 11.78 | E10: =IF(C10="Fix",D10,"") -> 11.78 | F10: =IF(C10="Fix",E10,"") -> 11.78 | G10: =IF(C10="Fix",F10,"") -> 11.78 | H10: =IF(C10="Fix",G10,"") -> 11.78 | I10: =IF(C10="Fix",H10,"") -> 11.78 | J10: =IF(C10="Fix",I10,"") -> 11.78 | K10: =IF(C10="Fix",J10,"") -> 11.78 | L10: =IF(C10="Fix",K10,"") -> 11.78 | M10: =IF(C10="Fix",L10,"") -> 11.78 | N10: =IF(C10="Fix",M10,"") -> 11.78 | O10: =IF(C10="Fix",N10,"") -> 11.78 | P10: =IF(C10="Fix",O10,"") -> 11.78 | Q10: =IF(C10="Fix",P10,"") -> 11.78 | R10: =IF(C10="Fix",Q10,"") -> 11.78 | S10: =IF(C10="Fix",R10,"") -> 11.78 | T10: =IF(C10="Fix",S10,"") -> 11.78 | U10: =IF(C10="Fix",T10,"") -> 11.78 | V10: =IF(C10="Fix",U10,"") -> 11.78 | W10: =IF(C10="Fix",V10,"") -> 11.78 | X10: =IF(C10="Fix",W10,"") -> 11.78 | Y10: =IF(C10="Fix",X10,"") -> 11.78 | Z10: =IF(C10="Fix",Y10,"") -> 11.78 | AA10: =IF(C10="Fix",Z10,"") -> 11.78 | AB10: =IF(C10="Fix",AA10,"") -> 11.78 | AC10: =IF(C10="Fix",AB10,"") -> 11.78 | AD10: =IF(C10="Fix",AC10,"") -> 11.78 | AE10: =IF(C10="Fix",AD10,"") -> 11.78 | AF10: =IF(C10="Fix",AE10,"") -> 11.78 | AG10: =IF(C10="Fix",AF10,"") -> 11.78 | AH10: =IF(C10="Fix",AG10,"") -> 11.78 | AI10: =IF(C10="Fix",AH10,"") -> 11.78 | AJ10: =IF(C10="Fix",AI10,"") -> 11.78 | AK10: =IF(C10="Fix",AJ10,"") -> 11.78
A11: 5. | B11: Apple Cloud | C11: Fix | D11: 19.99 | E11: =IF(C11="Fix",D11,"") -> 19.99 | F11: =IF(C11="Fix",E11,"") -> 19.99 | G11: =IF(C11="Fix",F11,"") -> 19.99 | H11: =IF(C11="Fix",G11,"") -> 19.99 | I11: =IF(C11="Fix",H11,"") -> 19.99 | J11: =IF(C11="Fix",I11,"") -> 19.99 | K11: =IF(C11="Fix",J11,"") -> 19.99 | L11: =IF(C11="Fix",K11,"") -> 19.99 | M11: =IF(C11="Fix",L11,"") -> 19.99 | N11: =IF(C11="Fix",M11,"") -> 19.99 | O11: =IF(C11="Fix",N11,"") -> 19.99 | P11: =IF(C11="Fix",O11,"") -> 19.99 | Q11: =IF(C11="Fix",P11,"") -> 19.99 | R11: =IF(C11="Fix",Q11,"") -> 19.99 | S11: =IF(C11="Fix",R11,"") -> 19.99 | T11: =IF(C11="Fix",S11,"") -> 19.99 | U11: =IF(C11="Fix",T11,"") -> 19.99 | V11: =IF(C11="Fix",U11,"") -> 19.99 | W11: =IF(C11="Fix",V11,"") -> 19.99 | X11: =IF(C11="Fix",W11,"") -> 19.99 | Y11: =IF(C11="Fix",X11,"") -> 19.99 | Z11: =IF(C11="Fix",Y11,"") -> 19.99 | AA11: =IF(C11="Fix",Z11,"") -> 19.99 | AB11: =IF(C11="Fix",AA11,"") -> 19.99 | AC11: =IF(C11="Fix",AB11,"") -> 19.99 | AD11: =IF(C11="Fix",AC11,"") -> 19.99 | AE11: =IF(C11="Fix",AD11,"") -> 19.99 | AF11: =IF(C11="Fix",AE11,"") -> 19.99 | AG11: =IF(C11="Fix",AF11,"") -> 19.99 | AH11: =IF(C11="Fix",AG11,"") -> 19.99 | AI11: =IF(C11="Fix",AH11,"") -> 19.99 | AJ11: =IF(C11="Fix",AI11,"") -> 19.99 | AK11: =IF(C11="Fix",AJ11,"") -> 19.99
A12: 5. | B12: SPK Kontoführung | C12: Fix | D12: 70 | E12: =IF(C12="Fix",D12,"") -> 70 | F12: =IF(C12="Fix",E12,"") -> 70 | G12: =IF(C12="Fix",F12,"") -> 70 | H12: =IF(C12="Fix",G12,"") -> 70 | I12: =IF(C12="Fix",H12,"") -> 70 | J12: =IF(C12="Fix",I12,"") -> 70 | K12: =IF(C12="Fix",J12,"") -> 70 | L12: =IF(C12="Fix",K12,"") -> 70 | M12: =IF(C12="Fix",L12,"") -> 70 | N12: =IF(C12="Fix",M12,"") -> 70 | O12: =IF(C12="Fix",N12,"") -> 70 | P12: =IF(C12="Fix",O12,"") -> 70 | Q12: =IF(C12="Fix",P12,"") -> 70 | R12: =IF(C12="Fix",Q12,"") -> 70 | S12: =IF(C12="Fix",R12,"") -> 70 | T12: =IF(C12="Fix",S12,"") -> 70 | U12: =IF(C12="Fix",T12,"") -> 70 | V12: =IF(C12="Fix",U12,"") -> 70 | W12: =IF(C12="Fix",V12,"") -> 70 | X12: =IF(C12="Fix",W12,"") -> 70 | Y12: =IF(C12="Fix",X12,"") -> 70 | Z12: =IF(C12="Fix",Y12,"") -> 70 | AA12: =IF(C12="Fix",Z12,"") -> 70 | AB12: =IF(C12="Fix",AA12,"") -> 70 | AC12: =IF(C12="Fix",AB12,"") -> 70 | AD12: =IF(C12="Fix",AC12,"") -> 70 | AE12: =IF(C12="Fix",AD12,"") -> 70 | AF12: =IF(C12="Fix",AE12,"") -> 70 | AG12: =IF(C12="Fix",AF12,"") -> 70 | AH12: =IF(C12="Fix",AG12,"") -> 70 | AI12: =IF(C12="Fix",AH12,"") -> 70 | AJ12: =IF(C12="Fix",AI12,"") -> 70 | AK12: =IF(C12="Fix",AJ12,"") -> 70
A13: 6. | B13: Impuls Coach | C13: Fix | D13: 250 | E13: =IF(C13="Fix",D13,"") -> 250 | F13: =IF(C13="Fix",E13,"") -> 250 | G13: =IF(C13="Fix",F13,"") -> 250 | H13: =IF(C13="Fix",G13,"") -> 250 | I13: =IF(C13="Fix",H13,"") -> 250 | J13: =IF(C13="Fix",I13,"") -> 250 | K13: =IF(C13="Fix",J13,"") -> 250 | L13: =IF(C13="Fix",K13,"") -> 250 | M13: =IF(C13="Fix",L13,"") -> 250 | N13: =IF(C13="Fix",M13,"") -> 250 | O13: =IF(C13="Fix",N13,"") -> 250 | P13: =IF(C13="Fix",O13,"") -> 250 | Q13: =IF(C13="Fix",P13,"") -> 250 | R13: =IF(C13="Fix",Q13,"") -> 250 | S13: =IF(C13="Fix",R13,"") -> 250 | T13: =IF(C13="Fix",S13,"") -> 250 | U13: =IF(C13="Fix",T13,"") -> 250 | V13: =IF(C13="Fix",U13,"") -> 250 | W13: =IF(C13="Fix",V13,"") -> 250 | X13: =IF(C13="Fix",W13,"") -> 250 | Y13: =IF(C13="Fix",X13,"") -> 250 | Z13: =IF(C13="Fix",Y13,"") -> 250 | AA13: =IF(C13="Fix",Z13,"") -> 250 | AB13: =IF(C13="Fix",AA13,"") -> 250 | AC13: =IF(C13="Fix",AB13,"") -> 250 | AD13: =IF(C13="Fix",AC13,"") -> 250 | AE13: =IF(C13="Fix",AD13,"") -> 250 | AF13: =IF(C13="Fix",AE13,"") -> 250 | AG13: =IF(C13="Fix",AF13,"") -> 250 | AH13: =IF(C13="Fix",AG13,"") -> 250 | AI13: =IF(C13="Fix",AH13,"") -> 250 | AJ13: =IF(C13="Fix",AI13,"") -> 250 | AK13: =IF(C13="Fix",AJ13,"") -> 250
A14: 6. | B14: Strom | C14: Fix | D14: 47 | E14: =IF(C14="Fix",D14,"") -> 47 | F14: =IF(C14="Fix",E14,"") -> 47 | G14: =IF(C14="Fix",F14,"") -> 47 | H14: =IF(C14="Fix",G14,"") -> 47 | I14: =IF(C14="Fix",H14,"") -> 47 | J14: =IF(C14="Fix",I14,"") -> 47 | K14: =IF(C14="Fix",J14,"") -> 47 | L14: =IF(C14="Fix",K14,"") -> 47 | M14: =IF(C14="Fix",L14,"") -> 47 | N14: =IF(C14="Fix",M14,"") -> 47 | O14: =IF(C14="Fix",N14,"") -> 47 | P14: =IF(C14="Fix",O14,"") -> 47 | Q14: =IF(C14="Fix",P14,"") -> 47 | R14: =IF(C14="Fix",Q14,"") -> 47 | S14: =IF(C14="Fix",R14,"") -> 47 | T14: =IF(C14="Fix",S14,"") -> 47 | U14: =IF(C14="Fix",T14,"") -> 47 | V14: =IF(C14="Fix",U14,"") -> 47 | W14: =IF(C14="Fix",V14,"") -> 47 | X14: =IF(C14="Fix",W14,"") -> 47 | Y14: =IF(C14="Fix",X14,"") -> 47 | Z14: =IF(C14="Fix",Y14,"") -> 47 | AA14: =IF(C14="Fix",Z14,"") -> 47 | AB14: =IF(C14="Fix",AA14,"") -> 47 | AC14: =IF(C14="Fix",AB14,"") -> 47 | AD14: =IF(C14="Fix",AC14,"") -> 47 | AE14: =IF(C14="Fix",AD14,"") -> 47 | AF14: =IF(C14="Fix",AE14,"") -> 47 | AG14: =IF(C14="Fix",AF14,"") -> 47 | AH14: =IF(C14="Fix",AG14,"") -> 47 | AI14: =IF(C14="Fix",AH14,"") -> 47 | AJ14: =IF(C14="Fix",AI14,"") -> 47 | AK14: =IF(C14="Fix",AJ14,"") -> 47
A15: 6. | B15: Lexoffice | C15: Fix | D15: 14.16 | E15: =IF(C15="Fix",D15,"") -> 14.16 | F15: =IF(C15="Fix",E15,"") -> 14.16 | G15: =IF(C15="Fix",F15,"") -> 14.16 | H15: =IF(C15="Fix",G15,"") -> 14.16 | I15: =IF(C15="Fix",H15,"") -> 14.16 | J15: =IF(C15="Fix",I15,"") -> 14.16 | K15: =IF(C15="Fix",J15,"") -> 14.16 | L15: =IF(C15="Fix",K15,"") -> 14.16 | M15: =IF(C15="Fix",L15,"") -> 14.16 | N15: =IF(C15="Fix",M15,"") -> 14.16 | O15: =IF(C15="Fix",N15,"") -> 14.16 | P15: =IF(C15="Fix",O15,"") -> 14.16 | Q15: =IF(C15="Fix",P15,"") -> 14.16 | R15: =IF(C15="Fix",Q15,"") -> 14.16 | S15: =IF(C15="Fix",R15,"") -> 14.16 | T15: =IF(C15="Fix",S15,"") -> 14.16 | U15: =IF(C15="Fix",T15,"") -> 14.16 | V15: =IF(C15="Fix",U15,"") -> 14.16 | W15: =IF(C15="Fix",V15,"") -> 14.16 | X15: =IF(C15="Fix",W15,"") -> 14.16 | Y15: =IF(C15="Fix",X15,"") -> 14.16 | Z15: =IF(C15="Fix",Y15,"") -> 14.16 | AA15: =IF(C15="Fix",Z15,"") -> 14.16 | AB15: =IF(C15="Fix",AA15,"") -> 14.16 | AC15: =IF(C15="Fix",AB15,"") -> 14.16 | AD15: =IF(C15="Fix",AC15,"") -> 14.16 | AE15: =IF(C15="Fix",AD15,"") -> 14.16 | AF15: =IF(C15="Fix",AE15,"") -> 14.16 | AG15: =IF(C15="Fix",AF15,"") -> 14.16 | AH15: =IF(C15="Fix",AG15,"") -> 14.16 | AI15: =IF(C15="Fix",AH15,"") -> 14.16 | AJ15: =IF(C15="Fix",AI15,"") -> 14.16 | AK15: =IF(C15="Fix",AJ15,"") -> 14.16
A16: 6. | B16: Website | C16: Fix | D16: 629.51 | E16: =IF(C16="Fix",D16,"") -> 629.51 | F16: =IF(C16="Fix",E16,"") -> 629.51 | G16: =IF(C16="Fix",F16,"") -> 629.51 | H16: =IF(C16="Fix",G16,"") -> 629.51 | I16: =IF(C16="Fix",H16,"") -> 629.51 | J16: =IF(C16="Fix",I16,"") -> 629.51 | K16: =IF(C16="Fix",J16,"") -> 629.51 | L16: =IF(C16="Fix",K16,"") -> 629.51 | M16: =IF(C16="Fix",L16,"") -> 629.51 | N16: =IF(C16="Fix",M16,"") -> 629.51 | O16: =IF(C16="Fix",N16,"") -> 629.51 | P16: =IF(C16="Fix",O16,"") -> 629.51 | Q16: =IF(C16="Fix",P16,"") -> 629.51 | R16: =IF(C16="Fix",Q16,"") -> 629.51 | S16: =IF(C16="Fix",R16,"") -> 629.51 | T16: =IF(C16="Fix",S16,"") -> 629.51 | U16: =IF(C16="Fix",T16,"") -> 629.51 | V16: =IF(C16="Fix",U16,"") -> 629.51 | W16: =IF(C16="Fix",V16,"") -> 629.51 | X16: =IF(C16="Fix",W16,"") -> 629.51 | Y16: =IF(C16="Fix",X16,"") -> 629.51 | Z16: =IF(C16="Fix",Y16,"") -> 629.51 | AA16: =IF(C16="Fix",Z16,"") -> 629.51 | AB16: =IF(C16="Fix",AA16,"") -> 629.51 | AC16: =IF(C16="Fix",AB16,"") -> 629.51 | AD16: =IF(C16="Fix",AC16,"") -> 629.51 | AE16: =IF(C16="Fix",AD16,"") -> 629.51 | AF16: =IF(C16="Fix",AE16,"") -> 629.51 | AG16: =IF(C16="Fix",AF16,"") -> 629.51 | AH16: =IF(C16="Fix",AG16,"") -> 629.51 | AI16: =IF(C16="Fix",AH16,"") -> 629.51 | AJ16: =IF(C16="Fix",AI16,"") -> 629.51 | AK16: =IF(C16="Fix",AJ16,"") -> 629.51
... A19: 11. | B19: EC Gebühren | C19: Variabel | D19: 120 | E19: =IF(C19="Fix",D19,"") | F19: =IF(C19="Fix",E19,"") | G19: =IF(C19="Fix",F19,"") | H19: =IF(C19="Fix",G19,"") | I19: =IF(C19="Fix",H19,"") | J19: =IF(C19="Fix",I19,"") | K19: =IF(C19="Fix",J19,"") | L19: =IF(C19="Fix",K19,"") | M19: =IF(C19="Fix",L19,"") | N19: =IF(C19="Fix",M19,"") | O19: =IF(C19="Fix",N19,"") | P19: =IF(C19="Fix",O19,"") | Q19: =IF(C19="Fix",P19,"") | R19: =IF(C19="Fix",Q19,"") | S19: =IF(C19="Fix",R19,"") | T19: =IF(C19="Fix",S19,"") | U19: =IF(C19="Fix",T19,"") | V19: =IF(C19="Fix",U19,"") | W19: =IF(C19="Fix",V19,"") | X19: =IF(C19="Fix",W19,"") | Y19: =IF(C19="Fix",X19,"") | Z19: =IF(C19="Fix",Y19,"") | AA19: =IF(C19="Fix",Z19,"") | AB19: =IF(C19="Fix",AA19,"") | AC19: =IF(C19="Fix",AB19,"") | AD19: =IF(C19="Fix",AC19,"") | AE19: =IF(C19="Fix",AD19,"") | AF19: =IF(C19="Fix",AE19,"") | AG19: =IF(C19="Fix",AF19,"") | AH19: =IF(C19="Fix",AG19,"") | AI19: =IF(C19="Fix",AH19,"") | AJ19: =IF(C19="Fix",AI19,"") | AK19: =IF(C19="Fix",AJ19,"")
A20: 14. | B20: Identity Shift | C20: Fix | D20: 270 | E20: =IF(C20="Fix",D20,"") -> 270 | G20: =IF(C20="Fix",F20,"") -> 0 | H20: =IF(C20="Fix",G20,"") -> 0 | I20: =IF(C20="Fix",H20,"") -> 0 | J20: =IF(C20="Fix",I20,"") -> 0 | K20: =IF(C20="Fix",J20,"") -> 0 | L20: =IF(C20="Fix",K20,"") -> 0 | M20: =IF(C20="Fix",L20,"") -> 0 | N20: =IF(C20="Fix",M20,"") -> 0 | O20: =IF(C20="Fix",N20,"") -> 0 | P20: =IF(C20="Fix",O20,"") -> 0 | Q20: =IF(C20="Fix",P20,"") -> 0 | R20: =IF(C20="Fix",Q20,"") -> 0 | S20: =IF(C20="Fix",R20,"") -> 0 | T20: =IF(C20="Fix",S20,"") -> 0 | U20: =IF(C20="Fix",T20,"") -> 0 | V20: =IF(C20="Fix",U20,"") -> 0 | W20: =IF(C20="Fix",V20,"") -> 0 | X20: =IF(C20="Fix",W20,"") -> 0 | Y20: =IF(C20="Fix",X20,"") -> 0 | Z20: =IF(C20="Fix",Y20,"") -> 0 | AA20: =IF(C20="Fix",Z20,"") -> 0 | AB20: =IF(C20="Fix",AA20,"") -> 0 | AC20: =IF(C20="Fix",AB20,"") -> 0 | AD20: =IF(C20="Fix",AC20,"") -> 0 | AE20: =IF(C20="Fix",AD20,"") -> 0 | AF20: =IF(C20="Fix",AE20,"") -> 0 | AG20: =IF(C20="Fix",AF20,"") -> 0 | AH20: =IF(C20="Fix",AG20,"") -> 0 | AI20: =IF(C20="Fix",AH20,"") -> 0 | AJ20: =IF(C20="Fix",AI20,"") -> 0 | AK20: =IF(C20="Fix",AJ20,"") -> 0
A21: 14. | B21: Steuer Umsatz | C21: Variabel | D21: 2200 | E21: =IF(C21="Fix",D21,"") | F21: =IF(C21="Fix",E21,"") | G21: =IF(C21="Fix",F21,"") | H21: =IF(C21="Fix",G21,"") | I21: =IF(C21="Fix",H21,"") | J21: =IF(C21="Fix",I21,"") | K21: =IF(C21="Fix",J21,"") | L21: =IF(C21="Fix",K21,"") | M21: =IF(C21="Fix",L21,"") | N21: =IF(C21="Fix",M21,"") | O21: =IF(C21="Fix",N21,"") | P21: =IF(C21="Fix",O21,"") | Q21: =IF(C21="Fix",P21,"") | R21: =IF(C21="Fix",Q21,"") | S21: =IF(C21="Fix",R21,"") | T21: =IF(C21="Fix",S21,"") | U21: =IF(C21="Fix",T21,"") | V21: =IF(C21="Fix",U21,"") | W21: =IF(C21="Fix",V21,"") | X21: =IF(C21="Fix",W21,"") | Y21: =IF(C21="Fix",X21,"") | Z21: =IF(C21="Fix",Y21,"") | AA21: =IF(C21="Fix",Z21,"") | AB21: =IF(C21="Fix",AA21,"") | AC21: =IF(C21="Fix",AB21,"") | AD21: =IF(C21="Fix",AC21,"") | AE21: =IF(C21="Fix",AD21,"") | AF21: =IF(C21="Fix",AE21,"") | AG21: =IF(C21="Fix",AF21,"") | AH21: =IF(C21="Fix",AG21,"") | AI21: =IF(C21="Fix",AH21,"") | AJ21: =IF(C21="Fix",AI21,"") | AK21: =IF(C21="Fix",AJ21,"")
A22: 15. | B22: SenVend | C22: Fix | D22: 16.36 | E22: =IF(C22="Fix",D22,"") -> 16.36 | F22: =IF(C22="Fix",E22,"") -> 16.36 | G22: =IF(C22="Fix",F22,"") -> 16.36 | H22: =IF(C22="Fix",G22,"") -> 16.36 | I22: =IF(C22="Fix",H22,"") -> 16.36 | J22: =IF(C22="Fix",I22,"") -> 16.36 | K22: =IF(C22="Fix",J22,"") -> 16.36 | L22: =IF(C22="Fix",K22,"") -> 16.36 | M22: =IF(C22="Fix",L22,"") -> 16.36 | N22: =IF(C22="Fix",M22,"") -> 16.36 | O22: =IF(C22="Fix",N22,"") -> 16.36 | P22: =IF(C22="Fix",O22,"") -> 16.36 | Q22: =IF(C22="Fix",P22,"") -> 16.36 | R22: =IF(C22="Fix",Q22,"") -> 16.36 | S22: =IF(C22="Fix",R22,"") -> 16.36 | T22: =IF(C22="Fix",S22,"") -> 16.36 | U22: =IF(C22="Fix",T22,"") -> 16.36 | V22: =IF(C22="Fix",U22,"") -> 16.36 | W22: =IF(C22="Fix",V22,"") -> 16.36 | X22: =IF(C22="Fix",W22,"") -> 16.36 | Y22: =IF(C22="Fix",X22,"") -> 16.36 | Z22: =IF(C22="Fix",Y22,"") -> 16.36 | AA22: =IF(C22="Fix",Z22,"") -> 16.36 | AB22: =IF(C22="Fix",AA22,"") -> 16.36 | AC22: =IF(C22="Fix",AB22,"") -> 16.36 | AD22: =IF(C22="Fix",AC22,"") -> 16.36 | AE22: =IF(C22="Fix",AD22,"") -> 16.36 | AF22: =IF(C22="Fix",AE22,"") -> 16.36 | AG22: =IF(C22="Fix",AF22,"") -> 16.36 | AH22: =IF(C22="Fix",AG22,"") -> 16.36 | AI22: =IF(C22="Fix",AH22,"") -> 16.36 | AJ22: =IF(C22="Fix",AI22,"") -> 16.36 | AK22: =IF(C22="Fix",AJ22,"") -> 16.36
A23: 15. | B23: Terminland | C23: Fix | D23: 19.99 | E23: =IF(C23="Fix",D23,"") -> 19.99 | F23: =IF(C23="Fix",E23,"") -> 19.99 | G23: =IF(C23="Fix",F23,"") -> 19.99 | H23: =IF(C23="Fix",G23,"") -> 19.99 | I23: =IF(C23="Fix",H23,"") -> 19.99 | J23: =IF(C23="Fix",I23,"") -> 19.99 | K23: =IF(C23="Fix",J23,"") -> 19.99 | L23: =IF(C23="Fix",K23,"") -> 19.99 | M23: =IF(C23="Fix",L23,"") -> 19.99 | N23: =IF(C23="Fix",M23,"") -> 19.99 | O23: =IF(C23="Fix",N23,"") -> 19.99 | P23: =IF(C23="Fix",O23,"") -> 19.99 | Q23: =IF(C23="Fix",P23,"") -> 19.99 | R23: =IF(C23="Fix",Q23,"") -> 19.99 | S23: =IF(C23="Fix",R23,"") -> 19.99 | T23: =IF(C23="Fix",S23,"") -> 19.99 | U23: =IF(C23="Fix",T23,"") -> 19.99 | V23: =IF(C23="Fix",U23,"") -> 19.99 | W23: =IF(C23="Fix",V23,"") -> 19.99 | X23: =IF(C23="Fix",W23,"") -> 19.99 | Y23: =IF(C23="Fix",X23,"") -> 19.99 | Z23: =IF(C23="Fix",Y23,"") -> 19.99 | AA23: =IF(C23="Fix",Z23,"") -> 19.99 | AB23: =IF(C23="Fix",AA23,"") -> 19.99 | AC23: =IF(C23="Fix",AB23,"") -> 19.99 | AD23: =IF(C23="Fix",AC23,"") -> 19.99 | AE23: =IF(C23="Fix",AD23,"") -> 19.99 | AF23: =IF(C23="Fix",AE23,"") -> 19.99 | AG23: =IF(C23="Fix",AF23,"") -> 19.99 | AH23: =IF(C23="Fix",AG23,"") -> 19.99 | AI23: =IF(C23="Fix",AH23,"") -> 19.99 | AJ23: =IF(C23="Fix",AI23,"") -> 19.99 | AK23: =IF(C23="Fix",AJ23,"") -> 19.99
A24: 15. | B24: Miete Automat | C24: Fix | D24: 70 | E24: =IF(C24="Fix",D24,"") -> 70 | F24: =IF(C24="Fix",E24,"") -> 70 | G24: =IF(C24="Fix",F24,"") -> 70 | H24: =IF(C24="Fix",G24,"") -> 70 | I24: =IF(C24="Fix",H24,"") -> 70 | J24: =IF(C24="Fix",I24,"") -> 70 | K24: =IF(C24="Fix",J24,"") -> 70 | L24: =IF(C24="Fix",K24,"") -> 70 | M24: =IF(C24="Fix",L24,"") -> 70 | N24: =IF(C24="Fix",M24,"") -> 70 | O24: =IF(C24="Fix",N24,"") -> 70 | P24: =IF(C24="Fix",O24,"") -> 70 | Q24: =IF(C24="Fix",P24,"") -> 70 | R24: =IF(C24="Fix",Q24,"") -> 70 | S24: =IF(C24="Fix",R24,"") -> 70 | T24: =IF(C24="Fix",S24,"") -> 70 | U24: =IF(C24="Fix",T24,"") -> 70 | V24: =IF(C24="Fix",U24,"") -> 70 | W24: =IF(C24="Fix",V24,"") -> 70 | X24: =IF(C24="Fix",W24,"") -> 70 | Y24: =IF(C24="Fix",X24,"") -> 70 | Z24: =IF(C24="Fix",Y24,"") -> 70 | AA24: =IF(C24="Fix",Z24,"") -> 70 | AB24: =IF(C24="Fix",AA24,"") -> 70 | AC24: =IF(C24="Fix",AB24,"") -> 70 | AD24: =IF(C24="Fix",AC24,"") -> 70 | AE24: =IF(C24="Fix",AD24,"") -> 70 | AF24: =IF(C24="Fix",AE24,"") -> 70 | AG24: =IF(C24="Fix",AF24,"") -> 70 | AH24: =IF(C24="Fix",AG24,"") -> 70 | AI24: =IF(C24="Fix",AH24,"") -> 70 | AJ24: =IF(C24="Fix",AI24,"") -> 70 | AK24: =IF(C24="Fix",AJ24,"") -> 70
A25: 15. | B25: Steuerberater | C25: Fix | D25: 119 | E25: =IF(C25="Fix",D25,"") -> 119 | F25: =IF(C25="Fix",E25,"") -> 119 | G25: =IF(C25="Fix",F25,"") -> 119 | H25: =IF(C25="Fix",G25,"") -> 119 | I25: =IF(C25="Fix",H25,"") -> 119 | J25: =IF(C25="Fix",I25,"") -> 119 | K25: =IF(C25="Fix",J25,"") -> 119 | L25: =IF(C25="Fix",K25,"") -> 119 | M25: =IF(C25="Fix",L25,"") -> 119 | N25: =IF(C25="Fix",M25,"") -> 119 | O25: =IF(C25="Fix",N25,"") -> 119 | P25: =IF(C25="Fix",O25,"") -> 119 | Q25: =IF(C25="Fix",P25,"") -> 119 | R25: =IF(C25="Fix",Q25,"") -> 119 | S25: =IF(C25="Fix",R25,"") -> 119 | T25: =IF(C25="Fix",S25,"") -> 119 | U25: =IF(C25="Fix",T25,"") -> 119 | V25: =IF(C25="Fix",U25,"") -> 119 | W25: =IF(C25="Fix",V25,"") -> 119 | X25: =IF(C25="Fix",W25,"") -> 119 | Y25: =IF(C25="Fix",X25,"") -> 119 | Z25: =IF(C25="Fix",Y25,"") -> 119 | AA25: =IF(C25="Fix",Z25,"") -> 119 | AB25: =IF(C25="Fix",AA25,"") -> 119 | AC25: =IF(C25="Fix",AB25,"") -> 119 | AD25: =IF(C25="Fix",AC25,"") -> 119 | AE25: =IF(C25="Fix",AD25,"") -> 119 | AF25: =IF(C25="Fix",AE25,"") -> 119 | AG25: =IF(C25="Fix",AF25,"") -> 119 | AH25: =IF(C25="Fix",AG25,"") -> 119 | AI25: =IF(C25="Fix",AH25,"") -> 119 | AJ25: =IF(C25="Fix",AI25,"") -> 119 | AK25: =IF(C25="Fix",AJ25,"") -> 119
A26: 17. | B26: Social Media Club | C26: Fix | D26: 37 | E26: =IF(C26="Fix",D26,"") -> 37 | F26: =IF(C26="Fix",E26,"") -> 37 | G26: =IF(C26="Fix",F26,"") -> 37 | H26: =IF(C26="Fix",G26,"") -> 37 | I26: =IF(C26="Fix",H26,"") -> 37 | J26: =IF(C26="Fix",I26,"") -> 37 | K26: =IF(C26="Fix",J26,"") -> 37 | L26: =IF(C26="Fix",K26,"") -> 37 | M26: =IF(C26="Fix",L26,"") -> 37 | N26: =IF(C26="Fix",M26,"") -> 37 | O26: =IF(C26="Fix",N26,"") -> 37 | P26: =IF(C26="Fix",O26,"") -> 37 | Q26: =IF(C26="Fix",P26,"") -> 37 | R26: =IF(C26="Fix",Q26,"") -> 37 | S26: =IF(C26="Fix",R26,"") -> 37 | T26: =IF(C26="Fix",S26,"") -> 37 | U26: =IF(C26="Fix",T26,"") -> 37 | V26: =IF(C26="Fix",U26,"") -> 37 | W26: =IF(C26="Fix",V26,"") -> 37 | X26: =IF(C26="Fix",W26,"") -> 37 | Y26: =IF(C26="Fix",X26,"") -> 37 | Z26: =IF(C26="Fix",Y26,"") -> 37 | AA26: =IF(C26="Fix",Z26,"") -> 37 | AB26: =IF(C26="Fix",AA26,"") -> 37 | AC26: =IF(C26="Fix",AB26,"") -> 37 | AD26: =IF(C26="Fix",AC26,"") -> 37 | AE26: =IF(C26="Fix",AD26,"") -> 37 | AF26: =IF(C26="Fix",AE26,"") -> 37 | AG26: =IF(C26="Fix",AF26,"") -> 37 | AH26: =IF(C26="Fix",AG26,"") -> 37 | AI26: =IF(C26="Fix",AH26,"") -> 37 | AJ26: =IF(C26="Fix",AI26,"") -> 37 | AK26: =IF(C26="Fix",AJ26,"") -> 37
A27: 17. | B27: Marketing Masterclass | C27: Fix | D27: 250 | E27: =IF(C27="Fix",D27,"") -> 250 | F27: =IF(C27="Fix",E27,"") -> 250 | G27: =IF(C27="Fix",F27,"") -> 250 | H27: =IF(C27="Fix",G27,"") -> 250 | I27: =IF(C27="Fix",H27,"") -> 250 | J27: =IF(C27="Fix",I27,"") -> 250 | K27: =IF(C27="Fix",J27,"") -> 250 | L27: =IF(C27="Fix",K27,"") -> 250 | M27: =IF(C27="Fix",L27,"") -> 250 | N27: =IF(C27="Fix",M27,"") -> 250 | O27: =IF(C27="Fix",N27,"") -> 250 | P27: =IF(C27="Fix",O27,"") -> 250 | Q27: =IF(C27="Fix",P27,"") -> 250 | R27: =IF(C27="Fix",Q27,"") -> 250 | S27: =IF(C27="Fix",R27,"") -> 250 | T27: =IF(C27="Fix",S27,"") -> 250 | U27: =IF(C27="Fix",T27,"") -> 250 | V27: =IF(C27="Fix",U27,"") -> 250 | W27: =IF(C27="Fix",V27,"") -> 250 | X27: =IF(C27="Fix",W27,"") -> 250 | Y27: =IF(C27="Fix",X27,"") -> 250 | Z27: =IF(C27="Fix",Y27,"") -> 250 | AA27: =IF(C27="Fix",Z27,"") -> 250 | AB27: =IF(C27="Fix",AA27,"") -> 250 | AC27: =IF(C27="Fix",AB27,"") -> 250 | AD27: =IF(C27="Fix",AC27,"") -> 250 | AE27: =IF(C27="Fix",AD27,"") -> 250 | AF27: =IF(C27="Fix",AE27,"") -> 250 | AG27: =IF(C27="Fix",AF27,"") -> 250 | AH27: =IF(C27="Fix",AG27,"") -> 250 | AI27: =IF(C27="Fix",AH27,"") -> 250 | AJ27: =IF(C27="Fix",AI27,"") -> 250 | AK27: =IF(C27="Fix",AJ27,"") -> 250
A28: 18. | B28: Tele 1&1 | C28: Variabel | D28: 45 | E28: =IF(C28="Fix",D28,"") | F28: =IF(C28="Fix",E28,"") | G28: =IF(C28="Fix",F28,"") | H28: =IF(C28="Fix",G28,"") | I28: =IF(C28="Fix",H28,"") | J28: =IF(C28="Fix",I28,"") | K28: =IF(C28="Fix",J28,"") | L28: =IF(C28="Fix",K28,"") | M28: =IF(C28="Fix",L28,"") | N28: =IF(C28="Fix",M28,"") | O28: =IF(C28="Fix",N28,"") | P28: =IF(C28="Fix",O28,"") | Q28: =IF(C28="Fix",P28,"") | R28: =IF(C28="Fix",Q28,"") | S28: =IF(C28="Fix",R28,"") | T28: =IF(C28="Fix",S28,"") | U28: =IF(C28="Fix",T28,"") | V28: =IF(C28="Fix",U28,"") | W28: =IF(C28="Fix",V28,"") | X28: =IF(C28="Fix",W28,"") | Y28: =IF(C28="Fix",X28,"") | Z28: =IF(C28="Fix",Y28,"") | AA28: =IF(C28="Fix",Z28,"") | AB28: =IF(C28="Fix",AA28,"") | AC28: =IF(C28="Fix",AB28,"") | AD28: =IF(C28="Fix",AC28,"") | AE28: =IF(C28="Fix",AD28,"") | AF28: =IF(C28="Fix",AE28,"") | AG28: =IF(C28="Fix",AF28,"") | AH28: =IF(C28="Fix",AG28,"") | AI28: =IF(C28="Fix",AH28,"") | AJ28: =IF(C28="Fix",AI28,"") | AK28: =IF(C28="Fix",AJ28,"")
A29: 28. | B29: LEADY | C29: Fix | D29: 630 | E29: =IF(C29="Fix",D29,"") -> 630 | F29: =IF(C29="Fix",E29,"") -> 630 | G29: =IF(C29="Fix",F29,"") -> 630 | H29: =IF(C29="Fix",G29,"") -> 630 | I29: =IF(C29="Fix",H29,"") -> 630 | J29: =IF(C29="Fix",I29,"") -> 630 | K29: =IF(C29="Fix",J29,"") -> 630 | L29: =IF(C29="Fix",K29,"") -> 630 | N29: =IF(C29="Fix",M29,"") -> 0 | O29: =IF(C29="Fix",N29,"") -> 0 | P29: =IF(C29="Fix",O29,"") -> 0 | Q29: =IF(C29="Fix",P29,"") -> 0 | R29: =IF(C29="Fix",Q29,"") -> 0 | S29: =IF(C29="Fix",R29,"") -> 0 | T29: =IF(C29="Fix",S29,"") -> 0 | U29: =IF(C29="Fix",T29,"") -> 0 | V29: =IF(C29="Fix",U29,"") -> 0 | W29: =IF(C29="Fix",V29,"") -> 0 | X29: =IF(C29="Fix",W29,"") -> 0 | Y29: =IF(C29="Fix",X29,"") -> 0 | Z29: =IF(C29="Fix",Y29,"") -> 0 | AA29: =IF(C29="Fix",Z29,"") -> 0 | AB29: =IF(C29="Fix",AA29,"") -> 0 | AC29: =IF(C29="Fix",AB29,"") -> 0 | AD29: =IF(C29="Fix",AC29,"") -> 0 | AE29: =IF(C29="Fix",AD29,"") -> 0 | AF29: =IF(C29="Fix",AE29,"") -> 0 | AG29: =IF(C29="Fix",AF29,"") -> 0 | AH29: =IF(C29="Fix",AG29,"") -> 0 | AI29: =IF(C29="Fix",AH29,"") -> 0 | AJ29: =IF(C29="Fix",AI29,"") -> 0 | AK29: =IF(C29="Fix",AJ29,"") -> 0
A30: 28. | B30: Apple | C30: Fix | D30: 10.9 | E30: =IF(C30="Fix",D30,"") -> 10.9 | F30: =IF(C30="Fix",E30,"") -> 10.9 | G30: =IF(C30="Fix",F30,"") -> 10.9 | H30: =IF(C30="Fix",G30,"") -> 10.9 | I30: =IF(C30="Fix",H30,"") -> 10.9 | J30: =IF(C30="Fix",I30,"") -> 10.9 | K30: =IF(C30="Fix",J30,"") -> 10.9 | L30: =IF(C30="Fix",K30,"") -> 10.9 | M30: =IF(C30="Fix",L30,"") -> 10.9 | N30: =IF(C30="Fix",M30,"") -> 10.9 | O30: =IF(C30="Fix",N30,"") -> 10.9 | P30: =IF(C30="Fix",O30,"") -> 10.9 | Q30: =IF(C30="Fix",P30,"") -> 10.9 | R30: =IF(C30="Fix",Q30,"") -> 10.9 | S30: =IF(C30="Fix",R30,"") -> 10.9 | T30: =IF(C30="Fix",S30,"") -> 10.9 | U30: =IF(C30="Fix",T30,"") -> 10.9 | V30: =IF(C30="Fix",U30,"") -> 10.9 | W30: =IF(C30="Fix",V30,"") -> 10.9 | X30: =IF(C30="Fix",W30,"") -> 10.9 | Y30: =IF(C30="Fix",X30,"") -> 10.9 | Z30: =IF(C30="Fix",Y30,"") -> 10.9 | AA30: =IF(C30="Fix",Z30,"") -> 10.9 | AB30: =IF(C30="Fix",AA30,"") -> 10.9 | AC30: =IF(C30="Fix",AB30,"") -> 10.9 | AD30: =IF(C30="Fix",AC30,"") -> 10.9 | AE30: =IF(C30="Fix",AD30,"") -> 10.9 | AF30: =IF(C30="Fix",AE30,"") -> 10.9 | AG30: =IF(C30="Fix",AF30,"") -> 10.9 | AH30: =IF(C30="Fix",AG30,"") -> 10.9 | AI30: =IF(C30="Fix",AH30,"") -> 10.9 | AJ30: =IF(C30="Fix",AI30,"") -> 10.9 | AK30: =IF(C30="Fix",AJ30,"") -> 10.9
A31: 25. | B31: Grover gesamt | C31: Fix | D31: 94.34 | E31: =IF(C31="Fix",D31,"") -> 94.34 | F31: =IF(C31="Fix",E31,"") -> 94.34 | G31: =IF(C31="Fix",F31,"") -> 94.34 | H31: =IF(C31="Fix",G31,"") -> 94.34 | I31: =IF(C31="Fix",H31,"") -> 94.34 | J31: =IF(C31="Fix",I31,"") -> 94.34 | K31: =IF(C31="Fix",J31,"") -> 94.34 | L31: =IF(C31="Fix",K31,"") -> 94.34 | M31: =IF(C31="Fix",L31,"") -> 94.34 | N31: =IF(C31="Fix",M31,"") -> 94.34 | O31: =IF(C31="Fix",N31,"") -> 94.34 | P31: =IF(C31="Fix",O31,"") -> 94.34 | Q31: =IF(C31="Fix",P31,"") -> 94.34 | R31: =IF(C31="Fix",Q31,"") -> 94.34 | S31: =IF(C31="Fix",R31,"") -> 94.34 | T31: =IF(C31="Fix",S31,"") -> 94.34 | U31: =IF(C31="Fix",T31,"") -> 94.34 | V31: =IF(C31="Fix",U31,"") -> 94.34 | W31: =IF(C31="Fix",V31,"") -> 94.34 | X31: =IF(C31="Fix",W31,"") -> 94.34 | Y31: =IF(C31="Fix",X31,"") -> 94.34 | Z31: =IF(C31="Fix",Y31,"") -> 94.34 | AA31: =IF(C31="Fix",Z31,"") -> 94.34 | AB31: =IF(C31="Fix",AA31,"") -> 94.34 | AC31: =IF(C31="Fix",AB31,"") -> 94.34 | AD31: =IF(C31="Fix",AC31,"") -> 94.34 | AE31: =IF(C31="Fix",AD31,"") -> 94.34 | AF31: =IF(C31="Fix",AE31,"") -> 94.34 | AG31: =IF(C31="Fix",AF31,"") -> 94.34 | AH31: =IF(C31="Fix",AG31,"") -> 94.34 | AI31: =IF(C31="Fix",AH31,"") -> 94.34 | AJ31: =IF(C31="Fix",AI31,"") -> 94.34 | AK31: =IF(C31="Fix",AJ31,"") -> 94.34
A32: 28. | B32: Claude Masterclass | C32: Fix | D32: 200 | E32: =IF(C32="Fix",D32,"") -> 200 | G32: =IF(C32="Fix",F32,"") -> 0 | H32: =IF(C32="Fix",G32,"") -> 0 | I32: =IF(C32="Fix",H32,"") -> 0 | J32: =IF(C32="Fix",I32,"") -> 0 | K32: =IF(C32="Fix",J32,"") -> 0 | L32: =IF(C32="Fix",K32,"") -> 0 | M32: =IF(C32="Fix",L32,"") -> 0 | N32: =IF(C32="Fix",M32,"") -> 0 | O32: =IF(C32="Fix",N32,"") -> 0 | P32: =IF(C32="Fix",O32,"") -> 0 | Q32: =IF(C32="Fix",P32,"") -> 0 | R32: =IF(C32="Fix",Q32,"") -> 0 | S32: =IF(C32="Fix",R32,"") -> 0 | T32: =IF(C32="Fix",S32,"") -> 0 | U32: =IF(C32="Fix",T32,"") -> 0 | V32: =IF(C32="Fix",U32,"") -> 0 | W32: =IF(C32="Fix",V32,"") -> 0 | X32: =IF(C32="Fix",W32,"") -> 0 | Y32: =IF(C32="Fix",X32,"") -> 0 | Z32: =IF(C32="Fix",Y32,"") -> 0 | AA32: =IF(C32="Fix",Z32,"") -> 0 | AB32: =IF(C32="Fix",AA32,"") -> 0 | AC32: =IF(C32="Fix",AB32,"") -> 0 | AD32: =IF(C32="Fix",AC32,"") -> 0 | AE32: =IF(C32="Fix",AD32,"") -> 0 | AF32: =IF(C32="Fix",AE32,"") -> 0 | AG32: =IF(C32="Fix",AF32,"") -> 0 | AH32: =IF(C32="Fix",AG32,"") -> 0 | AI32: =IF(C32="Fix",AH32,"") -> 0 | AJ32: =IF(C32="Fix",AI32,"") -> 0 | AK32: =IF(C32="Fix",AJ32,"") -> 0
A33: 30. | B33: SPK Kredit | C33: Fix | D33: 525 | E33: =IF(C33="Fix",D33,"") -> 525 | F33: =IF(C33="Fix",E33,"") -> 525 | G33: =IF(C33="Fix",F33,"") -> 525 | H33: =IF(C33="Fix",G33,"") -> 525 | I33: =IF(C33="Fix",H33,"") -> 525 | J33: =IF(C33="Fix",I33,"") -> 525 | K33: =IF(C33="Fix",J33,"") -> 525 | L33: =IF(C33="Fix",K33,"") -> 525 | M33: =IF(C33="Fix",L33,"") -> 525 | N33: =IF(C33="Fix",M33,"") -> 525 | O33: =IF(C33="Fix",N33,"") -> 525 | P33: =IF(C33="Fix",O33,"") -> 525 | Q33: =IF(C33="Fix",P33,"") -> 525 | R33: =IF(C33="Fix",Q33,"") -> 525 | S33: =IF(C33="Fix",R33,"") -> 525 | T33: =IF(C33="Fix",S33,"") -> 525 | U33: =IF(C33="Fix",T33,"") -> 525 | V33: =IF(C33="Fix",U33,"") -> 525 | W33: =IF(C33="Fix",V33,"") -> 525 | X33: =IF(C33="Fix",W33,"") -> 525 | Y33: =IF(C33="Fix",X33,"") -> 525 | Z33: =IF(C33="Fix",Y33,"") -> 525 | AA33: =IF(C33="Fix",Z33,"") -> 525 | AB33: =IF(C33="Fix",AA33,"") -> 525 | AC33: =IF(C33="Fix",AB33,"") -> 525 | AD33: =IF(C33="Fix",AC33,"") -> 525 | AE33: =IF(C33="Fix",AD33,"") -> 525 | AF33: =IF(C33="Fix",AE33,"") -> 525 | AG33: =IF(C33="Fix",AF33,"") -> 525 | AH33: =IF(C33="Fix",AG33,"") -> 525 | AI33: =IF(C33="Fix",AH33,"") -> 525 | AJ33: =IF(C33="Fix",AI33,"") -> 525 | AK33: =IF(C33="Fix",AJ33,"") -> 525
A34: 30. | B34: Mitarbeiter Minijob | C34: Fix | D34: 581.29 | E34: =IF(C34="Fix",D34,"") -> 581.29 | F34: =IF(C34="Fix",E34,"") -> 581.29 | G34: =IF(C34="Fix",F34,"") -> 581.29 | H34: =IF(C34="Fix",G34,"") -> 581.29 | I34: =IF(C34="Fix",H34,"") -> 581.29 | J34: =IF(C34="Fix",I34,"") -> 581.29 | K34: =IF(C34="Fix",J34,"") -> 581.29 | L34: =IF(C34="Fix",K34,"") -> 581.29 | M34: =IF(C34="Fix",L34,"") -> 581.29 | N34: =IF(C34="Fix",M34,"") -> 581.29 | O34: =IF(C34="Fix",N34,"") -> 581.29 | P34: =IF(C34="Fix",O34,"") -> 581.29 | Q34: =IF(C34="Fix",P34,"") -> 581.29 | R34: =IF(C34="Fix",Q34,"") -> 581.29 | S34: =IF(C34="Fix",R34,"") -> 581.29 | T34: =IF(C34="Fix",S34,"") -> 581.29 | U34: =IF(C34="Fix",T34,"") -> 581.29 | V34: =IF(C34="Fix",U34,"") -> 581.29 | W34: =IF(C34="Fix",V34,"") -> 581.29 | X34: =IF(C34="Fix",W34,"") -> 581.29 | Y34: =IF(C34="Fix",X34,"") -> 581.29 | Z34: =IF(C34="Fix",Y34,"") -> 581.29 | AA34: =IF(C34="Fix",Z34,"") -> 581.29 | AB34: =IF(C34="Fix",AA34,"") -> 581.29 | AC34: =IF(C34="Fix",AB34,"") -> 581.29 | AD34: =IF(C34="Fix",AC34,"") -> 581.29 | AE34: =IF(C34="Fix",AD34,"") -> 581.29 | AF34: =IF(C34="Fix",AE34,"") -> 581.29 | AG34: =IF(C34="Fix",AF34,"") -> 581.29 | AH34: =IF(C34="Fix",AG34,"") -> 581.29 | AI34: =IF(C34="Fix",AH34,"") -> 581.29 | AJ34: =IF(C34="Fix",AI34,"") -> 581.29 | AK34: =IF(C34="Fix",AJ34,"") -> 581.29
A35: 30. | B35: Sozialabgabe MA | C35: Fix | D35: 211.6 | E35: =IF(C35="Fix",D35,"") -> 211.6 | F35: =IF(C35="Fix",E35,"") -> 211.6 | G35: =IF(C35="Fix",F35,"") -> 211.6 | H35: =IF(C35="Fix",G35,"") -> 211.6 | I35: =IF(C35="Fix",H35,"") -> 211.6 | J35: =IF(C35="Fix",I35,"") -> 211.6 | K35: =IF(C35="Fix",J35,"") -> 211.6 | L35: =IF(C35="Fix",K35,"") -> 211.6 | M35: =IF(C35="Fix",L35,"") -> 211.6 | N35: =IF(C35="Fix",M35,"") -> 211.6 | O35: =IF(C35="Fix",N35,"") -> 211.6 | P35: =IF(C35="Fix",O35,"") -> 211.6 | Q35: =IF(C35="Fix",P35,"") -> 211.6 | R35: =IF(C35="Fix",Q35,"") -> 211.6 | S35: =IF(C35="Fix",R35,"") -> 211.6 | T35: =IF(C35="Fix",S35,"") -> 211.6 | U35: =IF(C35="Fix",T35,"") -> 211.6 | V35: =IF(C35="Fix",U35,"") -> 211.6 | W35: =IF(C35="Fix",V35,"") -> 211.6 | X35: =IF(C35="Fix",W35,"") -> 211.6 | Y35: =IF(C35="Fix",X35,"") -> 211.6 | Z35: =IF(C35="Fix",Y35,"") -> 211.6 | AA35: =IF(C35="Fix",Z35,"") -> 211.6 | AB35: =IF(C35="Fix",AA35,"") -> 211.6 | AC35: =IF(C35="Fix",AB35,"") -> 211.6 | AD35: =IF(C35="Fix",AC35,"") -> 211.6 | AE35: =IF(C35="Fix",AD35,"") -> 211.6 | AF35: =IF(C35="Fix",AE35,"") -> 211.6 | AG35: =IF(C35="Fix",AF35,"") -> 211.6 | AH35: =IF(C35="Fix",AG35,"") -> 211.6 | AI35: =IF(C35="Fix",AH35,"") -> 211.6 | AJ35: =IF(C35="Fix",AI35,"") -> 211.6 | AK35: =IF(C35="Fix",AJ35,"") -> 211.6
A36: 30. | B36: Miete Querweg | C36: Fix | D36: 690 | E36: =IF(C36="Fix",D36,"") -> 690 | F36: =IF(C36="Fix",E36,"") -> 690 | G36: =IF(C36="Fix",F36,"") -> 690 | H36: =IF(C36="Fix",G36,"") -> 690 | I36: =IF(C36="Fix",H36,"") -> 690 | J36: =IF(C36="Fix",I36,"") -> 690 | K36: =IF(C36="Fix",J36,"") -> 690 | L36: =IF(C36="Fix",K36,"") -> 690 | M36: =IF(C36="Fix",L36,"") -> 690 | N36: =IF(C36="Fix",M36,"") -> 690 | O36: =IF(C36="Fix",N36,"") -> 690 | P36: =IF(C36="Fix",O36,"") -> 690 | Q36: =IF(C36="Fix",P36,"") -> 690 | R36: =IF(C36="Fix",Q36,"") -> 690 | S36: =IF(C36="Fix",R36,"") -> 690 | T36: =IF(C36="Fix",S36,"") -> 690 | U36: =IF(C36="Fix",T36,"") -> 690 | V36: =IF(C36="Fix",U36,"") -> 690 | W36: =IF(C36="Fix",V36,"") -> 690 | X36: =IF(C36="Fix",W36,"") -> 690 | Y36: =IF(C36="Fix",X36,"") -> 690 | Z36: =IF(C36="Fix",Y36,"") -> 690 | AA36: =IF(C36="Fix",Z36,"") -> 690 | AB36: =IF(C36="Fix",AA36,"") -> 690 | AC36: =IF(C36="Fix",AB36,"") -> 690 | AD36: =IF(C36="Fix",AC36,"") -> 690 | AE36: =IF(C36="Fix",AD36,"") -> 690 | AF36: =IF(C36="Fix",AE36,"") -> 690 | AG36: =IF(C36="Fix",AF36,"") -> 690 | AH36: =IF(C36="Fix",AG36,"") -> 690 | AI36: =IF(C36="Fix",AH36,"") -> 690 | AJ36: =IF(C36="Fix",AI36,"") -> 690 | AK36: =IF(C36="Fix",AJ36,"") -> 690
A37: 30. | B37: Miete Lager Widukindstr. | C37: Fix | D37: 455.28 | E37: =IF(C37="Fix",D37,"") -> 455.28 | F37: =IF(C37="Fix",E37,"") -> 455.28 | G37: =IF(C37="Fix",F37,"") -> 455.28 | H37: =IF(C37="Fix",G37,"") -> 455.28 | I37: =IF(C37="Fix",H37,"") -> 455.28 | J37: =IF(C37="Fix",I37,"") -> 455.28 | K37: =IF(C37="Fix",J37,"") -> 455.28 | L37: =IF(C37="Fix",K37,"") -> 455.28 | M37: =IF(C37="Fix",L37,"") -> 455.28 | N37: =IF(C37="Fix",M37,"") -> 455.28 | O37: =IF(C37="Fix",N37,"") -> 455.28 | P37: =IF(C37="Fix",O37,"") -> 455.28 | Q37: =IF(C37="Fix",P37,"") -> 455.28 | R37: =IF(C37="Fix",Q37,"") -> 455.28 | S37: =IF(C37="Fix",R37,"") -> 455.28 | T37: =IF(C37="Fix",S37,"") -> 455.28 | U37: =IF(C37="Fix",T37,"") -> 455.28 | V37: =IF(C37="Fix",U37,"") -> 455.28 | W37: =IF(C37="Fix",V37,"") -> 455.28 | X37: =IF(C37="Fix",W37,"") -> 455.28 | Y37: =IF(C37="Fix",X37,"") -> 455.28 | Z37: =IF(C37="Fix",Y37,"") -> 455.28 | AA37: =IF(C37="Fix",Z37,"") -> 455.28 | AB37: =IF(C37="Fix",AA37,"") -> 455.28 | AC37: =IF(C37="Fix",AB37,"") -> 455.28 | AD37: =IF(C37="Fix",AC37,"") -> 455.28 | AE37: =IF(C37="Fix",AD37,"") -> 455.28 | AF37: =IF(C37="Fix",AE37,"") -> 455.28 | AG37: =IF(C37="Fix",AF37,"") -> 455.28 | AH37: =IF(C37="Fix",AG37,"") -> 455.28 | AI37: =IF(C37="Fix",AH37,"") -> 455.28 | AJ37: =IF(C37="Fix",AI37,"") -> 455.28 | AK37: =IF(C37="Fix",AJ37,"") -> 455.28
E38: =IF(C38="Fix",D38,"") | F38: =IF(C38="Fix",E38,"") | G38: =IF(C38="Fix",F38,"") | H38: =IF(C38="Fix",G38,"") | I38: =IF(C38="Fix",H38,"") | J38: =IF(C38="Fix",I38,"") | K38: =IF(C38="Fix",J38,"") | L38: =IF(C38="Fix",K38,"") | M38: =IF(C38="Fix",L38,"") | N38: =IF(C38="Fix",M38,"") | O38: =IF(C38="Fix",N38,"") | P38: =IF(C38="Fix",O38,"") | Q38: =IF(C38="Fix",P38,"") | R38: =IF(C38="Fix",Q38,"") | S38: =IF(C38="Fix",R38,"") | T38: =IF(C38="Fix",S38,"") | U38: =IF(C38="Fix",T38,"") | V38: =IF(C38="Fix",U38,"") | W38: =IF(C38="Fix",V38,"") | X38: =IF(C38="Fix",W38,"") | Y38: =IF(C38="Fix",X38,"") | Z38: =IF(C38="Fix",Y38,"") | AA38: =IF(C38="Fix",Z38,"") | AB38: =IF(C38="Fix",AA38,"") | AC38: =IF(C38="Fix",AB38,"") | AD38: =IF(C38="Fix",AC38,"") | AE38: =IF(C38="Fix",AD38,"") | AF38: =IF(C38="Fix",AE38,"") | AG38: =IF(C38="Fix",AF38,"") | AH38: =IF(C38="Fix",AG38,"") | AI38: =IF(C38="Fix",AH38,"") | AJ38: =IF(C38="Fix",AI38,"") | AK38: =IF(C38="Fix",AJ38,"")
E39: =IF(C39="Fix",D39,"") | F39: =IF(C39="Fix",E39,"") | G39: =IF(C39="Fix",F39,"") | H39: =IF(C39="Fix",G39,"") | I39: =IF(C39="Fix",H39,"") | J39: =IF(C39="Fix",I39,"") | K39: =IF(C39="Fix",J39,"") | L39: =IF(C39="Fix",K39,"") | M39: =IF(C39="Fix",L39,"") | N39: =IF(C39="Fix",M39,"") | O39: =IF(C39="Fix",N39,"") | P39: =IF(C39="Fix",O39,"") | Q39: =IF(C39="Fix",P39,"") | R39: =IF(C39="Fix",Q39,"") | S39: =IF(C39="Fix",R39,"") | T39: =IF(C39="Fix",S39,"") | U39: =IF(C39="Fix",T39,"")
A40: Summe Fixkosten | D40: =SUMIF(C5:C38,"Fix",D5:D38) -> 6066.88 | E40: =SUMIF(C5:C38,"Fix",E5:E38) -> 6066.88 | F40: =SUMIF(C5:C38,"Fix",F5:F38) -> 5596.88 | G40: =SUMIF(C5:C38,"Fix",G5:G38) -> 5596.88 | H40: =SUMIF(C5:C38,"Fix",H5:H38) -> 5596.88 | I40: =SUMIF(C5:C38,"Fix",I5:I38) -> 5596.88 | J40: =SUMIF(C5:C38,"Fix",J5:J38) -> 5596.88 | K40: =SUMIF(C5:C38,"Fix",K5:K38) -> 5596.88 | L40: =SUMIF(C5:C38,"Fix",L5:L38) -> 5596.88 | M40: =SUMIF(C5:C38,"Fix",M5:M38) -> 4966.88 | N40: =SUMIF(C5:C38,"Fix",N5:N38) -> 4966.88 | O40: =SUMIF(C5:C38,"Fix",O5:O38) -> 4966.88 | P40: =SUMIF(C5:C38,"Fix",P5:P38) -> 4966.88 | Q40: =SUMIF(C5:C38,"Fix",Q5:Q38) -> 4966.88 | R40: =SUMIF(C5:C38,"Fix",R5:R38) -> 4966.88 | S40: =SUMIF(C5:C38,"Fix",S5:S38) -> 4966.88 | T40: =SUMIF(C5:C38,"Fix",T5:T38) -> 4966.88 | U40: =SUMIF(C5:C38,"Fix",U5:U38) -> 4966.88 | V40: =SUMIF(C5:C38,"Fix",V5:V38) -> 4966.88 | W40: =SUMIF(C5:C38,"Fix",W5:W38) -> 4966.88 | X40: =SUMIF(C5:C38,"Fix",X5:X38) -> 4966.88 | Y40: =SUMIF(C5:C38,"Fix",Y5:Y38) -> 4966.88 | Z40: =SUMIF(C5:C38,"Fix",Z5:Z38) -> 4966.88 | AA40: =SUMIF(C5:C38,"Fix",AA5:AA38) -> 4966.88 | AB40: =SUMIF(C5:C38,"Fix",AB5:AB38) -> 4966.88 | AC40: =SUMIF(C5:C38,"Fix",AC5:AC38) -> 4966.88 | AD40: =SUMIF(C5:C38,"Fix",AD5:AD38) -> 4966.88 | AE40: =SUMIF(C5:C38,"Fix",AE5:AE38) -> 4966.88 | AF40: =SUMIF(C5:C38,"Fix",AF5:AF38) -> 4966.88 | AG40: =SUMIF(C5:C38,"Fix",AG5:AG38) -> 4966.88 | AH40: =SUMIF(C5:C38,"Fix",AH5:AH38) -> 4966.88 | AI40: =SUMIF(C5:C38,"Fix",AI5:AI38) -> 4966.88 | AJ40: =SUMIF(C5:C38,"Fix",AJ5:AJ38) -> 4966.88 | AK40: =SUMIF(C5:C38,"Fix",AK5:AK38) -> 4966.88
A41: Summe Variable Kosten | D41: =SUMIF(C5:C38,"Variabel",D5:D38) -> 2365 | E41: =SUMIF(C5:C38,"Variabel",E5:E38) -> 0 | F41: =SUMIF(C5:C38,"Variabel",F5:F38) -> 0 | G41: =SUMIF(C5:C38,"Variabel",G5:G38) -> 0 | H41: =SUMIF(C5:C38,"Variabel",H5:H38) -> 0 | I41: =SUMIF(C5:C38,"Variabel",I5:I38) -> 0 | J41: =SUMIF(C5:C38,"Variabel",J5:J38) -> 0 | K41: =SUMIF(C5:C38,"Variabel",K5:K38) -> 0 | L41: =SUMIF(C5:C38,"Variabel",L5:L38) -> 0 | M41: =SUMIF(C5:C38,"Variabel",M5:M38) -> 0 | N41: =SUMIF(C5:C38,"Variabel",N5:N38) -> 0 | O41: =SUMIF(C5:C38,"Variabel",O5:O38) -> 0 | P41: =SUMIF(C5:C38,"Variabel",P5:P38) -> 0 | Q41: =SUMIF(C5:C38,"Variabel",Q5:Q38) -> 0 | R41: =SUMIF(C5:C38,"Variabel",R5:R38) -> 0 | S41: =SUMIF(C5:C38,"Variabel",S5:S38) -> 0 | T41: =SUMIF(C5:C38,"Variabel",T5:T38) -> 0 | U41: =SUMIF(C5:C38,"Variabel",U5:U38) -> 0 | V41: =SUMIF(C5:C38,"Variabel",V5:V38) -> 0 | W41: =SUMIF(C5:C38,"Variabel",W5:W38) -> 0 | X41: =SUMIF(C5:C38,"Variabel",X5:X38) -> 0 | Y41: =SUMIF(C5:C38,"Variabel",Y5:Y38) -> 0 | Z41: =SUMIF(C5:C38,"Variabel",Z5:Z38) -> 0 | AA41: =SUMIF(C5:C38,"Variabel",AA5:AA38) -> 0 | AB41: =SUMIF(C5:C38,"Variabel",AB5:AB38) -> 0 | AC41: =SUMIF(C5:C38,"Variabel",AC5:AC38) -> 0 | AD41: =SUMIF(C5:C38,"Variabel",AD5:AD38) -> 0 | AE41: =SUMIF(C5:C38,"Variabel",AE5:AE38) -> 0 | AF41: =SUMIF(C5:C38,"Variabel",AF5:AF38) -> 0 | AG41: =SUMIF(C5:C38,"Variabel",AG5:AG38) -> 0 | AH41: =SUMIF(C5:C38,"Variabel",AH5:AH38) -> 0 | AI41: =SUMIF(C5:C38,"Variabel",AI5:AI38) -> 0 | AJ41: =SUMIF(C5:C38,"Variabel",AJ5:AJ38) -> 0 | AK41: =SUMIF(C5:C38,"Variabel",AK5:AK38) -> 0
A42: Gesamtsumme | D42: =D40+D41 -> 8431.88 | E42: =E40+E41 -> 6066.88 | F42: =F40+F41 -> 5596.88 | G42: =G40+G41 -> 5596.88 | H42: =H40+H41 -> 5596.88 | I42: =I40+I41 -> 5596.88 | J42: =J40+J41 -> 5596.88 | K42: =K40+K41 -> 5596.88 | ... AK42: =AK40+AK41 -> 4966.88

Sheet Zahltag-Übersicht
A1: Zahltag-Übersicht: Fixkosten & Ausgaben nebeneinander
A2: Fixkosten werden automatisch übernommen (Monat oben einstellen). Trage bei 'Ausgaben' Name + Betrag ein. Um einen Ausgaben-Posten zu entfernen ohne ihn zu löschen: Spalte 'Ausgabe zählt?' auf 'Nein' setzen — der Posten wird durchgestrichen dargestellt und aus der Summe unten herausgerechnet.
A3: Aktueller Monat (Nummer, 1-34): | D3: 1 | E3: ="→ "&INDEX('Fixkosten-Variable Kosten'!$D$4:$AK$4,1,$D$3) -> → Monat 1 | G3: Monat 2
A5: Tag | B5: Name (Fix) | C5: Fix (€) | D5: Name (Ausgaben) | E5: Ausgaben (€) | F5: Ausgabe zählt?
A6: =VALUE(SUBSTITUTE(TRIM('Fixkosten-Variable Kosten'!A5),".","")) -> 1 | B6: ='Fixkosten-Variable Kosten'!B5 -> Claude Code | C6: =INDEX('Fixkosten-Variable Kosten'!$D5:$AK5,1,$D$3) -> 17.99 | D6: DHL | E6: 7.83
A7: 1 | D7: DHL | E7: 9.46
A8: 1 | D8: Prisma | E8: 1040.61
A9: =VALUE(SUBSTITUTE(TRIM('Fixkosten-Variable Kosten'!A6),".","")) -> 2 | B9: ='Fixkosten-Variable Kosten'!B6 -> Rechtsschutz | C9: =INDEX('Fixkosten-Variable Kosten'!$D6:$AK6,1,$D$3) -> 68.65 | D9: Swandoo | E9: 307.62
A10: =VALUE(SUBSTITUTE(TRIM('Fixkosten-Variable Kosten'!A7),".","")) -> 2 | B10: ='Fixkosten-Variable Kosten'!B7 -> Grover | C10: =INDEX('Fixkosten-Variable Kosten'!$D7:$AK7,1,$D$3) -> 24.9 | D10: Avio | E10: 997.84
A11: 2 | D11: minime | E11: 371.88
A12: 2 | F12: Ja
A13: =VALUE(SUBSTITUTE(TRIM('Fixkosten-Variable Kosten'!A8),".","")) -> 3 | B13: ='Fixkosten-Variable Kosten'!B8 -> Vers. Leasing | C13: =INDEX('Fixkosten-Variable Kosten'!$D8:$AK8,1,$D$3) -> 24.9 | F13: Ja
A14: =VALUE(SUBSTITUTE(TRIM('Fixkosten-Variable Kosten'!A9),".","")) -> 3 | B14: ='Fixkosten-Variable Kosten'!B9 -> Taxi Werbung | C14: =INDEX('Fixkosten-Variable Kosten'!$D9:$AK9,1,$D$3) -> 202.42 | F14: Ja
A15: 3 | F15: Ja
A16: 3 | F16: Ja
A17: =VALUE(SUBSTITUTE(TRIM('Fixkosten-Variable Kosten'!A10),".","")) -> 4 | B17: ='Fixkosten-Variable Kosten'!B10 -> IT Recht | C17: =INDEX('Fixkosten-Variable Kosten'!$D10:$AK10,1,$D$3) -> 11.78 | F17: Ja
A18: 4 | F18: Ja
A19: 4 | F19: Ja
A20: =VALUE(SUBSTITUTE(TRIM('Fixkosten-Variable Kosten'!A11),".","")) -> 5 | B20: ='Fixkosten-Variable Kosten'!B11 -> Apple Cloud | C20: =INDEX('Fixkosten-Variable Kosten'!$D11:$AK11,1,$D$3) -> 19.99 | F20: Ja
A21: =VALUE(SUBSTITUTE(TRIM('Fixkosten-Variable Kosten'!A12),".","")) -> 5 | B21: ='Fixkosten-Variable Kosten'!B12 -> SPK Kontoführung | C21: =INDEX('Fixkosten-Variable Kosten'!$D12:$AK12,1,$D$3) -> 70 | F21: Ja
A22: 5 | F22: Ja
A23: 5 | F23: Ja
A24: =VALUE(SUBSTITUTE(TRIM('Fixkosten-Variable Kosten'!A13),".","")) -> 6 | B24: ='Fixkosten-Variable Kosten'!B13 -> Impuls Coach | C24: =INDEX('Fixkosten-Variable Kosten'!$D13:$AK13,1,$D$3) -> 250 | F24: Ja
A25: =VALUE(SUBSTITUTE(TRIM('Fixkosten-Variable Kosten'!A14),".","")) -> 6 | B25: ='Fixkosten-Variable Kosten'!B14 -> Strom | C25: =INDEX('Fixkosten-Variable Kosten'!$D14:$AK14,1,$D$3) -> 47 | F25: Ja
A26: =VALUE(SUBSTITUTE(TRIM('Fixkosten-Variable Kosten'!A15),".","")) -> 6 | B26: ='Fixkosten-Variable Kosten'!B15 -> Lexoffice | C26: =INDEX('Fixkosten-Variable Kosten'!$D15:$AK15,1,$D$3) -> 14.16 | F26: Ja
A27: =VALUE(SUBSTITUTE(TRIM('Fixkosten-Variable Kosten'!A16),".","")) -> 6 | B27: ='Fixkosten-Variable Kosten'!B16 -> Website | C27: =INDEX('Fixkosten-Variable Kosten'!$D16:$AK16,1,$D$3) -> 629.51 | F27: Ja
A28: =VALUE(SUBSTITUTE(TRIM('Fixkosten-Variable Kosten'!A17),".","")) -> 6 | B28: ='Fixkosten-Variable Kosten'!B17 -> Auto Leasing | C28: =INDEX('Fixkosten-Variable Kosten'!$D17:$AK17,1,$D$3) -> 453.15 | F28: Ja
A29: 6 | F29: Ja
A30: 6 | F30: Ja
A31: =VALUE(SUBSTITUTE(TRIM('Fixkosten-Variable Kosten'!A18),".","")) -> 11 | B31: ='Fixkosten-Variable Kosten'!B18 -> Versicherung Laden | C31: =INDEX('Fixkosten-Variable Kosten'!$D18:$AK18,1,$D$3) -> 51.67 | D31: Joie | E31: 301.5
A32: 11 | B32: EC Gebühren | C32: 120 | D32: Avio | E32: 272.24
A33: 11 | D33: Avio | E33: 878.4 | F33: Ja
A34: =VALUE(SUBSTITUTE(TRIM('Fixkosten-Variable Kosten'!A20),".","")) -> 14 | B34: ='Fixkosten-Variable Kosten'!B20 -> Identity Shift | C34: =INDEX('Fixkosten-Variable Kosten'!$D20:$AK20,1,$D$3) -> 270 | D34: Joie | E34: 539.97 | F34: Ja
A35: 14 | B35: Umsatzsteuer | C35: 802.91 | D35: Joie | E35: 301.5 | F35: Ja
A36: 14 | F36: Ja
A37: =VALUE(SUBSTITUTE(TRIM('Fixkosten-Variable Kosten'!A22),".","")) -> 15 | B37: ='Fixkosten-Variable Kosten'!B22 -> SenVend | C37: =INDEX('Fixkosten-Variable Kosten'!$D22:$AK22,1,$D$3) -> 16.36 | F37: Ja
A38: =VALUE(SUBSTITUTE(TRIM('Fixkosten-Variable Kosten'!A23),".","")) -> 15 | B38: ='Fixkosten-Variable Kosten'!B23 -> Terminland | C38: =INDEX('Fixkosten-Variable Kosten'!$D23:$AK23,1,$D$3) -> 19.99 | F38: Ja
A39: =VALUE(SUBSTITUTE(TRIM('Fixkosten-Variable Kosten'!A24),".","")) -> 15 | B39: ='Fixkosten-Variable Kosten'!B24 -> Miete Automat | C39: =INDEX('Fixkosten-Variable Kosten'!$D24:$AK24,1,$D$3) -> 70 | F39: Ja
A40: =VALUE(SUBSTITUTE(TRIM('Fixkosten-Variable Kosten'!A25),".","")) -> 15 | B40: ='Fixkosten-Variable Kosten'!B25 -> Steuerberater | C40: =INDEX('Fixkosten-Variable Kosten'!$D25:$AK25,1,$D$3) -> 119 | F40: Ja
A41: 15 | F41: Ja
...
