Workbook

Sheet Babyschalen
A1: Margenberechnung Verbund (Stand: 27.05.2024)
A2: Babyschalen
A3: Sitz/Variante | B3: VK Brutto | C3: VK netto | D3: EK netto regulär | E3: EK netto | F3: Zuschlag | G3: Gewinn | H3: Gewinn nach Skonto | I3: Marge [%] | J3: Marge [%] nach Skonto | K3: Rabatt(+)/ Zuschlag(-) | L3: Skonto
A5: Avionaut
A6: Cosmo | B6: 184 | C6: =B6/119*100 -> 154.62185 | D6: 119 | E6: =D6-K6*D6 -> 95.2 | F6: =C6/E6 -> 1.6241791 | G6: =C6-E6 -> 59.421849 | H6: =C6-E6*(1-L6) -> 59.421849 | I6: =G6/C6 -> 0.38430435 | J6: =H6/C6 -> 0.38430435 | K6: ='eigene Konditionen'!B$3 -> 0.2 | L6: ='eigene Konditionen'!C$3 -> 0
A7: Pixel Pro2.0 C | B7: 279 | C7: =B7/119*100 -> 234.45378 | D7: 168 | E7: =D7-K7*D7 -> 134.4 | F7: =C7/E7 -> 1.7444478 | G7: =C7-E7 -> 100.05378 | H7: =C7-E7*(1-L7) -> 100.05378 | I7: =G7/C7 -> 0.42675269 | J7: =H7/C7 -> 0.42675269 | K7: ='eigene Konditionen'!B$3 -> 0.2 | L7: ='eigene Konditionen'!C$3 -> 0
A8: Base IQ | B8: 199 | C8: =B8/119*100 -> 167.22689 | D8: 152 | E8: =D8-K8*D8 -> 121.6 | F8: =C8/E8 -> 1.3752211 | G8: =C8-E8 -> 45.626891 | H8: =C8-E8*(1-L8) -> 45.626891 | I8: =G8/C8 -> 0.27284422 | J8: =H8/C8 -> 0.27284422 | K8: ='eigene Konditionen'!B$3 -> 0.2 | L8: ='eigene Konditionen'!C$3 -> 0
A9: BeSafe
A10: Go Beyond | B10: 389 | C10: =B10/119*100 -> 326.89076 | D10: 204 | E10: =D10-K10*D10 -> 205.02 | F10: =C10/E10 -> 1.5944335 | G10: =C10-E10 -> 121.87076 | H10: =C10-E10*(1-L10) -> 121.87076 | I10: =G10/C10 -> 0.37281799 | J10: =H10/C10 -> 0.37281799 | K10: ='eigene Konditionen'!B$6 -> -0.005 | L10: ='eigene Konditionen'!C$6 -> 0
A11: Go Beyond Mesh | B11: 409 | C11: =B11/119*100 -> 343.69748 | D11: 212
A12: Go Modular X2 | B12: 239 | C12: =B12/119*100 -> 200.84034 | D12: 115 | E12: =D12-K12*D12 -> 115.575 | F12: =C12/E12 -> 1.737749 | G12: =C12-E12 -> 85.265336 | H12: =C12-E12*(1-L12) -> 85.265336 | I12: =G12/C12 -> 0.42454289 | J12: =H12/C12 -> 0.42454289 | K12: ='eigene Konditionen'!B$6 -> -0.005 | L12: ='eigene Konditionen'!C$6 -> 0
A13: Go Modular X2 Mesh | B13: 259 | C13: =B13/119*100 -> 217.64706 | D13: 125 | E13: =D13-K13*D13 -> 125.625 | F13: =C13/E13 -> 1.7325139 | G13: =C13-E13 -> 92.022059 | H13: =C13-E13*(1-L13) -> 92.022059 | I13: =G13/C13 -> 0.42280405 | J13: =H13/C13 -> 0.42280405 | K13: ='eigene Konditionen'!B$6 -> -0.005 | L13: ='eigene Konditionen'!C$6 -> 0
A14: Beyond Base | B14: 289 | C14: =B14/119*100 -> 242.85714 | D14: 152 | E14: =D14-K14*D14 -> 152.76 | F14: =C14/E14 -> 1.5897954 | G14: =C14-E14 -> 90.097143 | H14: =C14-E14*(1-L14) -> 90.097143 | I14: =G14/C14 -> 0.37098824 | J14: =H14/C14 -> 0.37098824 | K14: ='eigene Konditionen'!B$6 -> -0.005 | L14: ='eigene Konditionen'!C$6 -> 0
A15: Modular i-Size Base | B15: 199 | C15: =B15/119*100 -> 167.22689 | D15: 105 | E15: =D15-K15*D15 -> 105.525 | F15: =C15/E15 -> 1.5847135 | G15: =C15-E15 -> 61.701891 | H15: =C15-E15*(1-L15) -> 61.701891 | I15: =G15/C15 -> 0.36897111 | J15: =H15/C15 -> 0.36897111 | K15: ='eigene Konditionen'!B$6 -> -0.005 | L15: ='eigene Konditionen'!C$6 -> 0
A16: Britax Römer
A17: Baby-Safe 3 i-Size Standard | B17: 259.9 | C17: =B17/119*100 -> 218.40336 | D17: 200 | E17: =D17-K17*D17 -> 146 | F17: =C17/E17 -> 1.4959134 | G17: =C17-E17 -> 72.403361 | H17: =C17-E17*(1-L17) -> 76.783361 | I17: =G17/C17 -> 0.33151212 | J17: =H17/C17 -> 0.35156676 | K17: ='eigene Konditionen'!B$7 -> 0.27 | L17: ='eigene Konditionen'!C$7 -> 0.03
A18: Baby-Safe 3 i-Size Marble | B18: 289.9 | C18: =B18/119*100 -> 243.61345 | D18: 225.21 | E18: =D18-K18*D18 -> 164.4033 | F18: =C18/E18 -> 1.4818039 | G18: =C18-E18 -> 79.210145 | H18: =C18-E18*(1-L18) -> 84.142244 | I18: =G18/C18 -> 0.32514685 | J18: =H18/C18 -> 0.34539245 | K18: ='eigene Konditionen'!B$7 -> 0.27 | L18: ='eigene Konditionen'!C$7 -> 0.03
A19: Babysafe 3 i-size & Vario 5Z | B19: 479 | C19: =B19/119*100 -> 402.52101 | D19: 380 | E19: =D19-K19*D19 -> 277.4 | F19: =C19/E19 -> 1.4510491 | G19: =C19-E19 -> 125.12101 | H19: =C19-E19*(1-L19) -> 133.44301 | I19: =G19/C19 -> 0.31084342 | J19: =H19/C19 -> 0.33151812 | K19: ='eigene Konditionen'!B$7 -> 0.27 | L19: ='eigene Konditionen'!C$7 -> 0.03
A20: Vario Base 5Z | B20: 259.9 | C20: =B20/119*100 -> 218.40336 | D20: 225 | E20: =D20-K20*D20 -> 164.25 | F20: =C20/E20 -> 1.3297008 | G20: =C20-E20 -> 54.153361 | H20: =C20-E20*(1-L20) -> 59.080861 | I20: =G20/C20 -> 0.24795114 | J20: =H20/C20 -> 0.2705126 | K20: ='eigene Konditionen'!B$7 -> 0.27 | L20: ='eigene Konditionen'!C$7 -> 0.03
A21: Flex Base 5Z | B21: 259.9 | C21: =B21/119*100 -> 218.40336 | D21: 225 | E21: =D21-K21*D21 -> 164.25 | F21: =C21/E21 -> 1.3297008 | G21: =C21-E21 -> 54.153361 | H21: =C21-E21*(1-L21) -> 59.080861 | I21: =G21/C21 -> 0.24795114 | J21: =H21/C21 -> 0.2705126 | K21: ='eigene Konditionen'!B$7 -> 0.27 | L21: ='eigene Konditionen'!C$7 -> 0.03
A22: Cybex
A23: Cloud T i-size | B23: 249.95 | C23: =B23/119*100 -> 210.04202 | D23: 151.3 | E23: =D23-K23*D23 -> 151.3 | F23: =C23/E23 -> 1.3882486 | G23: =C23-E23 -> 58.742017 | H23: =C23-E23*(1-L23) -> 63.281017 | I23: =G23/C23 -> 0.27966793 | J23: =H23/C23 -> 0.3012779 | K23: ='eigene Konditionen'!B$9 -> 0 | L23: ='eigene Konditionen'!C$9 -> 0.03
A24: Cloud T i-size Plus | B24: 279.95 | C24: =B24/119*100 -> 235.2521 | D24: 169 | E24: =D24-K24*D24 -> 169 | F24: =C24/E24 -> 1.3920243 | G24: =C24-E24 -> 66.252101 | H24: =C24-E24*(1-L24) -> 71.322101 | I24: =G24/C24 -> 0.28162172 | J24: =H24/C24 -> 0.30317307 | K24: ='eigene Konditionen'!B$9 -> 0 | L24: ='eigene Konditionen'!C$9 -> 0.03
A25: Base T | B25: 249.95 | C25: =B25/119*100 -> 210.04202 | D25: 160.6 | E25: =D25-K25*D25 -> 160.6 | F25: =C25/E25 -> 1.3078581 | G25: =C25-E25 -> 49.442017 | H25: =C25-E25*(1-L25) -> 54.260017 | I25: =G25/C25 -> 0.23539108 | J25: =H25/C25 -> 0.25832935 | K25: ='eigene Konditionen'!B$9 -> 0 | L25: ='eigene Konditionen'!C$9 -> 0.03
A26: Joie i-Snug 2 | B26: 119.95 | C26: =B26/119*100 -> 100.79832 | D26: 72.7 | E26: =D26-K26*D26 -> 72.7 | F26: =C26/E26 -> 1.3864968 | G26: =C26-E26 -> 28.098319 | H26: =C26-E26*(1-L26) -> 31.733319 | I26: =G26/C26 -> 0.27875782 | J26: =H26/C26 -> 0.31481992 | K26: ='eigene Konditionen'!B$9 -> 0 | L26: ='eigene Konditionen'!C$11 -> 0.05
A27: Kiddy Evoluna i-Size 2 | B27: 399 | C27: =B27/119*100 -> 335.29412 | D27: 309 | E27: =D27-K27*D27 -> 309 | F27: =C27/E27 -> 1.0850942 | G27: =C27-E27 -> 26.294118 | H27: =C27-E27*(1-L27) -> 35.564118 | I27: =G27/C27 -> 0.078421053 | J27: =H27/C27 -> 0.10606842 | K27: ='eigene Konditionen'!B$9 -> 0 | L27: ='eigene Konditionen'!C$9 -> 0.03
A28: Maxi Cosi
A29: Coral 360 | B29: 349.99 | C29: =B29/119*100 -> 294.10924 | D29: 289.19 | E29: =D29-K29*D29 -> 198.09515 | F29: =C29/E29 -> 1.4846867 | G29: =C29-E29 -> 96.014094 | H29: =C29-E29*(1-L29) -> 96.014094 | I29: =G29/C29 -> 0.32645725 | J29: =H29/C29 -> 0.32645725 | K29: ='eigene Konditionen'!B$14 -> 0.315 | L29: ='eigene Konditionen'!C$14 -> 0
A30: Jade | B30: 269.99 | C30: =B30/119*100 -> 226.88235 | D30: 223.09 | E30: =D30-K30*D30 -> 152.81665 | F30: =C30/E30 -> 1.4846704 | G30: =C30-E30 -> 74.065703 | H30: =C30-E30*(1-L30) -> 74.065703 | I30: =G30/C30 -> 0.32644982 | J30: =H30/C30 -> 0.32644982 | K30: ='eigene Konditionen'!B$14 -> 0.315 | L30: ='eigene Konditionen'!C$14 -> 0
A31: Pebble 360 | B31: 229.99 | C31: =B31/119*100 -> 193.26891 | D31: 190.09 | E31: =D31-K31*D31 -> 130.21165 | F31: =C31/E31 -> 1.4842674 | G31: =C31-E31 -> 63.057258 | H31: =C31-E31*(1-L31) -> 63.057258 | I31: =G31/C31 -> 0.32626695 | J31: =H31/C31 -> 0.32626695 | K31: ='eigene Konditionen'!B$14 -> 0.315 | L31: ='eigene Konditionen'!C$14 -> 0
A32: Pebble 360 Luxe | B32: 249.99 | C32: =B32/119*100 -> 210.07563 | D32: 206.59 | E32: =D32-K32*D32 -> 141.51415 | F32: =C32/E32 -> 1.484485 | G32: =C32-E32 -> 68.56148 | H32: =C32-E32*(1-L32) -> 68.56148 | I32: =G32/C32 -> 0.3263657 | J32: =H32/C32 -> 0.3263657 | K32: ='eigene Konditionen'!B$14 -> 0.315 | L32: ='eigene Konditionen'!C$14 -> 0
A33: Pebble 360 Pro2 | B33: 299.99 | C33: =B33/119*100 -> 252.09244 | D33: 247.89 | E33: =D33-K33*D33 -> 169.80465 | F33: =C33/E33 -> 1.4846027 | G33: =C33-E33 -> 82.287787 | H33: =C33-E33*(1-L33) -> 82.287787 | I33: =G33/C33 -> 0.3264191 | J33: =H33/C33 -> 0.3264191 | K33: ='eigene Konditionen'!B$14 -> 0.315 | L33: ='eigene Konditionen'!C$14 -> 0
A34: Pebble 360 Pro2 Twillic | B34: 319.99 | C34: =B34/119*100 -> 268.89916 | D34: 264.49 | E34: =D34-K34*D34 -> 181.17565 | F34: =C34/E34 -> 1.4841904 | G34: =C34-E34 -> 87.72351 | H34: =C34-E34*(1-L34) -> 87.72351 | I34: =G34/C34 -> 0.326232 | J34: =H34/C34 -> 0.326232 | K34: ='eigene Konditionen'!B$14 -> 0.315 | L34: ='eigene Konditionen'!C$14 -> 0
A35: Pebble Pro i-Size | B35: 199.99 | C35: =B35/119*100 -> 168.05882 | D35: 165.29 | E35: =D35-K35*D35 -> 113.22365 | F35: =C35/E35 -> 1.4843085 | G35: =C35-E35 -> 54.835174 | H35: =C35-E35*(1-L35) -> 54.835174 | I35: =G35/C35 -> 0.3262856 | J35: =H35/C35 -> 0.3262856 | K35: ='eigene Konditionen'!B$14 -> 0.315 | L35: ='eigene Konditionen'!C$14 -> 0
A36: FamilyFix 3 | B36: 189.99 | C36: =B36/119*100 -> 159.65546 | D36: 156.99 | E36: =D36-K36*D36 -> 107.53815 | F36: =C36/E36 -> 1.4846402 | G36: =C36-E36 -> 52.117312 | H36: =C36-E36*(1-L36) -> 52.117312 | I36: =G36/C36 -> 0.32643614 | J36: =H36/C36 -> 0.32643614 | K36: ='eigene Konditionen'!B$14 -> 0.315 | L36: ='eigene Konditionen'!C$14 -> 0
A37: FamilyFix 360 | B37: 219.99 | C37: =B37/119*100 -> 184.86555 | D37: 181.79 | E37: =D37-K37*D37 -> 124.52615 | F37: =C37/E37 -> 1.484552 | G37: =C37-E37 -> 60.339396 | H37: =C37-E37*(1-L37) -> 60.339396 | I37: =G37/C37 -> 0.32639612 | J37: =H37/C37 -> 0.32639612 | K37: ='eigene Konditionen'!B$14 -> 0.315 | L37: ='eigene Konditionen'!C$14 -> 0
A38: nuna
A39: Arra next | B39: 279.95 | C39: =B39/119*100 -> 235.2521 | D39: 155.95 | E39: =D39-K39*D39 -> 148.1525 | F39: =C39/E39 -> 1.587905 | G39: =C39-E39 -> 87.099601 | H39: =C39-E39*(1-L39) -> 94.507226 | I39: =G39/C39 -> 0.37023942 | J39: =H39/C39 -> 0.40172745 | K39: ='eigene Konditionen'!B$16 -> 0.05 | L39: ='eigene Konditionen'!C$16 -> 0.05
A40: Base next | B40: 219.95 | C40: =B40/119*100 -> 184.83193 | D40: 121.95 | E40: =D40-K40*D40 -> 115.8525 | F40: =C40/E40 -> 1.5954074 | G40: =C40-E40 -> 68.979433 | H40: =C40-E40*(1-L40) -> 74.772058 | I40: =G40/C40 -> 0.37320084 | J40: =H40/C40 -> 0.4045408 | K40: ='eigene Konditionen'!B$16 -> 0.05 | L40: ='eigene Konditionen'!C$16 -> 0.05
A41: Swandoo
...

Sheet Reboarder
A1: Margenberechnung Verbund (Stand: 27.05.2024)
A2: Reboarder
A3: Sitz/Variante | B3: VK Brutto | C3: VK netto | D3: EK netto regulär | E3: EK netto | F3: Zuschlag | G3: Gewinn | H3: Gewinn nach Skonto | I3: Marge [%] | J3: Marge [%] nach Skonto | K3: Rabatt(+)/ Zuschlag(-) | L3: Skonto
A5: Avionaut
A6: AeroFIX 2.0 C | B6: 329 | C6: =B6/119*100 -> 276.47059 | D6: 195 | E6: =D6-K6*D6 -> 156 | F6: =C6/E6 -> 1.7722474 | G6: =C6-E6 -> 120.47059 | H6: =C6-E6*(1-L6) -> 120.47059 | I6: =G6/C6 -> 0.43574468 | J6: =H6/C6 -> 0.43574468 | K6: ='eigene Konditionen'!B$3 -> 0.2 | L6: ='eigene Konditionen'!C$3 -> 0
A7: AeroFIX RWF 2.0 C | B7: 329 | C7: =B7/119*100 -> 276.47059 | D7: 195 | E7: =D7-K7*D7 -> 156 | F7: =C7/E7 -> 1.7722474 | G7: =C7-E7 -> 120.47059 | H7: =C7-E7*(1-L7) -> 120.47059 | I7: =G7/C7 -> 0.43574468 | J7: =H7/C7 -> 0.43574468 | K7: ='eigene Konditionen'!B$3 -> 0.2 | L7: ='eigene Konditionen'!C$3 -> 0
A8: Sky 2.0 | B8: 439 | C8: =B8/119*100 -> 368.90756 | D8: 265 | E8: =D8-K8*D8 -> 212 | F8: =C8/E8 -> 1.74013 | G8: =C8-E8 -> 156.90756 | H8: =C8-E8*(1-L8) -> 156.90756 | I8: =G8/C8 -> 0.4253303 | J8: =H8/C8 -> 0.4253303 | K8: ='eigene Konditionen'!B$3 -> 0.2 | L8: ='eigene Konditionen'!C$3 -> 0
A9: Avova
A10: Sperber-Fix Grey & Black | B10: 499.95 | C10: =B10/119*100 -> 420.12605 | D10: 269 | E10: =D10-K10*D10 -> 269 | F10: =C10/E10 -> 1.5618069 | G10: =C10-E10 -> 151.12605 | H10: =C10-E10*(1-L10) -> 159.19605 | I10: =G10/C10 -> 0.35971597 | J10: =H10/C10 -> 0.37892449 | K10: ='eigene Konditionen'!B$4 -> 0 | L10: ='eigene Konditionen'!C$4 -> 0.03
A11: Sperber-Fix i-Size alle anderen | B11: 489.95 | C11: =B11/119*100 -> 411.72269 | D11: 264 | E11: =D11-K11*D11 -> 264 | F11: =C11/E11 -> 1.5595556 | G11: =C11-E11 -> 147.72269 | H11: =C11-E11*(1-L11) -> 155.64269 | I11: =G11/C11 -> 0.35879171 | J11: =H11/C11 -> 0.37802796 | K11: ='eigene Konditionen'!B$4 -> 0 | L11: ='eigene Konditionen'!C$4 -> 0.03
A12: Sperber-Fix 61 Grey & Black | B12: 479.95 | C12: =B12/119*100 -> 403.31933 | D12: 259 | E12: =D12-K12*D12 -> 259 | F12: =C12/E12 -> 1.5572175 | G12: =C12-E12 -> 144.31933 | H12: =C12-E12*(1-L12) -> 152.08933 | I12: =G12/C12 -> 0.35782894 | J12: =H12/C12 -> 0.37709407 | K12: ='eigene Konditionen'!B$4 -> 0 | L12: ='eigene Konditionen'!C$4 -> 0.03
A13: Sperber-Fix 61 alle anderen | B13: 469.95 | C13: =B13/119*100 -> 394.91597 | D13: 254 | E13: =D13-K13*D13 -> 254 | F13: =C13/E13 -> 1.5547873 | G13: =C13-E13 -> 140.91597 | H13: =C13-E13*(1-L13) -> 148.53597 | I13: =G13/C13 -> 0.35682519 | J13: =H13/C13 -> 0.37612044 | K13: ='eigene Konditionen'!B$4 -> 0 | L13: ='eigene Konditionen'!C$4 -> 0.03
A14: Axkid
A15: Minikid 2 (bis 5 Stück) | B15: 299.9 | C15: =B15/119*100 -> 252.01681 | D15: 190 | E15: =D15-K15*D15 -> 190 | F15: =C15/E15 -> 1.3264042 | G15: =C15-E15 -> 62.016807 | H15: =C15-E15*(1-L15) -> 65.816807 | I15: =G15/C15 -> 0.24608203 | J15: =H15/C15 -> 0.26116039 | K15: ='eigene Konditionen'!B$5 -> 0 | L15: ='eigene Konditionen'!C$5 -> 0.02
A16: Minikid 2 (ab 6 Stück) | B16: 299.9 | C16: =B16/119*100 -> 252.01681 | D16: 175 | E16: =D16-K16*D16 -> 175 | F16: =C16/E16 -> 1.440096 | G16: =C16-E16 -> 77.016807 | H16: =C16-E16*(1-L16) -> 80.516807 | I16: =G16/C16 -> 0.30560187 | J16: =H16/C16 -> 0.31948983 | K16: ='eigene Konditionen'!B$5 -> 0 | L16: ='eigene Konditionen'!C$5 -> 0.02
A17: Minikid 4 (bis 5 Stück) | B17: 649.9 | C17: =B17/119*100 -> 546.13445 | D17: 327.68 | E17: =D17-K17*D17 -> 327.68 | F17: =C17/E17 -> 1.6666701 | G17: =C17-E17 -> 218.45445 | H17: =C17-E17*(1-L17) -> 225.00805 | I17: =G17/C17 -> 0.40000123 | J17: =H17/C17 -> 0.41200121 | K17: ='eigene Konditionen'!B$5 -> 0 | L17: ='eigene Konditionen'!C$5 -> 0.02
A18: Minikid 4 (ab 6 Stück) | B18: 649.9 | C18: =B18/119*100 -> 546.13445 | D18: 315 | E18: =D18-K18*D18 -> 315 | F18: =C18/E18 -> 1.7337602 | G18: =C18-E18 -> 231.13445 | H18: =C18-E18*(1-L18) -> 237.43445 | I18: =G18/C18 -> 0.42321896 | J18: =H18/C18 -> 0.43475458 | K18: ='eigene Konditionen'!B$5 -> 0 | L18: ='eigene Konditionen'!C$5 -> 0.02
A19: Movekid (bis 5 Stück) | B19: 449.9 | C19: =B19/119*100 -> 378.06723 | D19: 235 | E19: =D19-K19*D19 -> 235 | F19: =C19/E19 -> 1.6087967 | G19: =C19-E19 -> 143.06723 | H19: =C19-E19*(1-L19) -> 147.76723 | I19: =G19/C19 -> 0.37841743 | J19: =H19/C19 -> 0.39084908 | K19: ='eigene Konditionen'!B$5 -> 0 | L19: ='eigene Konditionen'!C$5 -> 0.02
A20: Movekid (ab 6 Stück) | B20: 449.9 | C20: =B20/119*100 -> 378.06723 | D20: 225 | E20: =D20-K20*D20 -> 225 | F20: =C20/E20 -> 1.6802988 | G20: =C20-E20 -> 153.06723 | H20: =C20-E20*(1-L20) -> 157.56723 | I20: =G20/C20 -> 0.40486775 | J20: =H20/C20 -> 0.41677039 | K20: ='eigene Konditionen'!B$5 -> 0 | L20: ='eigene Konditionen'!C$5 -> 0.02
A21: One 2 (bis 5 Stück) | B21: 799.9 | C21: =B21/119*100 -> 672.18487 | D21: 435.26 | E21: =D21-K21*D21 -> 435.26 | F21: =C21/E21 -> 1.5443295 | G21: =C21-E21 -> 236.92487 | H21: =C21-E21*(1-L21) -> 245.63007 | I21: =G21/C21 -> 0.35246981 | J21: =H21/C21 -> 0.36542041 | K21: ='eigene Konditionen'!B$5 -> 0 | L21: ='eigene Konditionen'!C$5 -> 0.02
A22: One 2 (ab 6 Stück) | B22: 799.9 | C22: =B22/119*100 -> 672.18487 | D22: 420 | E22: =D22-K22*D22 -> 420 | F22: =C22/E22 -> 1.6004402 | G22: =C22-E22 -> 252.18487 | H22: =C22-E22*(1-L22) -> 260.58487 | I22: =G22/C22 -> 0.3751719 | J22: =H22/C22 -> 0.38766846 | K22: ='eigene Konditionen'!B$5 -> 0 | L22: ='eigene Konditionen'!C$5 -> 0.02
A23: One+ 2 (bis 5 Stück) | B23: 849.9 | C23: =B23/119*100 -> 714.20168 | D23: 464.23 | E23: =D23-K23*D23 -> 464.23 | F23: =C23/E23 -> 1.5384652 | G23: =C23-E23 -> 249.97168 | H23: =C23-E23*(1-L23) -> 259.25628 | I23: =G23/C23 -> 0.35000153 | J23: =H23/C23 -> 0.3630015 | K23: ='eigene Konditionen'!B$5 -> 0 | L23: ='eigene Konditionen'!C$5 -> 0.02
A24: One+ 2 (ab 6 Stück) | B24: 849.9 | C24: =B24/119*100 -> 714.20168 | D24: 450 | E24: =D24-K24*D24 -> 450 | F24: =C24/E24 -> 1.5871148 | G24: =C24-E24 -> 264.20168 | H24: =C24-E24*(1-L24) -> 273.20168 | I24: =G24/C24 -> 0.36992587 | J24: =H24/C24 -> 0.38252736 | K24: ='eigene Konditionen'!B$5 -> 0 | L24: ='eigene Konditionen'!C$5 -> 0.02
A25: Rekid | B25: 499.9 | C25: =B25/119*100 -> 420.08403 | D25: 285 | E25: =D25-K25*D25 -> 285 | F25: =C25/E25 -> 1.4739791 | G25: =C25-E25 -> 135.08403 | H25: =C25-E25*(1-L25) -> 140.78403 | I25: =G25/C25 -> 0.32156431 | J25: =H25/C25 -> 0.33513303 | K25: ='eigene Konditionen'!B$5 -> 0 | L25: ='eigene Konditionen'!C$5 -> 0.02
A26: BeSafe | M26: BeSafe: 1,5% Frachtzuschlag auf EK berücksichtigt
A27: Beyond | B27: 469 | C27: =B27/119*100 -> 394.11765 | D27: 246 | E27: =D27-K27*D27 -> 247.23 | F27: =C27/E27 -> 1.5941336 | G27: =C27-E27 -> 146.88765 | H27: =C27-E27*(1-L27) -> 146.88765 | I27: =G27/C27 -> 0.3727 | J27: =H27/C27 -> 0.3727 | K27: ='eigene Konditionen'!B$6 -> -0.005 | L27: ='eigene Konditionen'!C$6 -> 0
A28: Beyond Mesh | B28: 489 | C28: =B28/119*100 -> 410.92437 | D28: 257 | E28: =D28-K28*D28 -> 258.285 | F28: =C28/E28 -> 1.5909726 | G28: =C28-E28 -> 152.63937 | H28: =C28-E28*(1-L28) -> 152.63937 | I28: =G28/C28 -> 0.37145368 | J28: =H28/C28 -> 0.37145368 | K28: ='eigene Konditionen'!B$6 -> -0.005 | L28: ='eigene Konditionen'!C$6 -> 0
A29: Beyond 360 | B29: 499 | C29: =B29/119*100 -> 419.32773 | D29: 262 | E29: =D29-K29*D29 -> 263.31 | F29: =C29/E29 -> 1.5925249 | G29: =C29-E29 -> 156.01773 | H29: =C29-E29*(1-L29) -> 156.01773 | I29: =G29/C29 -> 0.37206633 | J29: =H29/C29 -> 0.37206633 | K29: ='eigene Konditionen'!B$6 -> -0.005 | L29: ='eigene Konditionen'!C$6 -> 0
A30: Beyond 360 Mesh | B30: 519 | C30: =B30/119*100 -> 436.13445 | D30: 273 | E30: =D30-K30*D30 -> 274.365 | F30: =C30/E30 -> 1.589614 | G30: =C30-E30 -> 161.76945 | H30: =C30-E30*(1-L30) -> 161.76945 | I30: =G30/C30 -> 0.37091647 | J30: =H30/C30 -> 0.37091647 | K30: ='eigene Konditionen'!B$6 -> -0.005 | L30: ='eigene Konditionen'!C$6 -> 0
A31: Modular A (RF) X1 i-Size Mél | B31: 359 | C31: =B31/119*100 -> 301.68067 | D31: 200 | E31: =D31-K31*D31 -> 201 | F31: =C31/E31 -> 1.5008989 | G31: =C31-E31 -> 100.68067 | H31: =C31-E31*(1-L31) -> 100.68067 | I31: =G31/C31 -> 0.33373259 | J31: =H31/C31 -> 0.33373259 | K31: ='eigene Konditionen'!B$6 -> -0.005 | L31: ='eigene Konditionen'!C$6 -> 0
A32: Modular A (RF) X1 i-Size Mesh | B32: 379 | C32: =B32/119*100 -> 318.48739 | D32: 205 | E32: =D32-K32*D32 -> 206.025 | F32: =C32/E32 -> 1.5458677 | G32: =C32-E32 -> 112.46239 | H32: =C32-E32*(1-L32) -> 112.46239 | I32: =G32/C32 -> 0.35311412 | J32: =H32/C32 -> 0.35311412 | K32: ='eigene Konditionen'!B$6 -> -0.005 | L32: ='eigene Konditionen'!C$6 -> 0
A33: Modular (RF) X1 i-Size alle | B33: 339 | C33: =B33/119*100 -> 284.87395 | D33: 175 | E33: =D33-K33*D33 -> 175.875 | F33: =C33/E33 -> 1.6197524 | G33: =C33-E33 -> 108.99895 | H33: =C33-E33*(1-L33) -> 108.99895 | I33: =G33/C33 -> 0.38262168 | J33: =H33/C33 -> 0.38262168 | K33: ='eigene Konditionen'!B$6 -> -0.005 | L33: ='eigene Konditionen'!C$6 -> 0
A34: Plus X1 BC | B34: 519 | C34: =B34/119*100 -> 436.13445 | D34: 316.5 | E34: =D34-K34*D34 -> 318.0825 | F34: =C34/E34 -> 1.3711363 | G34: =C34-E34 -> 118.05195 | H34: =C34-E34*(1-L34) -> 118.05195 | I34: =G34/C34 -> 0.27067789 | J34: =H34/C34 -> 0.27067789 | K34: ='eigene Konditionen'!B$6 -> -0.005 | L34: ='eigene Konditionen'!C$6 -> 0
A35: Turn B i-Size BC | B35: 639 | C35: =B35/119*100 -> 536.97479 | D35: 341 | E35: =D35-K35*D35 -> 342.705 | F35: =C35/E35 -> 1.5668718 | G35: =C35-E35 -> 194.26979 | H35: =C35-E35*(1-L35) -> 194.26979 | I35: =G35/C35 -> 0.36178568 | J35: =H35/C35 -> 0.36178568 | K35: ='eigene Konditionen'!B$6 -> -0.005 | L35: ='eigene Konditionen'!C$6 -> 0 | M35: VK ab 15.06.24: 639 EUR
A36: Turn B i-Size Mél & PCI | B36: 639 | C36: =B36/119*100 -> 536.97479 | D36: 341 | E36: =D36-K36*D36 -> 342.705 | F36: =C36/E36 -> 1.5668718 | G36: =C36-E36 -> 194.26979 | H36: =C36-E36*(1-L36) -> 194.26979 | I36: =G36/C36 -> 0.36178568 | J36: =H36/C36 -> 0.36178568 | K36: ='eigene Konditionen'!B$6 -> -0.005 | L36: ='eigene Konditionen'!C$6 -> 0 | M36: VK ab 15.06.24: 639 EUR
A37: Turn B i-Size Mesh | B37: 659 | C37: =B37/119*100 -> 553.78151 | D37: 350 | E37: =D37-K37*D37 -> 351.75 | F37: =C37/E37 -> 1.5743611 | G37: =C37-E37 -> 202.03151 | H37: =C37-E37*(1-L37) -> 202.03151 | I37: =G37/C37 -> 0.3648217 | J37: =H37/C37 -> 0.3648217 | K37: ='eigene Konditionen'!B$6 -> -0.005 | L37: ='eigene Konditionen'!C$6 -> 0 | M37: VK ab 15.06.24: 659 EUR
A38: Turn M i-Size Melange | B38: 599 | C38: =B38/119*100 -> 503.36134 | D38: 298 | E38: =D38-K38*D38 -> 299.49 | F38: =C38/E38 -> 1.6807284 | G38: =C38-E38 -> 203.87134 | H38: =C38-E38*(1-L38) -> 203.87134 | I38: =G38/C38 -> 0.40501987 | J38: =H38/C38 -> 0.40501987 | K38: ='eigene Konditionen'!B$6 -> -0.005 | L38: ='eigene Konditionen'!C$6 -> 0 | M38: VK ab 15.06.24: 599 EUR
A39: Turn M i-Size Mesh | B39: 619 | C39: =B39/119*100 -> 520.16807 | D39: 307 | E39: =D39-K39*D39 -> 308.535 | F39: =C39/E39 -> 1.6859289 | G39: =C39-E39 -> 211.63307 | H39: =C39-E39*(1-L39) -> 211.63307 | I39: =G39/C39 -> 0.40685517 | J39: =H39/C39 -> 0.40685517 | K39: ='eigene Konditionen'!B$6 -> -0.005 | L39: ='eigene Konditionen'!C$6 -> 0 | M39: VK ab 15.06.24: 619 EUR
A40: Turn i-Size BC | B40: 559 | C40: =B40/119*100 -> 469.7479 | D40: 298 | E40: =D40-K40*D40 -> 299.49 | F40: =C40/E40 -> 1.5684928 | G40: =C40-E40 -> 170.2579 | H40: =C40-E40*(1-L40) -> 170.2579 | I40: =G40/C40 -> 0.36244526 | J40: =H40/C40 -> 0.36244526 | K40: ='eigene Konditionen'!B$6 -> -0.005 | L40: ='eigene Konditionen'!C$6 -> 0 | M40: VK ab 15.06.24: 559 EUR
A41: Turn i-Size Mél & PCI | B41: 559 | C41: =B41/119*100 -> 469.7479 | D41: 298 | E41: =D41-K41*D41 -> 299.49 | F41: =C41/E41 -> 1.5684928 | G41: =C41-E41 -> 170.2579 | H41: =C41-E41*(1-L41) -> 170.2579 | I41: =G41/C41 -> 0.36244526 | J41: =H41/C41 -> 0.36244526 | K41: ='eigene Konditionen'!B$6 -> -0.005 | L41: ='eigene Konditionen'!C$6 -> 0 | M41: VK ab 15.06.24: 559 EUR
...

Sheet Folgesitze
A1: Margenberechnung Verbund (Stand: 27.05.2024)
A2: Folgesitze
A3: Sitz/Variante | B3: VK Brutto | C3: VK netto | D3: EK netto regulär | E3: EK netto | F3: Zuschlag | G3: Gewinn | H3: Gewinn nach Skonto | I3: Marge [%] | J3: Marge [%] nach Skonto | K3: Rabatt(+)/ Zuschlag(-) | L3: Skonto [%]
A5: Avionaut
A6: Max Space Comfort System + | B6: 319 | C6: =B6/119*100 -> 268.06723 | D6: 200 | E6: =D6-D6*K6 -> 160 | F6: =C6/E6 -> 1.6754202 | G6: =C6-E6 -> 108.06723 | H6: =C6-E6*(1-L6) -> 108.06723 | I6: =G6/C6 -> 0.4031348 | J6: =H6/C6 -> 0.4031348 | K6: ='eigene Konditionen'!B$3 -> 0.2 | L6: ='eigene Konditionen'!C$3 -> 0
A7: Avova
A8: Sora Fix Grex & Black | B8: 239.95 | C8: =B8/119*100 -> 201.63866 | D8: 120 | E8: =D8-D8*K8 -> 120 | F8: =C8/E8 -> 1.6803221 | G8: =C8-E8 -> 81.638655 | H8: =C8-E8*(1-L8) -> 85.238655 | I8: =G8/C8 -> 0.40487602 | J8: =H8/C8 -> 0.42272974 | K8: ='eigene Konditionen'!B$4 -> 0 | L8: ='eigene Konditionen'!C$4 -> 0.03
A9: Sora fix alle anderen | B9: 239.95 | C9: =B9/119*100 -> 201.63866 | D9: 120 | E9: =D9-D9*K9 -> 120 | F9: =C9/E9 -> 1.6803221 | G9: =C9-E9 -> 81.638655 | H9: =C9-E9*(1-L9) -> 85.238655 | I9: =G9/C9 -> 0.40487602 | J9: =H9/C9 -> 0.42272974 | K9: ='eigene Konditionen'!B$4 -> 0 | L9: ='eigene Konditionen'!C$4 -> 0.03
A10: Star Grey & Black | B10: 149.95 | C10: =B10/119*100 -> 126.0084 | D10: 78.5 | E10: =D10-D10*K10 -> 78.5 | F10: =C10/E10 -> 1.6052026 | G10: =C10-E10 -> 47.508403 | H10: =C10-E10*(1-L10) -> 49.863403 | I10: =G10/C10 -> 0.37702568 | J10: =H10/C10 -> 0.3957149 | K10: ='eigene Konditionen'!B$4 -> 0 | L10: ='eigene Konditionen'!C$4 -> 0.03 | M10: EK für Doppelpack!
A11: Star alle anderen | B11: 139.95 | C11: =B11/119*100 -> 117.60504 | D11: 71 | E11: =D11-D11*K11 -> 71 | F11: =C11/E11 -> 1.656409 | G11: =C11-E11 -> 46.605042 | H11: =C11-E11*(1-L11) -> 48.735042 | I11: =G11/C11 -> 0.39628439 | J11: =H11/C11 -> 0.41439586 | K11: ='eigene Konditionen'!B$4 -> 0 | L11: ='eigene Konditionen'!C$4 -> 0.03 | M11: EK für Doppelpack!
A12: Star Fix Grey & Black | B12: 229.95 | C12: =B12/119*100 -> 193.23529 | D12: 112.5 | E12: =D12-D12*K12 -> 112.5 | F12: =C12/E12 -> 1.7176471 | G12: =C12-E12 -> 80.735294 | H12: =C12-E12*(1-L12) -> 84.110294 | I12: =G12/C12 -> 0.41780822 | J12: =H12/C12 -> 0.43527397 | K12: ='eigene Konditionen'!B$4 -> 0 | L12: ='eigene Konditionen'!C$4 -> 0.03 | M12: EK für Doppelpack!
A13: Star Fix alle anderen | B13: 219.95 | C13: =B13/119*100 -> 184.83193 | D13: 105 | E13: =D13-D13*K13 -> 105 | F13: =C13/E13 -> 1.7603041 | G13: =C13-E13 -> 79.831933 | H13: =C13-E13*(1-L13) -> 82.981933 | I13: =G13/C13 -> 0.43191634 | J13: =H13/C13 -> 0.44895885 | K13: ='eigene Konditionen'!B$4 -> 0 | L13: ='eigene Konditionen'!C$4 -> 0.03 | M13: EK für Doppelpack!
A14: BeSafe | M14: 1,5% Frachtzuschlag auf EK
A15: Flex Fix 2 | B15: 329 | C15: =B15/119*100 -> 276.47059 | D15: 193 | E15: =D15-D15*K15 -> 193.965 | F15: =C15/E15 -> 1.4253633 | G15: =C15-E15 -> 82.505588 | H15: =C15-E15*(1-L15) -> 82.505588 | I15: =G15/C15 -> 0.29842447 | J15: =H15/C15 -> 0.29842447 | K15: ='eigene Konditionen'!B$6 -> -0.005 | L15: ='eigene Konditionen'!C$6 -> 0
A16: Flex Fix i-Size Mesh | B16: 349 | C16: =B16/119*100 -> 293.27731 | D16: 201 | E16: =D16-D16*K16 -> 202.005 | F16: =C16/E16 -> 1.4518319 | G16: =C16-E16 -> 91.272311 | H16: =C16-E16*(1-L16) -> 91.272311 | I16: =G16/C16 -> 0.31121504 | J16: =H16/C16 -> 0.31121504 | K16: ='eigene Konditionen'!B$6 -> -0.005 | L16: ='eigene Konditionen'!C$6 -> 0
A17: Britax Römer
A18: Kidfix i-Size Standard | B18: 229.9 | C18: =B18/119*100 -> 193.19328 | D18: 190 | E18: =D18-D18*K18 -> 138.7 | F18: =C18/E18 -> 1.3928859 | G18: =C18-E18 -> 54.493277 | H18: =C18-E18*(1-L18) -> 58.654277 | I18: =G18/C18 -> 0.28206612 | J18: =H18/C18 -> 0.30360413 | K18: ='eigene Konditionen'!B$7 -> 0.27 | L18: ='eigene Konditionen'!C$7 -> 0.03
A19: Kidfix i-Size Green Sense | B19: 259.9 | C19: =B19/119*100 -> 218.40336 | D19: 215.21 | E19: =D19-D19*K19 -> 157.1033 | F19: =C19/E19 -> 1.3901895 | G19: =C19-E19 -> 61.300061 | H19: =C19-E19*(1-L19) -> 66.01316 | I19: =G19/C19 -> 0.28067362 | J19: =H19/C19 -> 0.30225341 | K19: ='eigene Konditionen'!B$7 -> 0.27 | L19: ='eigene Konditionen'!C$7 -> 0.03
A20: Kidfix M i-Size | B20: 209.9 | C20: =B20/119*100 -> 176.38655 | D20: 175 | E20: =D20-D20*K20 -> 127.75 | F20: =C20/E20 -> 1.3807167 | G20: =C20-E20 -> 48.636555 | H20: =C20-E20*(1-L20) -> 52.469055 | I20: =G20/C20 -> 0.27573845 | J20: =H20/C20 -> 0.29746629 | K20: ='eigene Konditionen'!B$7 -> 0.27 | L20: ='eigene Konditionen'!C$7 -> 0.03
A21: Cybex
A22: Solution T i-Fix | B22: 219.95 | C22: =B22/119*100 -> 184.83193 | D22: 141.8 | E22: =D22-D22*K22 -> 141.8 | F22: =C22/E22 -> 1.3034692 | G22: =C22-E22 -> 43.031933 | H22: =C22-E22*(1-L22) -> 47.285933 | I22: =G22/C22 -> 0.23281655 | J22: =H22/C22 -> 0.25583205 | K22: ='eigene Konditionen'!B$9 -> 0 | L22: ='eigene Konditionen'!C$9 -> 0.03
A23: Solution T i-Fix Plus | B23: 249.95 | C23: =B23/119*100 -> 210.04202 | D23: 160.6 | E23: =D23-D23*K23 -> 160.6 | F23: =C23/E23 -> 1.3078581 | G23: =C23-E23 -> 49.442017 | H23: =C23-E23*(1-L23) -> 54.260017 | I23: =G23/C23 -> 0.23539108 | J23: =H23/C23 -> 0.25832935 | K23: ='eigene Konditionen'!B$9 -> 0 | L23: ='eigene Konditionen'!C$9 -> 0.03
A24: Solution S2 i-Fix | B24: 179.95 | C24: =B24/119*100 -> 151.21849 | D24: 128.4 | E24: =D24-D24*K24 -> 128.4 | F24: =C24/E24 -> 1.1777141 | G24: =C24-E24 -> 22.818487 | H24: =C24-E24*(1-L24) -> 26.670487 | I24: =G24/C24 -> 0.15089747 | J24: =H24/C24 -> 0.17637055 | K24: ='eigene Konditionen'!B$9 -> 0 | L24: ='eigene Konditionen'!C$9 -> 0.03
A25: Solution G i-fix | B25: 199.95 | C25: =B25/119*100 -> 168.02521 | D25: 138.4 | E25: =D25-D25*K25 -> 138.4 | F25: =C25/E25 -> 1.214055 | G25: =C25-E25 -> 29.62521 | H25: =C25-E25*(1-L25) -> 33.77721 | I25: =G25/C25 -> 0.17631408 | J25: =H25/C25 -> 0.20102466 | K25: ='eigene Konditionen'!B$9 -> 0 | L25: ='eigene Konditionen'!C$9 -> 0.03
A26: Solution G i-fix Plus | B26: 229.95 | C26: =B26/119*100 -> 193.23529 | D26: 159.2 | E26: =D26-D26*K26 -> 159.2 | F26: =C26/E26 -> 1.2137895 | G26: =C26-E26 -> 34.035294 | H26: =C26-E26*(1-L26) -> 38.811294 | I26: =G26/C26 -> 0.17613394 | J26: =H26/C26 -> 0.20084992 | K26: ='eigene Konditionen'!B$9 -> 0 | L26: ='eigene Konditionen'!C$9 -> 0.03
A27: Joie
A28: i-Traver | B28: 189.95 | C28: =B28/119*100 -> 159.62185 | D28: 111.8 | E28: =D28-D28*K28 -> 106.21 | F28: =C28/E28 -> 1.5028891 | G28: =C28-E28 -> 53.411849 | H28: =C28-E28*(1-L28) -> 58.722349 | I28: =G28/C28 -> 0.3346149 | J28: =H28/C28 -> 0.36788415 | K28: ='eigene Konditionen'!B$11 -> 0.05 | L28: ='eigene Konditionen'!C$11 -> 0.05
A29: Traver | B29: 129.95 | C29: =B29/119*100 -> 109.20168 | D29: 78.8 | E29: =D29-D29*K29 -> 74.86 | F29: =C29/E29 -> 1.4587454 | G29: =C29-E29 -> 34.341681 | H29: =C29-E29*(1-L29) -> 38.084681 | I29: =G29/C29 -> 0.31447942 | J29: =H29/C29 -> 0.34875544 | K29: ='eigene Konditionen'!B$11 -> 0.05 | L29: ='eigene Konditionen'!C$11 -> 0.05
A30: Kiddy Cruiserfix 3 | B30: 279 | C30: =B30/119*100 -> 234.45378 | D30: 175 | E30: =D30-D30*K30 -> 175 | F30: =C30/E30 -> 1.3397359 | G30: =C30-E30 -> 59.453782 | H30: =C30-E30*(1-L30) -> 59.453782 | I30: =G30/C30 -> 0.25358423 | J30: =H30/C30 -> 0.25358423 | K30: ='eigene Konditionen'!B$12 -> 0 | L30: ='eigene Konditionen'!C$12 -> 0
A31: nuna aace | B31: 249.95 | C31: =B31/119*100 -> 210.04202 | D31: 151.95 | E31: =D31-D31*K31 -> 144.3525 | F31: =C31/E31 -> 1.4550632 | G31: =C31-E31 -> 65.689517 | H31: =C31-E31*(1-L31) -> 72.907142 | I31: =G31/C31 -> 0.31274465 | J31: =H31/C31 -> 0.34710742 | K31: ='eigene Konditionen'!B$16 -> 0.05 | L31: ='eigene Konditionen'!C$16 -> 0.05
A32: Swandoo Charlie i-Size | B32: 269 | C32: =B32/119*100 -> 226.05042 | D32: 159.9 | E32: =D32-K32*D32 -> 148.707 | F32: =C32/E32 -> 1.5201061 | G32: =C32-E32 -> 77.34342 | H32: =C32-E32*(1-L32) -> 81.80463 | I32: =G32/C32 -> 0.34215119 | J32: =H32/C32 -> 0.36188665 | K32: ='eigene Konditionen'!B$17 -> 0.07 | L32: ='eigene Konditionen'!C$17 -> 0.03
A33: Takata Maxi | B33: 299 | C33: =B33/119*100 -> 251.2605 | D33: 150 | E33: =D33-D33*K33 -> 150 | F33: =C33/E33 -> 1.67507 | G33: =C33-E33 -> 101.2605 | H33: =C33-E33*(1-L33) -> 101.2605 | I33: =G33/C33 -> 0.40301003 | J33: =H33/C33 -> 0.40301003 | K33: ='eigene Konditionen'!B$18 -> 0 | L33: ='eigene Konditionen'!C$18 -> 0

Sheet eigene Konditionen
A1: Konditionen Verbund (Stand: 27.05.2024 )
B2: Rabatt(+)/ Zuschlag(-) | C2: Skonto
A3: Avionaut | B3: 0.2 | C3: 0
A4: Avova | B4: 0 | C4: 0.03
A5: Axkid | B5: 0 | C5: 0.02 | D5: 2 % Rabatt für Star Händler
A6: BeSafe | B6: -0.005 | C6: 0
A7: Britax Römer | B7: 0.27 | C7: 0.03
A8: Concord | B8: 0 | C8: 0.03
A9: Cybex | B9: 0 | C9: 0.03
A10: Goodbaby | B10: 0 | C10: 0.03
A11: Joie | B11: 0.05 | C11: 0.05
A12: Kiddy | B12: 0 | C12: 0
A13: Klippan | B13: 0 | C13: 0
A14: Maxi Cosi | B14: 0.315 | C14: 0
A15: Nachfolger | B15: 0 | C15: 0
A16: nuna | B16: 0.05 | C16: 0.05
A17: Swandoo | B17: 0.07 | C17: 0.03
A18: Takata | B18: 0 | C18: 0
